[2025-02-28T14:02:22.061+0000] {processor.py:186} INFO - Started process (PID=51) to work on /opt/airflow/dags/__pycache__/fire_incidents_dag.py
[2025-02-28T14:02:22.063+0000] {processor.py:914} INFO - Processing file /opt/airflow/dags/__pycache__/fire_incidents_dag.py for tasks to queue
[2025-02-28T14:02:22.069+0000] {logging_mixin.py:190} INFO - [2025-02-28T14:02:22.067+0000] {dagbag.py:588} INFO - Filling up the DagBag from /opt/airflow/dags/__pycache__/fire_incidents_dag.py
[2025-02-28T14:02:22.081+0000] {logging_mixin.py:190} INFO - [2025-02-28T14:02:22.077+0000] {dagbag.py:387} ERROR - Failed to import: /opt/airflow/dags/__pycache__/fire_incidents_dag.py
Traceback (most recent call last):
  File "/home/airflow/.local/lib/python3.12/site-packages/airflow/models/dagbag.py", line 383, in parse
    loader.exec_module(new_module)
  File "<frozen importlib._bootstrap_external>", line 999, in exec_module
  File "<frozen importlib._bootstrap>", line 488, in _call_with_frames_removed
  File "/opt/airflow/dags/__pycache__/fire_incidents_dag.py", line 4, in <module>
    from pull_fire_incidents import pull_data_via_api
ModuleNotFoundError: No module named 'pull_fire_incidents'
[2025-02-28T14:02:22.082+0000] {processor.py:927} WARNING - No viable dags retrieved from /opt/airflow/dags/__pycache__/fire_incidents_dag.py
[2025-02-28T14:02:22.503+0000] {processor.py:208} INFO - Processing /opt/airflow/dags/__pycache__/fire_incidents_dag.py took 0.453 seconds
[2025-02-28T14:03:19.316+0000] {processor.py:186} INFO - Started process (PID=115) to work on /opt/airflow/dags/__pycache__/fire_incidents_dag.py
[2025-02-28T14:03:19.470+0000] {processor.py:914} INFO - Processing file /opt/airflow/dags/__pycache__/fire_incidents_dag.py for tasks to queue
[2025-02-28T14:03:19.473+0000] {logging_mixin.py:190} INFO - [2025-02-28T14:03:19.472+0000] {dagbag.py:588} INFO - Filling up the DagBag from /opt/airflow/dags/__pycache__/fire_incidents_dag.py
[2025-02-28T14:03:19.476+0000] {logging_mixin.py:190} INFO - [2025-02-28T14:03:19.475+0000] {dagbag.py:387} ERROR - Failed to import: /opt/airflow/dags/__pycache__/fire_incidents_dag.py
Traceback (most recent call last):
  File "/home/airflow/.local/lib/python3.12/site-packages/airflow/models/dagbag.py", line 383, in parse
    loader.exec_module(new_module)
  File "<frozen importlib._bootstrap_external>", line 999, in exec_module
  File "<frozen importlib._bootstrap>", line 488, in _call_with_frames_removed
  File "/opt/airflow/dags/__pycache__/fire_incidents_dag.py", line 4, in <module>
    from pull_fire_incidents import pull_data_via_api
ModuleNotFoundError: No module named 'pull_fire_incidents'
[2025-02-28T14:03:19.477+0000] {processor.py:927} WARNING - No viable dags retrieved from /opt/airflow/dags/__pycache__/fire_incidents_dag.py
[2025-02-28T14:03:19.656+0000] {processor.py:208} INFO - Processing /opt/airflow/dags/__pycache__/fire_incidents_dag.py took 0.345 seconds
[2025-02-28T14:03:58.884+0000] {processor.py:186} INFO - Started process (PID=172) to work on /opt/airflow/dags/__pycache__/fire_incidents_dag.py
[2025-02-28T14:03:58.885+0000] {processor.py:914} INFO - Processing file /opt/airflow/dags/__pycache__/fire_incidents_dag.py for tasks to queue
[2025-02-28T14:03:58.887+0000] {logging_mixin.py:190} INFO - [2025-02-28T14:03:58.887+0000] {dagbag.py:588} INFO - Filling up the DagBag from /opt/airflow/dags/__pycache__/fire_incidents_dag.py
[2025-02-28T14:03:58.890+0000] {logging_mixin.py:190} INFO - [2025-02-28T14:03:58.889+0000] {dagbag.py:387} ERROR - Failed to import: /opt/airflow/dags/__pycache__/fire_incidents_dag.py
Traceback (most recent call last):
  File "/home/airflow/.local/lib/python3.12/site-packages/airflow/models/dagbag.py", line 383, in parse
    loader.exec_module(new_module)
  File "<frozen importlib._bootstrap_external>", line 999, in exec_module
  File "<frozen importlib._bootstrap>", line 488, in _call_with_frames_removed
  File "/opt/airflow/dags/__pycache__/fire_incidents_dag.py", line 4, in <module>
    from pull_fire_incidents import pull_data_via_api
ModuleNotFoundError: No module named 'pull_fire_incidents'
[2025-02-28T14:03:58.891+0000] {processor.py:927} WARNING - No viable dags retrieved from /opt/airflow/dags/__pycache__/fire_incidents_dag.py
[2025-02-28T14:03:58.909+0000] {processor.py:208} INFO - Processing /opt/airflow/dags/__pycache__/fire_incidents_dag.py took 0.029 seconds
[2025-02-28T14:04:29.152+0000] {processor.py:186} INFO - Started process (PID=229) to work on /opt/airflow/dags/__pycache__/fire_incidents_dag.py
[2025-02-28T14:04:29.154+0000] {processor.py:914} INFO - Processing file /opt/airflow/dags/__pycache__/fire_incidents_dag.py for tasks to queue
[2025-02-28T14:04:29.159+0000] {logging_mixin.py:190} INFO - [2025-02-28T14:04:29.158+0000] {dagbag.py:588} INFO - Filling up the DagBag from /opt/airflow/dags/__pycache__/fire_incidents_dag.py
[2025-02-28T14:04:29.166+0000] {logging_mixin.py:190} INFO - [2025-02-28T14:04:29.164+0000] {dagbag.py:387} ERROR - Failed to import: /opt/airflow/dags/__pycache__/fire_incidents_dag.py
Traceback (most recent call last):
  File "/home/airflow/.local/lib/python3.12/site-packages/airflow/models/dagbag.py", line 383, in parse
    loader.exec_module(new_module)
  File "<frozen importlib._bootstrap_external>", line 999, in exec_module
  File "<frozen importlib._bootstrap>", line 488, in _call_with_frames_removed
  File "/opt/airflow/dags/__pycache__/fire_incidents_dag.py", line 4, in <module>
    from pull_fire_incidents import pull_data_via_api
ModuleNotFoundError: No module named 'pull_fire_incidents'
[2025-02-28T14:04:29.167+0000] {processor.py:927} WARNING - No viable dags retrieved from /opt/airflow/dags/__pycache__/fire_incidents_dag.py
[2025-02-28T14:04:29.189+0000] {processor.py:208} INFO - Processing /opt/airflow/dags/__pycache__/fire_incidents_dag.py took 0.051 seconds
[2025-02-28T14:05:08.525+0000] {processor.py:186} INFO - Started process (PID=287) to work on /opt/airflow/dags/__pycache__/fire_incidents_dag.py
[2025-02-28T14:05:08.526+0000] {processor.py:914} INFO - Processing file /opt/airflow/dags/__pycache__/fire_incidents_dag.py for tasks to queue
[2025-02-28T14:05:08.528+0000] {logging_mixin.py:190} INFO - [2025-02-28T14:05:08.528+0000] {dagbag.py:588} INFO - Filling up the DagBag from /opt/airflow/dags/__pycache__/fire_incidents_dag.py
[2025-02-28T14:05:09.449+0000] {logging_mixin.py:190} INFO - [2025-02-28T14:05:09.010+0000] {dagbag.py:387} ERROR - Failed to import: /opt/airflow/dags/__pycache__/fire_incidents_dag.py
Traceback (most recent call last):
  File "/home/airflow/.local/lib/python3.12/site-packages/airflow/models/dagbag.py", line 383, in parse
    loader.exec_module(new_module)
  File "<frozen importlib._bootstrap_external>", line 999, in exec_module
  File "<frozen importlib._bootstrap>", line 488, in _call_with_frames_removed
  File "/opt/airflow/dags/__pycache__/fire_incidents_dag.py", line 4, in <module>
    from pull_fire_incidents import pull_data_via_api
ModuleNotFoundError: No module named 'pull_fire_incidents'
[2025-02-28T14:05:09.483+0000] {processor.py:927} WARNING - No viable dags retrieved from /opt/airflow/dags/__pycache__/fire_incidents_dag.py
[2025-02-28T14:05:15.310+0000] {processor.py:208} INFO - Processing /opt/airflow/dags/__pycache__/fire_incidents_dag.py took 6.793 seconds
[2025-02-28T14:05:46.104+0000] {processor.py:186} INFO - Started process (PID=356) to work on /opt/airflow/dags/__pycache__/fire_incidents_dag.py
[2025-02-28T14:05:46.106+0000] {processor.py:914} INFO - Processing file /opt/airflow/dags/__pycache__/fire_incidents_dag.py for tasks to queue
[2025-02-28T14:05:46.109+0000] {logging_mixin.py:190} INFO - [2025-02-28T14:05:46.109+0000] {dagbag.py:588} INFO - Filling up the DagBag from /opt/airflow/dags/__pycache__/fire_incidents_dag.py
[2025-02-28T14:05:46.116+0000] {logging_mixin.py:190} INFO - [2025-02-28T14:05:46.114+0000] {dagbag.py:387} ERROR - Failed to import: /opt/airflow/dags/__pycache__/fire_incidents_dag.py
Traceback (most recent call last):
  File "/home/airflow/.local/lib/python3.12/site-packages/airflow/models/dagbag.py", line 383, in parse
    loader.exec_module(new_module)
  File "<frozen importlib._bootstrap_external>", line 999, in exec_module
  File "<frozen importlib._bootstrap>", line 488, in _call_with_frames_removed
  File "/opt/airflow/dags/__pycache__/fire_incidents_dag.py", line 4, in <module>
    from pull_fire_incidents import pull_data_via_api
ModuleNotFoundError: No module named 'pull_fire_incidents'
[2025-02-28T14:05:46.117+0000] {processor.py:927} WARNING - No viable dags retrieved from /opt/airflow/dags/__pycache__/fire_incidents_dag.py
[2025-02-28T14:05:46.135+0000] {processor.py:208} INFO - Processing /opt/airflow/dags/__pycache__/fire_incidents_dag.py took 0.042 seconds
[2025-02-28T14:06:16.432+0000] {processor.py:186} INFO - Started process (PID=421) to work on /opt/airflow/dags/__pycache__/fire_incidents_dag.py
[2025-02-28T14:06:16.434+0000] {processor.py:914} INFO - Processing file /opt/airflow/dags/__pycache__/fire_incidents_dag.py for tasks to queue
[2025-02-28T14:06:16.436+0000] {logging_mixin.py:190} INFO - [2025-02-28T14:06:16.435+0000] {dagbag.py:588} INFO - Filling up the DagBag from /opt/airflow/dags/__pycache__/fire_incidents_dag.py
[2025-02-28T14:06:16.439+0000] {logging_mixin.py:190} INFO - [2025-02-28T14:06:16.438+0000] {dagbag.py:387} ERROR - Failed to import: /opt/airflow/dags/__pycache__/fire_incidents_dag.py
Traceback (most recent call last):
  File "/home/airflow/.local/lib/python3.12/site-packages/airflow/models/dagbag.py", line 383, in parse
    loader.exec_module(new_module)
  File "<frozen importlib._bootstrap_external>", line 999, in exec_module
  File "<frozen importlib._bootstrap>", line 488, in _call_with_frames_removed
  File "/opt/airflow/dags/__pycache__/fire_incidents_dag.py", line 4, in <module>
    from pull_fire_incidents import pull_data_via_api
ModuleNotFoundError: No module named 'pull_fire_incidents'
[2025-02-28T14:06:16.439+0000] {processor.py:927} WARNING - No viable dags retrieved from /opt/airflow/dags/__pycache__/fire_incidents_dag.py
[2025-02-28T14:06:16.460+0000] {processor.py:208} INFO - Processing /opt/airflow/dags/__pycache__/fire_incidents_dag.py took 0.035 seconds
[2025-02-28T14:06:46.854+0000] {processor.py:186} INFO - Started process (PID=485) to work on /opt/airflow/dags/__pycache__/fire_incidents_dag.py
[2025-02-28T14:06:46.854+0000] {processor.py:914} INFO - Processing file /opt/airflow/dags/__pycache__/fire_incidents_dag.py for tasks to queue
[2025-02-28T14:06:46.856+0000] {logging_mixin.py:190} INFO - [2025-02-28T14:06:46.856+0000] {dagbag.py:588} INFO - Filling up the DagBag from /opt/airflow/dags/__pycache__/fire_incidents_dag.py
[2025-02-28T14:06:46.859+0000] {logging_mixin.py:190} INFO - [2025-02-28T14:06:46.858+0000] {dagbag.py:387} ERROR - Failed to import: /opt/airflow/dags/__pycache__/fire_incidents_dag.py
Traceback (most recent call last):
  File "/home/airflow/.local/lib/python3.12/site-packages/airflow/models/dagbag.py", line 383, in parse
    loader.exec_module(new_module)
  File "<frozen importlib._bootstrap_external>", line 999, in exec_module
  File "<frozen importlib._bootstrap>", line 488, in _call_with_frames_removed
  File "/opt/airflow/dags/__pycache__/fire_incidents_dag.py", line 4, in <module>
    from pull_fire_incidents import pull_data_via_api
ModuleNotFoundError: No module named 'pull_fire_incidents'
[2025-02-28T14:06:46.859+0000] {processor.py:927} WARNING - No viable dags retrieved from /opt/airflow/dags/__pycache__/fire_incidents_dag.py
[2025-02-28T14:06:46.872+0000] {processor.py:208} INFO - Processing /opt/airflow/dags/__pycache__/fire_incidents_dag.py took 0.022 seconds
[2025-02-28T14:07:17.791+0000] {processor.py:186} INFO - Started process (PID=549) to work on /opt/airflow/dags/__pycache__/fire_incidents_dag.py
[2025-02-28T14:07:17.792+0000] {processor.py:914} INFO - Processing file /opt/airflow/dags/__pycache__/fire_incidents_dag.py for tasks to queue
[2025-02-28T14:07:17.794+0000] {logging_mixin.py:190} INFO - [2025-02-28T14:07:17.793+0000] {dagbag.py:588} INFO - Filling up the DagBag from /opt/airflow/dags/__pycache__/fire_incidents_dag.py
[2025-02-28T14:07:18.104+0000] {logging_mixin.py:190} INFO - [2025-02-28T14:07:18.103+0000] {dagbag.py:387} ERROR - Failed to import: /opt/airflow/dags/__pycache__/fire_incidents_dag.py
Traceback (most recent call last):
  File "/home/airflow/.local/lib/python3.12/site-packages/airflow/models/dagbag.py", line 383, in parse
    loader.exec_module(new_module)
  File "<frozen importlib._bootstrap_external>", line 999, in exec_module
  File "<frozen importlib._bootstrap>", line 488, in _call_with_frames_removed
  File "/opt/airflow/dags/__pycache__/fire_incidents_dag.py", line 4, in <module>
    from pull_fire_incidents import pull_data_via_api
ModuleNotFoundError: No module named 'pull_fire_incidents'
[2025-02-28T14:07:18.105+0000] {processor.py:927} WARNING - No viable dags retrieved from /opt/airflow/dags/__pycache__/fire_incidents_dag.py
[2025-02-28T22:42:02.546+0000] {processor.py:186} INFO - Started process (PID=44) to work on /opt/airflow/dags/__pycache__/fire_incidents_dag.py
[2025-02-28T22:42:02.548+0000] {processor.py:914} INFO - Processing file /opt/airflow/dags/__pycache__/fire_incidents_dag.py for tasks to queue
[2025-02-28T22:42:02.554+0000] {logging_mixin.py:190} INFO - [2025-02-28T22:42:02.553+0000] {dagbag.py:588} INFO - Filling up the DagBag from /opt/airflow/dags/__pycache__/fire_incidents_dag.py
[2025-02-28T22:42:02.562+0000] {logging_mixin.py:190} INFO - [2025-02-28T22:42:02.561+0000] {dagbag.py:387} ERROR - Failed to import: /opt/airflow/dags/__pycache__/fire_incidents_dag.py
Traceback (most recent call last):
  File "/home/airflow/.local/lib/python3.12/site-packages/airflow/models/dagbag.py", line 383, in parse
    loader.exec_module(new_module)
  File "<frozen importlib._bootstrap_external>", line 999, in exec_module
  File "<frozen importlib._bootstrap>", line 488, in _call_with_frames_removed
  File "/opt/airflow/dags/__pycache__/fire_incidents_dag.py", line 4, in <module>
    from pull_fire_incidents import pull_data_via_api
ModuleNotFoundError: No module named 'pull_fire_incidents'
[2025-02-28T22:42:02.563+0000] {processor.py:927} WARNING - No viable dags retrieved from /opt/airflow/dags/__pycache__/fire_incidents_dag.py
[2025-02-28T22:42:02.591+0000] {processor.py:208} INFO - Processing /opt/airflow/dags/__pycache__/fire_incidents_dag.py took 0.053 seconds
[2025-02-28T22:42:33.464+0000] {processor.py:186} INFO - Started process (PID=108) to work on /opt/airflow/dags/__pycache__/fire_incidents_dag.py
[2025-02-28T22:42:33.466+0000] {processor.py:914} INFO - Processing file /opt/airflow/dags/__pycache__/fire_incidents_dag.py for tasks to queue
[2025-02-28T22:42:33.471+0000] {logging_mixin.py:190} INFO - [2025-02-28T22:42:33.471+0000] {dagbag.py:588} INFO - Filling up the DagBag from /opt/airflow/dags/__pycache__/fire_incidents_dag.py
[2025-02-28T22:42:33.479+0000] {logging_mixin.py:190} INFO - [2025-02-28T22:42:33.476+0000] {dagbag.py:387} ERROR - Failed to import: /opt/airflow/dags/__pycache__/fire_incidents_dag.py
Traceback (most recent call last):
  File "/home/airflow/.local/lib/python3.12/site-packages/airflow/models/dagbag.py", line 383, in parse
    loader.exec_module(new_module)
  File "<frozen importlib._bootstrap_external>", line 999, in exec_module
  File "<frozen importlib._bootstrap>", line 488, in _call_with_frames_removed
  File "/opt/airflow/dags/__pycache__/fire_incidents_dag.py", line 4, in <module>
    from pull_fire_incidents import pull_data_via_api
ModuleNotFoundError: No module named 'pull_fire_incidents'
[2025-02-28T22:42:33.480+0000] {processor.py:927} WARNING - No viable dags retrieved from /opt/airflow/dags/__pycache__/fire_incidents_dag.py
[2025-02-28T22:42:33.538+0000] {processor.py:208} INFO - Processing /opt/airflow/dags/__pycache__/fire_incidents_dag.py took 0.100 seconds
[2025-02-28T22:47:13.683+0000] {processor.py:186} INFO - Started process (PID=44) to work on /opt/airflow/dags/__pycache__/fire_incidents_dag.py
[2025-02-28T22:47:13.686+0000] {processor.py:914} INFO - Processing file /opt/airflow/dags/__pycache__/fire_incidents_dag.py for tasks to queue
[2025-02-28T22:47:13.697+0000] {logging_mixin.py:190} INFO - [2025-02-28T22:47:13.695+0000] {dagbag.py:588} INFO - Filling up the DagBag from /opt/airflow/dags/__pycache__/fire_incidents_dag.py
[2025-02-28T22:47:13.710+0000] {logging_mixin.py:190} INFO - [2025-02-28T22:47:13.708+0000] {dagbag.py:387} ERROR - Failed to import: /opt/airflow/dags/__pycache__/fire_incidents_dag.py
Traceback (most recent call last):
  File "/home/airflow/.local/lib/python3.12/site-packages/airflow/models/dagbag.py", line 383, in parse
    loader.exec_module(new_module)
  File "<frozen importlib._bootstrap_external>", line 999, in exec_module
  File "<frozen importlib._bootstrap>", line 488, in _call_with_frames_removed
  File "/opt/airflow/dags/__pycache__/fire_incidents_dag.py", line 4, in <module>
    from pull_fire_incidents import pull_data_via_api
ModuleNotFoundError: No module named 'pull_fire_incidents'
[2025-02-28T22:47:13.711+0000] {processor.py:927} WARNING - No viable dags retrieved from /opt/airflow/dags/__pycache__/fire_incidents_dag.py
[2025-02-28T22:47:13.770+0000] {processor.py:208} INFO - Processing /opt/airflow/dags/__pycache__/fire_incidents_dag.py took 0.098 seconds
[2025-02-28T22:47:44.772+0000] {processor.py:186} INFO - Started process (PID=108) to work on /opt/airflow/dags/__pycache__/fire_incidents_dag.py
[2025-02-28T22:47:44.773+0000] {processor.py:914} INFO - Processing file /opt/airflow/dags/__pycache__/fire_incidents_dag.py for tasks to queue
[2025-02-28T22:47:44.774+0000] {logging_mixin.py:190} INFO - [2025-02-28T22:47:44.774+0000] {dagbag.py:588} INFO - Filling up the DagBag from /opt/airflow/dags/__pycache__/fire_incidents_dag.py
[2025-02-28T22:47:44.777+0000] {logging_mixin.py:190} INFO - [2025-02-28T22:47:44.776+0000] {dagbag.py:387} ERROR - Failed to import: /opt/airflow/dags/__pycache__/fire_incidents_dag.py
Traceback (most recent call last):
  File "/home/airflow/.local/lib/python3.12/site-packages/airflow/models/dagbag.py", line 383, in parse
    loader.exec_module(new_module)
  File "<frozen importlib._bootstrap_external>", line 999, in exec_module
  File "<frozen importlib._bootstrap>", line 488, in _call_with_frames_removed
  File "/opt/airflow/dags/__pycache__/fire_incidents_dag.py", line 4, in <module>
    from pull_fire_incidents import pull_data_via_api
ModuleNotFoundError: No module named 'pull_fire_incidents'
[2025-02-28T22:47:44.778+0000] {processor.py:927} WARNING - No viable dags retrieved from /opt/airflow/dags/__pycache__/fire_incidents_dag.py
[2025-02-28T22:47:44.826+0000] {processor.py:208} INFO - Processing /opt/airflow/dags/__pycache__/fire_incidents_dag.py took 0.059 seconds
[2025-02-28T22:48:15.235+0000] {processor.py:186} INFO - Started process (PID=172) to work on /opt/airflow/dags/__pycache__/fire_incidents_dag.py
[2025-02-28T22:48:15.237+0000] {processor.py:914} INFO - Processing file /opt/airflow/dags/__pycache__/fire_incidents_dag.py for tasks to queue
[2025-02-28T22:48:15.240+0000] {logging_mixin.py:190} INFO - [2025-02-28T22:48:15.239+0000] {dagbag.py:588} INFO - Filling up the DagBag from /opt/airflow/dags/__pycache__/fire_incidents_dag.py
[2025-02-28T22:48:15.244+0000] {logging_mixin.py:190} INFO - [2025-02-28T22:48:15.243+0000] {dagbag.py:387} ERROR - Failed to import: /opt/airflow/dags/__pycache__/fire_incidents_dag.py
Traceback (most recent call last):
  File "/home/airflow/.local/lib/python3.12/site-packages/airflow/models/dagbag.py", line 383, in parse
    loader.exec_module(new_module)
  File "<frozen importlib._bootstrap_external>", line 999, in exec_module
  File "<frozen importlib._bootstrap>", line 488, in _call_with_frames_removed
  File "/opt/airflow/dags/__pycache__/fire_incidents_dag.py", line 4, in <module>
    from pull_fire_incidents import pull_data_via_api
ModuleNotFoundError: No module named 'pull_fire_incidents'
[2025-02-28T22:48:15.244+0000] {processor.py:927} WARNING - No viable dags retrieved from /opt/airflow/dags/__pycache__/fire_incidents_dag.py
[2025-02-28T22:48:15.382+0000] {processor.py:208} INFO - Processing /opt/airflow/dags/__pycache__/fire_incidents_dag.py took 0.161 seconds
[2025-02-28T22:48:46.404+0000] {processor.py:186} INFO - Started process (PID=236) to work on /opt/airflow/dags/__pycache__/fire_incidents_dag.py
[2025-02-28T22:48:46.406+0000] {processor.py:914} INFO - Processing file /opt/airflow/dags/__pycache__/fire_incidents_dag.py for tasks to queue
[2025-02-28T22:48:46.412+0000] {logging_mixin.py:190} INFO - [2025-02-28T22:48:46.411+0000] {dagbag.py:588} INFO - Filling up the DagBag from /opt/airflow/dags/__pycache__/fire_incidents_dag.py
[2025-02-28T22:48:46.420+0000] {logging_mixin.py:190} INFO - [2025-02-28T22:48:46.418+0000] {dagbag.py:387} ERROR - Failed to import: /opt/airflow/dags/__pycache__/fire_incidents_dag.py
Traceback (most recent call last):
  File "/home/airflow/.local/lib/python3.12/site-packages/airflow/models/dagbag.py", line 383, in parse
    loader.exec_module(new_module)
  File "<frozen importlib._bootstrap_external>", line 999, in exec_module
  File "<frozen importlib._bootstrap>", line 488, in _call_with_frames_removed
  File "/opt/airflow/dags/__pycache__/fire_incidents_dag.py", line 4, in <module>
    from pull_fire_incidents import pull_data_via_api
ModuleNotFoundError: No module named 'pull_fire_incidents'
[2025-02-28T22:48:46.421+0000] {processor.py:927} WARNING - No viable dags retrieved from /opt/airflow/dags/__pycache__/fire_incidents_dag.py
[2025-02-28T22:48:46.456+0000] {processor.py:208} INFO - Processing /opt/airflow/dags/__pycache__/fire_incidents_dag.py took 0.071 seconds
[2025-02-28T22:49:17.138+0000] {processor.py:186} INFO - Started process (PID=300) to work on /opt/airflow/dags/__pycache__/fire_incidents_dag.py
[2025-02-28T22:49:17.139+0000] {processor.py:914} INFO - Processing file /opt/airflow/dags/__pycache__/fire_incidents_dag.py for tasks to queue
[2025-02-28T22:49:17.142+0000] {logging_mixin.py:190} INFO - [2025-02-28T22:49:17.141+0000] {dagbag.py:588} INFO - Filling up the DagBag from /opt/airflow/dags/__pycache__/fire_incidents_dag.py
[2025-02-28T22:49:17.146+0000] {logging_mixin.py:190} INFO - [2025-02-28T22:49:17.145+0000] {dagbag.py:387} ERROR - Failed to import: /opt/airflow/dags/__pycache__/fire_incidents_dag.py
Traceback (most recent call last):
  File "/home/airflow/.local/lib/python3.12/site-packages/airflow/models/dagbag.py", line 383, in parse
    loader.exec_module(new_module)
  File "<frozen importlib._bootstrap_external>", line 999, in exec_module
  File "<frozen importlib._bootstrap>", line 488, in _call_with_frames_removed
  File "/opt/airflow/dags/__pycache__/fire_incidents_dag.py", line 4, in <module>
    from pull_fire_incidents import pull_data_via_api
ModuleNotFoundError: No module named 'pull_fire_incidents'
[2025-02-28T22:49:17.147+0000] {processor.py:927} WARNING - No viable dags retrieved from /opt/airflow/dags/__pycache__/fire_incidents_dag.py
[2025-02-28T22:49:17.170+0000] {processor.py:208} INFO - Processing /opt/airflow/dags/__pycache__/fire_incidents_dag.py took 0.040 seconds
[2025-02-28T22:49:47.670+0000] {processor.py:186} INFO - Started process (PID=364) to work on /opt/airflow/dags/__pycache__/fire_incidents_dag.py
[2025-02-28T22:49:47.672+0000] {processor.py:914} INFO - Processing file /opt/airflow/dags/__pycache__/fire_incidents_dag.py for tasks to queue
[2025-02-28T22:49:47.675+0000] {logging_mixin.py:190} INFO - [2025-02-28T22:49:47.674+0000] {dagbag.py:588} INFO - Filling up the DagBag from /opt/airflow/dags/__pycache__/fire_incidents_dag.py
[2025-02-28T22:49:47.678+0000] {logging_mixin.py:190} INFO - [2025-02-28T22:49:47.677+0000] {dagbag.py:387} ERROR - Failed to import: /opt/airflow/dags/__pycache__/fire_incidents_dag.py
Traceback (most recent call last):
  File "/home/airflow/.local/lib/python3.12/site-packages/airflow/models/dagbag.py", line 383, in parse
    loader.exec_module(new_module)
  File "<frozen importlib._bootstrap_external>", line 999, in exec_module
  File "<frozen importlib._bootstrap>", line 488, in _call_with_frames_removed
  File "/opt/airflow/dags/__pycache__/fire_incidents_dag.py", line 4, in <module>
    from pull_fire_incidents import pull_data_via_api
ModuleNotFoundError: No module named 'pull_fire_incidents'
[2025-02-28T22:49:47.679+0000] {processor.py:927} WARNING - No viable dags retrieved from /opt/airflow/dags/__pycache__/fire_incidents_dag.py
[2025-02-28T22:49:47.703+0000] {processor.py:208} INFO - Processing /opt/airflow/dags/__pycache__/fire_incidents_dag.py took 0.039 seconds
[2025-02-28T22:50:18.375+0000] {processor.py:186} INFO - Started process (PID=428) to work on /opt/airflow/dags/__pycache__/fire_incidents_dag.py
[2025-02-28T22:50:18.376+0000] {processor.py:914} INFO - Processing file /opt/airflow/dags/__pycache__/fire_incidents_dag.py for tasks to queue
[2025-02-28T22:50:18.381+0000] {logging_mixin.py:190} INFO - [2025-02-28T22:50:18.380+0000] {dagbag.py:588} INFO - Filling up the DagBag from /opt/airflow/dags/__pycache__/fire_incidents_dag.py
[2025-02-28T22:50:18.389+0000] {logging_mixin.py:190} INFO - [2025-02-28T22:50:18.386+0000] {dagbag.py:387} ERROR - Failed to import: /opt/airflow/dags/__pycache__/fire_incidents_dag.py
Traceback (most recent call last):
  File "/home/airflow/.local/lib/python3.12/site-packages/airflow/models/dagbag.py", line 383, in parse
    loader.exec_module(new_module)
  File "<frozen importlib._bootstrap_external>", line 999, in exec_module
  File "<frozen importlib._bootstrap>", line 488, in _call_with_frames_removed
  File "/opt/airflow/dags/__pycache__/fire_incidents_dag.py", line 4, in <module>
    from pull_fire_incidents import pull_data_via_api
ModuleNotFoundError: No module named 'pull_fire_incidents'
[2025-02-28T22:50:18.390+0000] {processor.py:927} WARNING - No viable dags retrieved from /opt/airflow/dags/__pycache__/fire_incidents_dag.py
[2025-02-28T22:50:18.456+0000] {processor.py:208} INFO - Processing /opt/airflow/dags/__pycache__/fire_incidents_dag.py took 0.238 seconds
[2025-02-28T22:50:49.326+0000] {processor.py:186} INFO - Started process (PID=492) to work on /opt/airflow/dags/__pycache__/fire_incidents_dag.py
[2025-02-28T22:50:49.327+0000] {processor.py:914} INFO - Processing file /opt/airflow/dags/__pycache__/fire_incidents_dag.py for tasks to queue
[2025-02-28T22:50:49.329+0000] {logging_mixin.py:190} INFO - [2025-02-28T22:50:49.329+0000] {dagbag.py:588} INFO - Filling up the DagBag from /opt/airflow/dags/__pycache__/fire_incidents_dag.py
[2025-02-28T22:50:49.332+0000] {logging_mixin.py:190} INFO - [2025-02-28T22:50:49.331+0000] {dagbag.py:387} ERROR - Failed to import: /opt/airflow/dags/__pycache__/fire_incidents_dag.py
Traceback (most recent call last):
  File "/home/airflow/.local/lib/python3.12/site-packages/airflow/models/dagbag.py", line 383, in parse
    loader.exec_module(new_module)
  File "<frozen importlib._bootstrap_external>", line 999, in exec_module
  File "<frozen importlib._bootstrap>", line 488, in _call_with_frames_removed
  File "/opt/airflow/dags/__pycache__/fire_incidents_dag.py", line 4, in <module>
    from pull_fire_incidents import pull_data_via_api
ModuleNotFoundError: No module named 'pull_fire_incidents'
[2025-02-28T22:50:49.333+0000] {processor.py:927} WARNING - No viable dags retrieved from /opt/airflow/dags/__pycache__/fire_incidents_dag.py
[2025-02-28T22:50:49.349+0000] {processor.py:208} INFO - Processing /opt/airflow/dags/__pycache__/fire_incidents_dag.py took 0.028 seconds
[2025-02-28T22:52:20.499+0000] {processor.py:186} INFO - Started process (PID=44) to work on /opt/airflow/dags/__pycache__/fire_incidents_dag.py
[2025-02-28T22:52:20.500+0000] {processor.py:914} INFO - Processing file /opt/airflow/dags/__pycache__/fire_incidents_dag.py for tasks to queue
[2025-02-28T22:52:20.502+0000] {logging_mixin.py:190} INFO - [2025-02-28T22:52:20.502+0000] {dagbag.py:588} INFO - Filling up the DagBag from /opt/airflow/dags/__pycache__/fire_incidents_dag.py
[2025-02-28T22:52:20.508+0000] {logging_mixin.py:190} INFO - [2025-02-28T22:52:20.507+0000] {dagbag.py:387} ERROR - Failed to import: /opt/airflow/dags/__pycache__/fire_incidents_dag.py
Traceback (most recent call last):
  File "/home/airflow/.local/lib/python3.12/site-packages/airflow/models/dagbag.py", line 383, in parse
    loader.exec_module(new_module)
  File "<frozen importlib._bootstrap_external>", line 999, in exec_module
  File "<frozen importlib._bootstrap>", line 488, in _call_with_frames_removed
  File "/opt/airflow/dags/__pycache__/fire_incidents_dag.py", line 4, in <module>
    from pull_fire_incidents import pull_data_via_api
ModuleNotFoundError: No module named 'pull_fire_incidents'
[2025-02-28T22:52:20.508+0000] {processor.py:927} WARNING - No viable dags retrieved from /opt/airflow/dags/__pycache__/fire_incidents_dag.py
[2025-02-28T22:52:20.523+0000] {processor.py:208} INFO - Processing /opt/airflow/dags/__pycache__/fire_incidents_dag.py took 0.028 seconds
[2025-02-28T22:52:50.863+0000] {processor.py:186} INFO - Started process (PID=108) to work on /opt/airflow/dags/__pycache__/fire_incidents_dag.py
[2025-02-28T22:52:50.867+0000] {processor.py:914} INFO - Processing file /opt/airflow/dags/__pycache__/fire_incidents_dag.py for tasks to queue
[2025-02-28T22:52:50.869+0000] {logging_mixin.py:190} INFO - [2025-02-28T22:52:50.869+0000] {dagbag.py:588} INFO - Filling up the DagBag from /opt/airflow/dags/__pycache__/fire_incidents_dag.py
[2025-02-28T22:52:50.871+0000] {logging_mixin.py:190} INFO - [2025-02-28T22:52:50.870+0000] {dagbag.py:387} ERROR - Failed to import: /opt/airflow/dags/__pycache__/fire_incidents_dag.py
Traceback (most recent call last):
  File "/home/airflow/.local/lib/python3.12/site-packages/airflow/models/dagbag.py", line 383, in parse
    loader.exec_module(new_module)
  File "<frozen importlib._bootstrap_external>", line 999, in exec_module
  File "<frozen importlib._bootstrap>", line 488, in _call_with_frames_removed
  File "/opt/airflow/dags/__pycache__/fire_incidents_dag.py", line 4, in <module>
    from pull_fire_incidents import pull_data_via_api
ModuleNotFoundError: No module named 'pull_fire_incidents'
[2025-02-28T22:52:50.872+0000] {processor.py:927} WARNING - No viable dags retrieved from /opt/airflow/dags/__pycache__/fire_incidents_dag.py
[2025-02-28T22:52:51.000+0000] {processor.py:208} INFO - Processing /opt/airflow/dags/__pycache__/fire_incidents_dag.py took 0.142 seconds
[2025-02-28T22:58:50.484+0000] {processor.py:186} INFO - Started process (PID=44) to work on /opt/airflow/dags/__pycache__/fire_incidents_dag.py
[2025-02-28T22:58:50.486+0000] {processor.py:914} INFO - Processing file /opt/airflow/dags/__pycache__/fire_incidents_dag.py for tasks to queue
[2025-02-28T22:58:50.494+0000] {logging_mixin.py:190} INFO - [2025-02-28T22:58:50.493+0000] {dagbag.py:588} INFO - Filling up the DagBag from /opt/airflow/dags/__pycache__/fire_incidents_dag.py
[2025-02-28T22:58:50.509+0000] {logging_mixin.py:190} INFO - [2025-02-28T22:58:50.506+0000] {dagbag.py:387} ERROR - Failed to import: /opt/airflow/dags/__pycache__/fire_incidents_dag.py
Traceback (most recent call last):
  File "/home/airflow/.local/lib/python3.12/site-packages/airflow/models/dagbag.py", line 383, in parse
    loader.exec_module(new_module)
  File "<frozen importlib._bootstrap_external>", line 999, in exec_module
  File "<frozen importlib._bootstrap>", line 488, in _call_with_frames_removed
  File "/opt/airflow/dags/__pycache__/fire_incidents_dag.py", line 4, in <module>
    from pull_fire_incidents import pull_data_via_api
ModuleNotFoundError: No module named 'pull_fire_incidents'
[2025-02-28T22:58:50.510+0000] {processor.py:927} WARNING - No viable dags retrieved from /opt/airflow/dags/__pycache__/fire_incidents_dag.py
[2025-02-28T22:58:50.572+0000] {processor.py:208} INFO - Processing /opt/airflow/dags/__pycache__/fire_incidents_dag.py took 0.120 seconds
[2025-02-28T22:59:20.667+0000] {processor.py:186} INFO - Started process (PID=109) to work on /opt/airflow/dags/__pycache__/fire_incidents_dag.py
[2025-02-28T22:59:20.669+0000] {processor.py:914} INFO - Processing file /opt/airflow/dags/__pycache__/fire_incidents_dag.py for tasks to queue
[2025-02-28T22:59:20.672+0000] {logging_mixin.py:190} INFO - [2025-02-28T22:59:20.672+0000] {dagbag.py:588} INFO - Filling up the DagBag from /opt/airflow/dags/__pycache__/fire_incidents_dag.py
[2025-02-28T22:59:20.676+0000] {logging_mixin.py:190} INFO - [2025-02-28T22:59:20.675+0000] {dagbag.py:387} ERROR - Failed to import: /opt/airflow/dags/__pycache__/fire_incidents_dag.py
Traceback (most recent call last):
  File "/home/airflow/.local/lib/python3.12/site-packages/airflow/models/dagbag.py", line 383, in parse
    loader.exec_module(new_module)
  File "<frozen importlib._bootstrap_external>", line 999, in exec_module
  File "<frozen importlib._bootstrap>", line 488, in _call_with_frames_removed
  File "/opt/airflow/dags/__pycache__/fire_incidents_dag.py", line 4, in <module>
    from pull_fire_incidents import pull_data_via_api
ModuleNotFoundError: No module named 'pull_fire_incidents'
[2025-02-28T22:59:20.676+0000] {processor.py:927} WARNING - No viable dags retrieved from /opt/airflow/dags/__pycache__/fire_incidents_dag.py
[2025-02-28T22:59:20.703+0000] {processor.py:208} INFO - Processing /opt/airflow/dags/__pycache__/fire_incidents_dag.py took 0.046 seconds
[2025-02-28T23:20:33.404+0000] {processor.py:186} INFO - Started process (PID=44) to work on /opt/airflow/dags/__pycache__/fire_incidents_dag.py
[2025-02-28T23:20:33.405+0000] {processor.py:914} INFO - Processing file /opt/airflow/dags/__pycache__/fire_incidents_dag.py for tasks to queue
[2025-02-28T23:20:33.407+0000] {logging_mixin.py:190} INFO - [2025-02-28T23:20:33.407+0000] {dagbag.py:588} INFO - Filling up the DagBag from /opt/airflow/dags/__pycache__/fire_incidents_dag.py
[2025-02-28T23:20:33.413+0000] {logging_mixin.py:190} INFO - [2025-02-28T23:20:33.412+0000] {dagbag.py:387} ERROR - Failed to import: /opt/airflow/dags/__pycache__/fire_incidents_dag.py
Traceback (most recent call last):
  File "/home/airflow/.local/lib/python3.12/site-packages/airflow/models/dagbag.py", line 383, in parse
    loader.exec_module(new_module)
  File "<frozen importlib._bootstrap_external>", line 999, in exec_module
  File "<frozen importlib._bootstrap>", line 488, in _call_with_frames_removed
  File "/opt/airflow/dags/__pycache__/fire_incidents_dag.py", line 4, in <module>
    from pull_fire_incidents import pull_data_via_api
ModuleNotFoundError: No module named 'pull_fire_incidents'
[2025-02-28T23:20:33.413+0000] {processor.py:927} WARNING - No viable dags retrieved from /opt/airflow/dags/__pycache__/fire_incidents_dag.py
[2025-02-28T23:20:33.436+0000] {processor.py:208} INFO - Processing /opt/airflow/dags/__pycache__/fire_incidents_dag.py took 0.037 seconds
[2025-02-28T23:21:04.302+0000] {processor.py:186} INFO - Started process (PID=108) to work on /opt/airflow/dags/__pycache__/fire_incidents_dag.py
[2025-02-28T23:21:04.303+0000] {processor.py:914} INFO - Processing file /opt/airflow/dags/__pycache__/fire_incidents_dag.py for tasks to queue
[2025-02-28T23:21:04.305+0000] {logging_mixin.py:190} INFO - [2025-02-28T23:21:04.304+0000] {dagbag.py:588} INFO - Filling up the DagBag from /opt/airflow/dags/__pycache__/fire_incidents_dag.py
[2025-02-28T23:21:04.307+0000] {logging_mixin.py:190} INFO - [2025-02-28T23:21:04.306+0000] {dagbag.py:387} ERROR - Failed to import: /opt/airflow/dags/__pycache__/fire_incidents_dag.py
Traceback (most recent call last):
  File "/home/airflow/.local/lib/python3.12/site-packages/airflow/models/dagbag.py", line 383, in parse
    loader.exec_module(new_module)
  File "<frozen importlib._bootstrap_external>", line 999, in exec_module
  File "<frozen importlib._bootstrap>", line 488, in _call_with_frames_removed
  File "/opt/airflow/dags/__pycache__/fire_incidents_dag.py", line 4, in <module>
    from pull_fire_incidents import pull_data_via_api
ModuleNotFoundError: No module named 'pull_fire_incidents'
[2025-02-28T23:21:04.307+0000] {processor.py:927} WARNING - No viable dags retrieved from /opt/airflow/dags/__pycache__/fire_incidents_dag.py
[2025-02-28T23:21:04.322+0000] {processor.py:208} INFO - Processing /opt/airflow/dags/__pycache__/fire_incidents_dag.py took 0.025 seconds
[2025-02-28T23:21:34.610+0000] {processor.py:186} INFO - Started process (PID=172) to work on /opt/airflow/dags/__pycache__/fire_incidents_dag.py
[2025-02-28T23:21:34.612+0000] {processor.py:914} INFO - Processing file /opt/airflow/dags/__pycache__/fire_incidents_dag.py for tasks to queue
[2025-02-28T23:21:34.616+0000] {logging_mixin.py:190} INFO - [2025-02-28T23:21:34.615+0000] {dagbag.py:588} INFO - Filling up the DagBag from /opt/airflow/dags/__pycache__/fire_incidents_dag.py
[2025-02-28T23:21:34.621+0000] {logging_mixin.py:190} INFO - [2025-02-28T23:21:34.619+0000] {dagbag.py:387} ERROR - Failed to import: /opt/airflow/dags/__pycache__/fire_incidents_dag.py
Traceback (most recent call last):
  File "/home/airflow/.local/lib/python3.12/site-packages/airflow/models/dagbag.py", line 383, in parse
    loader.exec_module(new_module)
  File "<frozen importlib._bootstrap_external>", line 999, in exec_module
  File "<frozen importlib._bootstrap>", line 488, in _call_with_frames_removed
  File "/opt/airflow/dags/__pycache__/fire_incidents_dag.py", line 4, in <module>
    from pull_fire_incidents import pull_data_via_api
ModuleNotFoundError: No module named 'pull_fire_incidents'
[2025-02-28T23:21:34.622+0000] {processor.py:927} WARNING - No viable dags retrieved from /opt/airflow/dags/__pycache__/fire_incidents_dag.py
[2025-02-28T23:21:34.644+0000] {processor.py:208} INFO - Processing /opt/airflow/dags/__pycache__/fire_incidents_dag.py took 0.044 seconds
[2025-02-28T23:22:06.213+0000] {processor.py:186} INFO - Started process (PID=236) to work on /opt/airflow/dags/__pycache__/fire_incidents_dag.py
[2025-02-28T23:22:06.216+0000] {processor.py:914} INFO - Processing file /opt/airflow/dags/__pycache__/fire_incidents_dag.py for tasks to queue
[2025-02-28T23:22:06.256+0000] {logging_mixin.py:190} INFO - [2025-02-28T23:22:06.255+0000] {dagbag.py:588} INFO - Filling up the DagBag from /opt/airflow/dags/__pycache__/fire_incidents_dag.py
[2025-02-28T23:22:06.508+0000] {logging_mixin.py:190} INFO - [2025-02-28T23:22:06.496+0000] {dagbag.py:387} ERROR - Failed to import: /opt/airflow/dags/__pycache__/fire_incidents_dag.py
Traceback (most recent call last):
  File "/home/airflow/.local/lib/python3.12/site-packages/airflow/models/dagbag.py", line 383, in parse
    loader.exec_module(new_module)
  File "<frozen importlib._bootstrap_external>", line 999, in exec_module
  File "<frozen importlib._bootstrap>", line 488, in _call_with_frames_removed
  File "/opt/airflow/dags/__pycache__/fire_incidents_dag.py", line 4, in <module>
    from pull_fire_incidents import pull_data_via_api
ModuleNotFoundError: No module named 'pull_fire_incidents'
[2025-02-28T23:22:06.509+0000] {processor.py:927} WARNING - No viable dags retrieved from /opt/airflow/dags/__pycache__/fire_incidents_dag.py
[2025-02-28T23:22:20.200+0000] {processor.py:208} INFO - Processing /opt/airflow/dags/__pycache__/fire_incidents_dag.py took 14.566 seconds
[2025-02-28T23:22:50.563+0000] {processor.py:186} INFO - Started process (PID=300) to work on /opt/airflow/dags/__pycache__/fire_incidents_dag.py
[2025-02-28T23:22:50.564+0000] {processor.py:914} INFO - Processing file /opt/airflow/dags/__pycache__/fire_incidents_dag.py for tasks to queue
[2025-02-28T23:22:50.569+0000] {logging_mixin.py:190} INFO - [2025-02-28T23:22:50.568+0000] {dagbag.py:588} INFO - Filling up the DagBag from /opt/airflow/dags/__pycache__/fire_incidents_dag.py
[2025-02-28T23:22:50.576+0000] {logging_mixin.py:190} INFO - [2025-02-28T23:22:50.574+0000] {dagbag.py:387} ERROR - Failed to import: /opt/airflow/dags/__pycache__/fire_incidents_dag.py
Traceback (most recent call last):
  File "/home/airflow/.local/lib/python3.12/site-packages/airflow/models/dagbag.py", line 383, in parse
    loader.exec_module(new_module)
  File "<frozen importlib._bootstrap_external>", line 999, in exec_module
  File "<frozen importlib._bootstrap>", line 488, in _call_with_frames_removed
  File "/opt/airflow/dags/__pycache__/fire_incidents_dag.py", line 4, in <module>
    from pull_fire_incidents import pull_data_via_api
ModuleNotFoundError: No module named 'pull_fire_incidents'
[2025-02-28T23:22:50.577+0000] {processor.py:927} WARNING - No viable dags retrieved from /opt/airflow/dags/__pycache__/fire_incidents_dag.py
[2025-02-28T23:22:50.610+0000] {processor.py:208} INFO - Processing /opt/airflow/dags/__pycache__/fire_incidents_dag.py took 0.068 seconds
[2025-02-28T23:23:21.430+0000] {processor.py:186} INFO - Started process (PID=370) to work on /opt/airflow/dags/__pycache__/fire_incidents_dag.py
[2025-02-28T23:23:21.432+0000] {processor.py:914} INFO - Processing file /opt/airflow/dags/__pycache__/fire_incidents_dag.py for tasks to queue
[2025-02-28T23:23:21.435+0000] {logging_mixin.py:190} INFO - [2025-02-28T23:23:21.435+0000] {dagbag.py:588} INFO - Filling up the DagBag from /opt/airflow/dags/__pycache__/fire_incidents_dag.py
[2025-02-28T23:23:21.439+0000] {logging_mixin.py:190} INFO - [2025-02-28T23:23:21.438+0000] {dagbag.py:387} ERROR - Failed to import: /opt/airflow/dags/__pycache__/fire_incidents_dag.py
Traceback (most recent call last):
  File "/home/airflow/.local/lib/python3.12/site-packages/airflow/models/dagbag.py", line 383, in parse
    loader.exec_module(new_module)
  File "<frozen importlib._bootstrap_external>", line 999, in exec_module
  File "<frozen importlib._bootstrap>", line 488, in _call_with_frames_removed
  File "/opt/airflow/dags/__pycache__/fire_incidents_dag.py", line 4, in <module>
    from pull_fire_incidents import pull_data_via_api
ModuleNotFoundError: No module named 'pull_fire_incidents'
[2025-02-28T23:23:21.440+0000] {processor.py:927} WARNING - No viable dags retrieved from /opt/airflow/dags/__pycache__/fire_incidents_dag.py
[2025-02-28T23:23:21.460+0000] {processor.py:208} INFO - Processing /opt/airflow/dags/__pycache__/fire_incidents_dag.py took 0.039 seconds
[2025-02-28T23:23:52.043+0000] {processor.py:186} INFO - Started process (PID=434) to work on /opt/airflow/dags/__pycache__/fire_incidents_dag.py
[2025-02-28T23:23:52.044+0000] {processor.py:914} INFO - Processing file /opt/airflow/dags/__pycache__/fire_incidents_dag.py for tasks to queue
[2025-02-28T23:23:52.046+0000] {logging_mixin.py:190} INFO - [2025-02-28T23:23:52.046+0000] {dagbag.py:588} INFO - Filling up the DagBag from /opt/airflow/dags/__pycache__/fire_incidents_dag.py
[2025-02-28T23:23:52.049+0000] {logging_mixin.py:190} INFO - [2025-02-28T23:23:52.048+0000] {dagbag.py:387} ERROR - Failed to import: /opt/airflow/dags/__pycache__/fire_incidents_dag.py
Traceback (most recent call last):
  File "/home/airflow/.local/lib/python3.12/site-packages/airflow/models/dagbag.py", line 383, in parse
    loader.exec_module(new_module)
  File "<frozen importlib._bootstrap_external>", line 999, in exec_module
  File "<frozen importlib._bootstrap>", line 488, in _call_with_frames_removed
  File "/opt/airflow/dags/__pycache__/fire_incidents_dag.py", line 4, in <module>
    from pull_fire_incidents import pull_data_via_api
ModuleNotFoundError: No module named 'pull_fire_incidents'
[2025-02-28T23:23:52.049+0000] {processor.py:927} WARNING - No viable dags retrieved from /opt/airflow/dags/__pycache__/fire_incidents_dag.py
[2025-02-28T23:23:52.079+0000] {processor.py:208} INFO - Processing /opt/airflow/dags/__pycache__/fire_incidents_dag.py took 0.041 seconds
