[2025-03-05T22:22:55.420+0000] {local_task_job_runner.py:123} INFO - ::group::Pre task execution logs
[2025-03-05T22:22:55.435+0000] {taskinstance.py:2614} INFO - Dependencies all met for dep_context=non-requeueable deps ti=<TaskInstance: task_etl_fire_incident_using_bash.task_etl_fire_incident_using_bash manual__2025-03-05T22:15:56.814914+00:00 [queued]>
[2025-03-05T22:22:55.443+0000] {taskinstance.py:2614} INFO - Dependencies all met for dep_context=requeueable deps ti=<TaskInstance: task_etl_fire_incident_using_bash.task_etl_fire_incident_using_bash manual__2025-03-05T22:15:56.814914+00:00 [queued]>
[2025-03-05T22:22:55.443+0000] {taskinstance.py:2867} INFO - Starting attempt 2 of 2
[2025-03-05T22:22:55.455+0000] {taskinstance.py:2890} INFO - Executing <Task(BashOperator): task_etl_fire_incident_using_bash> on 2025-03-05 22:15:56.814914+00:00
[2025-03-05T22:22:55.461+0000] {warnings.py:112} WARNING - /home/***/.local/lib/python3.12/site-packages/***/task/task_runner/standard_task_runner.py:70: DeprecationWarning: This process (pid=63) is multi-threaded, use of fork() may lead to deadlocks in the child.
  pid = os.fork()

[2025-03-05T22:22:55.463+0000] {standard_task_runner.py:72} INFO - Started process 72 to run task
[2025-03-05T22:22:55.463+0000] {standard_task_runner.py:104} INFO - Running: ['***', 'tasks', 'run', 'task_etl_fire_incident_using_bash', 'task_etl_fire_incident_using_bash', 'manual__2025-03-05T22:15:56.814914+00:00', '--job-id', '274', '--raw', '--subdir', 'DAGS_FOLDER/fire_incidents_dag.py', '--cfg-path', '/tmp/tmp2_88sqw1']
[2025-03-05T22:22:55.464+0000] {standard_task_runner.py:105} INFO - Job 274: Subtask task_etl_fire_incident_using_bash
[2025-03-05T22:22:55.500+0000] {task_command.py:467} INFO - Running <TaskInstance: task_etl_fire_incident_using_bash.task_etl_fire_incident_using_bash manual__2025-03-05T22:15:56.814914+00:00 [running]> on host 5848e088075f
[2025-03-05T22:22:55.581+0000] {taskinstance.py:3134} INFO - Exporting env vars: AIRFLOW_CTX_DAG_EMAIL='***@***.com' AIRFLOW_CTX_DAG_OWNER='***' AIRFLOW_CTX_DAG_ID='task_etl_fire_incident_using_bash' AIRFLOW_CTX_TASK_ID='task_etl_fire_incident_using_bash' AIRFLOW_CTX_EXECUTION_DATE='2025-03-05T22:15:56.814914+00:00' AIRFLOW_CTX_TRY_NUMBER='2' AIRFLOW_CTX_DAG_RUN_ID='manual__2025-03-05T22:15:56.814914+00:00'
[2025-03-05T22:22:55.583+0000] {logging_mixin.py:190} INFO - Task instance is in running state
[2025-03-05T22:22:55.583+0000] {logging_mixin.py:190} INFO -  Previous state of the Task instance: queued
[2025-03-05T22:22:55.583+0000] {logging_mixin.py:190} INFO - Current task name:task_etl_fire_incident_using_bash state:running start_date:2025-03-05 22:22:55.435735+00:00
[2025-03-05T22:22:55.583+0000] {logging_mixin.py:190} INFO - Dag name:task_etl_fire_incident_using_bash and current dag run status:running
[2025-03-05T22:22:55.584+0000] {taskinstance.py:732} INFO - ::endgroup::
[2025-03-05T22:22:55.584+0000] {subprocess.py:78} INFO - Tmp dir root location: /tmp
[2025-03-05T22:22:55.585+0000] {subprocess.py:88} INFO - Running command: ['/usr/bin/bash', '-c', 'docker ps']
[2025-03-05T22:22:55.599+0000] {subprocess.py:99} INFO - Output:
[2025-03-05T22:22:55.631+0000] {subprocess.py:106} INFO - permission denied while trying to connect to the Docker daemon socket at unix:///var/run/docker.sock: Get "http://%2Fvar%2Frun%2Fdocker.sock/v1.47/containers/json": dial unix /var/run/docker.sock: connect: permission denied
[2025-03-05T22:22:55.632+0000] {subprocess.py:110} INFO - Command exited with return code 1
[2025-03-05T22:22:55.640+0000] {taskinstance.py:3313} ERROR - Task failed with exception
Traceback (most recent call last):
  File "/home/airflow/.local/lib/python3.12/site-packages/airflow/models/taskinstance.py", line 768, in _execute_task
    result = _execute_callable(context=context, **execute_callable_kwargs)
             ^^^^^^^^^^^^^^^^^^^^^^^^^^^^^^^^^^^^^^^^^^^^^^^^^^^^^^^^^^^^^
  File "/home/airflow/.local/lib/python3.12/site-packages/airflow/models/taskinstance.py", line 734, in _execute_callable
    return ExecutionCallableRunner(
           ^^^^^^^^^^^^^^^^^^^^^^^^
  File "/home/airflow/.local/lib/python3.12/site-packages/airflow/utils/operator_helpers.py", line 252, in run
    return self.func(*args, **kwargs)
           ^^^^^^^^^^^^^^^^^^^^^^^^^^
  File "/home/airflow/.local/lib/python3.12/site-packages/airflow/models/baseoperator.py", line 424, in wrapper
    return func(self, *args, **kwargs)
           ^^^^^^^^^^^^^^^^^^^^^^^^^^^
  File "/home/airflow/.local/lib/python3.12/site-packages/airflow/operators/bash.py", line 276, in execute
    raise AirflowException(
airflow.exceptions.AirflowException: Bash command failed. The command returned a non-zero exit code 1.
[2025-03-05T22:22:55.644+0000] {logging_mixin.py:190} INFO - Task instance in failure state
[2025-03-05T22:22:55.645+0000] {logging_mixin.py:190} INFO - Task start:2025-03-05 22:22:55.435735+00:00 end:2025-03-05 22:22:55.644331+00:00 duration:0.208596
[2025-03-05T22:22:55.645+0000] {logging_mixin.py:190} INFO - Task:<Task(BashOperator): task_etl_fire_incident_using_bash> dag:<DAG: task_etl_fire_incident_using_bash> dagrun:<DagRun task_etl_fire_incident_using_bash @ 2025-03-05 22:15:56.814914+00:00: manual__2025-03-05T22:15:56.814914+00:00, state:running, queued_at: 2025-03-05 22:15:56.827216+00:00. externally triggered: True>
[2025-03-05T22:22:55.645+0000] {logging_mixin.py:190} INFO - Failure caused by Bash command failed. The command returned a non-zero exit code 1.
[2025-03-05T22:22:55.645+0000] {taskinstance.py:1226} INFO - Marking task as FAILED. dag_id=task_etl_fire_incident_using_bash, task_id=task_etl_fire_incident_using_bash, run_id=manual__2025-03-05T22:15:56.814914+00:00, execution_date=20250305T221556, start_date=20250305T222255, end_date=20250305T222255
[2025-03-05T22:22:55.668+0000] {taskinstance.py:341} INFO - ::group::Post task execution logs
[2025-03-05T22:22:55.669+0000] {standard_task_runner.py:124} ERROR - Failed to execute job 274 for task task_etl_fire_incident_using_bash (Bash command failed. The command returned a non-zero exit code 1.; 72)
Traceback (most recent call last):
  File "/home/airflow/.local/lib/python3.12/site-packages/airflow/task/task_runner/standard_task_runner.py", line 117, in _start_by_fork
    ret = args.func(args, dag=self.dag)
          ^^^^^^^^^^^^^^^^^^^^^^^^^^^^^
  File "/home/airflow/.local/lib/python3.12/site-packages/airflow/cli/cli_config.py", line 49, in command
    return func(*args, **kwargs)
           ^^^^^^^^^^^^^^^^^^^^^
  File "/home/airflow/.local/lib/python3.12/site-packages/airflow/utils/cli.py", line 116, in wrapper
    return f(*args, **kwargs)
           ^^^^^^^^^^^^^^^^^^
  File "/home/airflow/.local/lib/python3.12/site-packages/airflow/cli/commands/task_command.py", line 483, in task_run
    task_return_code = _run_task_by_selected_method(args, _dag, ti)
                       ^^^^^^^^^^^^^^^^^^^^^^^^^^^^^^^^^^^^^^^^^^^^
  File "/home/airflow/.local/lib/python3.12/site-packages/airflow/cli/commands/task_command.py", line 256, in _run_task_by_selected_method
    return _run_raw_task(args, ti)
           ^^^^^^^^^^^^^^^^^^^^^^^
  File "/home/airflow/.local/lib/python3.12/site-packages/airflow/cli/commands/task_command.py", line 341, in _run_raw_task
    return ti._run_raw_task(
           ^^^^^^^^^^^^^^^^^
  File "/home/airflow/.local/lib/python3.12/site-packages/airflow/utils/session.py", line 97, in wrapper
    return func(*args, session=session, **kwargs)
           ^^^^^^^^^^^^^^^^^^^^^^^^^^^^^^^^^^^^^^
  File "/home/airflow/.local/lib/python3.12/site-packages/airflow/models/taskinstance.py", line 3006, in _run_raw_task
    return _run_raw_task(
           ^^^^^^^^^^^^^^
  File "/home/airflow/.local/lib/python3.12/site-packages/airflow/models/taskinstance.py", line 274, in _run_raw_task
    TaskInstance._execute_task_with_callbacks(
  File "/home/airflow/.local/lib/python3.12/site-packages/airflow/models/taskinstance.py", line 3161, in _execute_task_with_callbacks
    result = self._execute_task(context, task_orig)
             ^^^^^^^^^^^^^^^^^^^^^^^^^^^^^^^^^^^^^^
  File "/home/airflow/.local/lib/python3.12/site-packages/airflow/models/taskinstance.py", line 3185, in _execute_task
    return _execute_task(self, context, task_orig)
           ^^^^^^^^^^^^^^^^^^^^^^^^^^^^^^^^^^^^^^^
  File "/home/airflow/.local/lib/python3.12/site-packages/airflow/models/taskinstance.py", line 768, in _execute_task
    result = _execute_callable(context=context, **execute_callable_kwargs)
             ^^^^^^^^^^^^^^^^^^^^^^^^^^^^^^^^^^^^^^^^^^^^^^^^^^^^^^^^^^^^^
  File "/home/airflow/.local/lib/python3.12/site-packages/airflow/models/taskinstance.py", line 734, in _execute_callable
    return ExecutionCallableRunner(
           ^^^^^^^^^^^^^^^^^^^^^^^^
  File "/home/airflow/.local/lib/python3.12/site-packages/airflow/utils/operator_helpers.py", line 252, in run
    return self.func(*args, **kwargs)
           ^^^^^^^^^^^^^^^^^^^^^^^^^^
  File "/home/airflow/.local/lib/python3.12/site-packages/airflow/models/baseoperator.py", line 424, in wrapper
    return func(self, *args, **kwargs)
           ^^^^^^^^^^^^^^^^^^^^^^^^^^^
  File "/home/airflow/.local/lib/python3.12/site-packages/airflow/operators/bash.py", line 276, in execute
    raise AirflowException(
airflow.exceptions.AirflowException: Bash command failed. The command returned a non-zero exit code 1.
[2025-03-05T22:22:55.717+0000] {local_task_job_runner.py:266} INFO - Task exited with return code 1
[2025-03-05T22:22:55.731+0000] {taskinstance.py:3901} INFO - 0 downstream tasks scheduled from follow-on schedule check
[2025-03-05T22:22:55.738+0000] {local_task_job_runner.py:245} INFO - ::endgroup::
