[2025-03-08T18:32:38.666+0000] {local_task_job_runner.py:123} INFO - ::group::Pre task execution logs
[2025-03-08T18:32:38.680+0000] {taskinstance.py:2614} INFO - Dependencies all met for dep_context=non-requeueable deps ti=<TaskInstance: etl_fire_incidents_dag.bash_data manual__2025-03-08T18:32:35.974570+00:00 [queued]>
[2025-03-08T18:32:38.686+0000] {taskinstance.py:2614} INFO - Dependencies all met for dep_context=requeueable deps ti=<TaskInstance: etl_fire_incidents_dag.bash_data manual__2025-03-08T18:32:35.974570+00:00 [queued]>
[2025-03-08T18:32:38.686+0000] {taskinstance.py:2867} INFO - Starting attempt 1 of 2
[2025-03-08T18:32:38.699+0000] {taskinstance.py:2890} INFO - Executing <Task(PythonOperator): bash_data> on 2025-03-08 18:32:35.974570+00:00
[2025-03-08T18:32:38.705+0000] {warnings.py:112} WARNING - /home/***/.local/lib/python3.12/site-packages/***/task/task_runner/standard_task_runner.py:70: DeprecationWarning: This process (pid=552) is multi-threaded, use of fork() may lead to deadlocks in the child.
  pid = os.fork()

[2025-03-08T18:32:38.707+0000] {standard_task_runner.py:72} INFO - Started process 566 to run task
[2025-03-08T18:32:38.708+0000] {standard_task_runner.py:104} INFO - Running: ['***', 'tasks', 'run', 'etl_fire_incidents_dag', 'bash_data', 'manual__2025-03-08T18:32:35.974570+00:00', '--job-id', '462', '--raw', '--subdir', 'DAGS_FOLDER/fire_incidents_dag.py', '--cfg-path', '/tmp/tmpccm4f3gu']
[2025-03-08T18:32:38.709+0000] {standard_task_runner.py:105} INFO - Job 462: Subtask bash_data
[2025-03-08T18:32:38.778+0000] {task_command.py:467} INFO - Running <TaskInstance: etl_fire_incidents_dag.bash_data manual__2025-03-08T18:32:35.974570+00:00 [running]> on host fad361e322ea
[2025-03-08T18:32:38.909+0000] {taskinstance.py:3134} INFO - Exporting env vars: AIRFLOW_CTX_DAG_EMAIL='***@***.com' AIRFLOW_CTX_DAG_OWNER='***' AIRFLOW_CTX_DAG_ID='etl_fire_incidents_dag' AIRFLOW_CTX_TASK_ID='bash_data' AIRFLOW_CTX_EXECUTION_DATE='2025-03-08T18:32:35.974570+00:00' AIRFLOW_CTX_TRY_NUMBER='1' AIRFLOW_CTX_DAG_RUN_ID='manual__2025-03-08T18:32:35.974570+00:00'
[2025-03-08T18:32:38.911+0000] {logging_mixin.py:190} INFO - Task instance is in running state
[2025-03-08T18:32:38.912+0000] {logging_mixin.py:190} INFO -  Previous state of the Task instance: queued
[2025-03-08T18:32:38.913+0000] {logging_mixin.py:190} INFO - Current task name:bash_data state:running start_date:2025-03-08 18:32:38.681144+00:00
[2025-03-08T18:32:38.913+0000] {logging_mixin.py:190} INFO - Dag name:etl_fire_incidents_dag and current dag run status:running
[2025-03-08T18:32:38.913+0000] {taskinstance.py:732} INFO - ::endgroup::
[2025-03-08T18:32:38.914+0000] {taskinstance.py:3313} ERROR - Task failed with exception
Traceback (most recent call last):
  File "/home/airflow/.local/lib/python3.12/site-packages/airflow/models/taskinstance.py", line 768, in _execute_task
    result = _execute_callable(context=context, **execute_callable_kwargs)
             ^^^^^^^^^^^^^^^^^^^^^^^^^^^^^^^^^^^^^^^^^^^^^^^^^^^^^^^^^^^^^
  File "/home/airflow/.local/lib/python3.12/site-packages/airflow/models/taskinstance.py", line 734, in _execute_callable
    return ExecutionCallableRunner(
           ^^^^^^^^^^^^^^^^^^^^^^^^
  File "/home/airflow/.local/lib/python3.12/site-packages/airflow/utils/operator_helpers.py", line 252, in run
    return self.func(*args, **kwargs)
           ^^^^^^^^^^^^^^^^^^^^^^^^^^
  File "/home/airflow/.local/lib/python3.12/site-packages/airflow/models/baseoperator.py", line 424, in wrapper
    return func(self, *args, **kwargs)
           ^^^^^^^^^^^^^^^^^^^^^^^^^^^
  File "/home/airflow/.local/lib/python3.12/site-packages/airflow/operators/python.py", line 238, in execute
    return_value = self.execute_callable()
                   ^^^^^^^^^^^^^^^^^^^^^^^
  File "/home/airflow/.local/lib/python3.12/site-packages/airflow/operators/python.py", line 256, in execute_callable
    return runner.run(*self.op_args, **self.op_kwargs)
           ^^^^^^^^^^^^^^^^^^^^^^^^^^^^^^^^^^^^^^^^^^^
  File "/home/airflow/.local/lib/python3.12/site-packages/airflow/utils/operator_helpers.py", line 252, in run
    return self.func(*args, **kwargs)
           ^^^^^^^^^^^^^^^^^^^^^^^^^^
  File "/opt/airflow/dags/pull_fire_incidents.py", line 72, in bash_function
    task_instance.xcom_push(key='push_bash_parameters', value= args)
                                                               ^^^^
NameError: name 'args' is not defined
[2025-03-08T18:32:38.935+0000] {logging_mixin.py:190} INFO - Task instance in failure state
[2025-03-08T18:32:38.935+0000] {logging_mixin.py:190} INFO - Task start:2025-03-08 18:32:38.681144+00:00 end:2025-03-08 18:32:38.935042+00:00 duration:0.253898
[2025-03-08T18:32:38.936+0000] {logging_mixin.py:190} INFO - Task:<Task(PythonOperator): bash_data> dag:<DAG: etl_fire_incidents_dag> dagrun:<DagRun etl_fire_incidents_dag @ 2025-03-08 18:32:35.974570+00:00: manual__2025-03-08T18:32:35.974570+00:00, state:running, queued_at: 2025-03-08 18:32:35.988839+00:00. externally triggered: True>
[2025-03-08T18:32:38.936+0000] {logging_mixin.py:190} INFO - Failure caused by name 'args' is not defined
[2025-03-08T18:32:38.936+0000] {taskinstance.py:1226} INFO - Marking task as UP_FOR_RETRY. dag_id=etl_fire_incidents_dag, task_id=bash_data, run_id=manual__2025-03-08T18:32:35.974570+00:00, execution_date=20250308T183235, start_date=20250308T183238, end_date=20250308T183238
[2025-03-08T18:32:38.974+0000] {taskinstance.py:341} INFO - ::group::Post task execution logs
[2025-03-08T18:32:38.975+0000] {standard_task_runner.py:124} ERROR - Failed to execute job 462 for task bash_data (name 'args' is not defined; 566)
Traceback (most recent call last):
  File "/home/airflow/.local/lib/python3.12/site-packages/airflow/task/task_runner/standard_task_runner.py", line 117, in _start_by_fork
    ret = args.func(args, dag=self.dag)
          ^^^^^^^^^^^^^^^^^^^^^^^^^^^^^
  File "/home/airflow/.local/lib/python3.12/site-packages/airflow/cli/cli_config.py", line 49, in command
    return func(*args, **kwargs)
           ^^^^^^^^^^^^^^^^^^^^^
  File "/home/airflow/.local/lib/python3.12/site-packages/airflow/utils/cli.py", line 116, in wrapper
    return f(*args, **kwargs)
           ^^^^^^^^^^^^^^^^^^
  File "/home/airflow/.local/lib/python3.12/site-packages/airflow/cli/commands/task_command.py", line 483, in task_run
    task_return_code = _run_task_by_selected_method(args, _dag, ti)
                       ^^^^^^^^^^^^^^^^^^^^^^^^^^^^^^^^^^^^^^^^^^^^
  File "/home/airflow/.local/lib/python3.12/site-packages/airflow/cli/commands/task_command.py", line 256, in _run_task_by_selected_method
    return _run_raw_task(args, ti)
           ^^^^^^^^^^^^^^^^^^^^^^^
  File "/home/airflow/.local/lib/python3.12/site-packages/airflow/cli/commands/task_command.py", line 341, in _run_raw_task
    return ti._run_raw_task(
           ^^^^^^^^^^^^^^^^^
  File "/home/airflow/.local/lib/python3.12/site-packages/airflow/utils/session.py", line 97, in wrapper
    return func(*args, session=session, **kwargs)
           ^^^^^^^^^^^^^^^^^^^^^^^^^^^^^^^^^^^^^^
  File "/home/airflow/.local/lib/python3.12/site-packages/airflow/models/taskinstance.py", line 3006, in _run_raw_task
    return _run_raw_task(
           ^^^^^^^^^^^^^^
  File "/home/airflow/.local/lib/python3.12/site-packages/airflow/models/taskinstance.py", line 274, in _run_raw_task
    TaskInstance._execute_task_with_callbacks(
  File "/home/airflow/.local/lib/python3.12/site-packages/airflow/models/taskinstance.py", line 3161, in _execute_task_with_callbacks
    result = self._execute_task(context, task_orig)
             ^^^^^^^^^^^^^^^^^^^^^^^^^^^^^^^^^^^^^^
  File "/home/airflow/.local/lib/python3.12/site-packages/airflow/models/taskinstance.py", line 3185, in _execute_task
    return _execute_task(self, context, task_orig)
           ^^^^^^^^^^^^^^^^^^^^^^^^^^^^^^^^^^^^^^^
  File "/home/airflow/.local/lib/python3.12/site-packages/airflow/models/taskinstance.py", line 768, in _execute_task
    result = _execute_callable(context=context, **execute_callable_kwargs)
             ^^^^^^^^^^^^^^^^^^^^^^^^^^^^^^^^^^^^^^^^^^^^^^^^^^^^^^^^^^^^^
  File "/home/airflow/.local/lib/python3.12/site-packages/airflow/models/taskinstance.py", line 734, in _execute_callable
    return ExecutionCallableRunner(
           ^^^^^^^^^^^^^^^^^^^^^^^^
  File "/home/airflow/.local/lib/python3.12/site-packages/airflow/utils/operator_helpers.py", line 252, in run
    return self.func(*args, **kwargs)
           ^^^^^^^^^^^^^^^^^^^^^^^^^^
  File "/home/airflow/.local/lib/python3.12/site-packages/airflow/models/baseoperator.py", line 424, in wrapper
    return func(self, *args, **kwargs)
           ^^^^^^^^^^^^^^^^^^^^^^^^^^^
  File "/home/airflow/.local/lib/python3.12/site-packages/airflow/operators/python.py", line 238, in execute
    return_value = self.execute_callable()
                   ^^^^^^^^^^^^^^^^^^^^^^^
  File "/home/airflow/.local/lib/python3.12/site-packages/airflow/operators/python.py", line 256, in execute_callable
    return runner.run(*self.op_args, **self.op_kwargs)
           ^^^^^^^^^^^^^^^^^^^^^^^^^^^^^^^^^^^^^^^^^^^
  File "/home/airflow/.local/lib/python3.12/site-packages/airflow/utils/operator_helpers.py", line 252, in run
    return self.func(*args, **kwargs)
           ^^^^^^^^^^^^^^^^^^^^^^^^^^
  File "/opt/airflow/dags/pull_fire_incidents.py", line 72, in bash_function
    task_instance.xcom_push(key='push_bash_parameters', value= args)
                                                               ^^^^
NameError: name 'args' is not defined
[2025-03-08T18:32:39.002+0000] {local_task_job_runner.py:266} INFO - Task exited with return code 1
[2025-03-08T18:32:39.022+0000] {taskinstance.py:3901} INFO - 0 downstream tasks scheduled from follow-on schedule check
[2025-03-08T18:32:39.024+0000] {local_task_job_runner.py:245} INFO - ::endgroup::
