[2025-03-08T13:51:04.358+0000] {local_task_job_runner.py:123} INFO - ::group::Pre task execution logs
[2025-03-08T13:51:04.371+0000] {taskinstance.py:2614} INFO - Dependencies all met for dep_context=non-requeueable deps ti=<TaskInstance: pull_fire_incidents_dag.task_etl_fire_incident_using_bash scheduled__2025-03-08T09:00:00+00:00 [queued]>
[2025-03-08T13:51:04.380+0000] {taskinstance.py:2614} INFO - Dependencies all met for dep_context=requeueable deps ti=<TaskInstance: pull_fire_incidents_dag.task_etl_fire_incident_using_bash scheduled__2025-03-08T09:00:00+00:00 [queued]>
[2025-03-08T13:51:04.380+0000] {taskinstance.py:2867} INFO - Starting attempt 1 of 2
[2025-03-08T13:51:04.394+0000] {taskinstance.py:2890} INFO - Executing <Task(BashOperator): task_etl_fire_incident_using_bash> on 2025-03-08 09:00:00+00:00
[2025-03-08T13:51:04.400+0000] {warnings.py:112} WARNING - /home/***/.local/lib/python3.12/site-packages/***/task/task_runner/standard_task_runner.py:70: DeprecationWarning: This process (pid=103) is multi-threaded, use of fork() may lead to deadlocks in the child.
  pid = os.fork()

[2025-03-08T13:51:04.401+0000] {standard_task_runner.py:72} INFO - Started process 105 to run task
[2025-03-08T13:51:04.401+0000] {standard_task_runner.py:104} INFO - Running: ['***', 'tasks', 'run', 'pull_fire_incidents_dag', 'task_etl_fire_incident_using_bash', 'scheduled__2025-03-08T09:00:00+00:00', '--job-id', '338', '--raw', '--subdir', 'DAGS_FOLDER/fire_incidents_dag.py', '--cfg-path', '/tmp/tmpt5hdv2sc']
[2025-03-08T13:51:04.402+0000] {standard_task_runner.py:105} INFO - Job 338: Subtask task_etl_fire_incident_using_bash
[2025-03-08T13:51:04.441+0000] {task_command.py:467} INFO - Running <TaskInstance: pull_fire_incidents_dag.task_etl_fire_incident_using_bash scheduled__2025-03-08T09:00:00+00:00 [running]> on host f4e55948dc16
[2025-03-08T13:51:04.556+0000] {taskinstance.py:3134} INFO - Exporting env vars: AIRFLOW_CTX_DAG_EMAIL='***@***.com' AIRFLOW_CTX_DAG_OWNER='***' AIRFLOW_CTX_DAG_ID='pull_fire_incidents_dag' AIRFLOW_CTX_TASK_ID='task_etl_fire_incident_using_bash' AIRFLOW_CTX_EXECUTION_DATE='2025-03-08T09:00:00+00:00' AIRFLOW_CTX_TRY_NUMBER='1' AIRFLOW_CTX_DAG_RUN_ID='scheduled__2025-03-08T09:00:00+00:00'
[2025-03-08T13:51:04.557+0000] {logging_mixin.py:190} INFO - Task instance is in running state
[2025-03-08T13:51:04.558+0000] {logging_mixin.py:190} INFO -  Previous state of the Task instance: queued
[2025-03-08T13:51:04.558+0000] {logging_mixin.py:190} INFO - Current task name:task_etl_fire_incident_using_bash state:running start_date:2025-03-08 13:51:04.372283+00:00
[2025-03-08T13:51:04.558+0000] {logging_mixin.py:190} INFO - Dag name:pull_fire_incidents_dag and current dag run status:running
[2025-03-08T13:51:04.559+0000] {taskinstance.py:732} INFO - ::endgroup::
[2025-03-08T13:51:04.560+0000] {subprocess.py:78} INFO - Tmp dir root location: /tmp
[2025-03-08T13:51:04.560+0000] {subprocess.py:88} INFO - Running command: ['/usr/bin/bash', '-c', 'docker run --rm \\--network=pg-network-fire-incidents \\nyc_fire_incidents:v001 \\--api_url=data.cityofnewyork.us \\--token=xoIfIdDlHq6gGzxqLqbUeMpsG \\--dataset_id=8m42-w767 \\--limit_rows=10000 \\--username=root \\--password=root \\--host_name=fire_incidents_db_container \\--port=5432 \\--database=fire_incidents_db \\--tbl_name=fire_incidents_tbl']
[2025-03-08T13:51:04.572+0000] {subprocess.py:99} INFO - Output:
[2025-03-08T13:51:04.710+0000] {subprocess.py:106} INFO - docker: Cannot connect to the Docker daemon at unix:///var/run/docker.sock. Is the docker daemon running?.
[2025-03-08T13:51:04.710+0000] {subprocess.py:106} INFO - See 'docker run --help'.
[2025-03-08T13:51:04.711+0000] {subprocess.py:110} INFO - Command exited with return code 125
[2025-03-08T13:51:04.719+0000] {taskinstance.py:3313} ERROR - Task failed with exception
Traceback (most recent call last):
  File "/home/airflow/.local/lib/python3.12/site-packages/airflow/models/taskinstance.py", line 768, in _execute_task
    result = _execute_callable(context=context, **execute_callable_kwargs)
             ^^^^^^^^^^^^^^^^^^^^^^^^^^^^^^^^^^^^^^^^^^^^^^^^^^^^^^^^^^^^^
  File "/home/airflow/.local/lib/python3.12/site-packages/airflow/models/taskinstance.py", line 734, in _execute_callable
    return ExecutionCallableRunner(
           ^^^^^^^^^^^^^^^^^^^^^^^^
  File "/home/airflow/.local/lib/python3.12/site-packages/airflow/utils/operator_helpers.py", line 252, in run
    return self.func(*args, **kwargs)
           ^^^^^^^^^^^^^^^^^^^^^^^^^^
  File "/home/airflow/.local/lib/python3.12/site-packages/airflow/models/baseoperator.py", line 424, in wrapper
    return func(self, *args, **kwargs)
           ^^^^^^^^^^^^^^^^^^^^^^^^^^^
  File "/home/airflow/.local/lib/python3.12/site-packages/airflow/operators/bash.py", line 276, in execute
    raise AirflowException(
airflow.exceptions.AirflowException: Bash command failed. The command returned a non-zero exit code 125.
[2025-03-08T13:51:04.732+0000] {logging_mixin.py:190} INFO - Task instance in failure state
[2025-03-08T13:51:04.732+0000] {logging_mixin.py:190} INFO - Task start:2025-03-08 13:51:04.372283+00:00 end:2025-03-08 13:51:04.731715+00:00 duration:0.359432
[2025-03-08T13:51:04.733+0000] {logging_mixin.py:190} INFO - Task:<Task(BashOperator): task_etl_fire_incident_using_bash> dag:<DAG: pull_fire_incidents_dag> dagrun:<DagRun pull_fire_incidents_dag @ 2025-03-08 09:00:00+00:00: scheduled__2025-03-08T09:00:00+00:00, state:running, queued_at: 2025-03-08 13:51:00.009952+00:00. externally triggered: False>
[2025-03-08T13:51:04.733+0000] {logging_mixin.py:190} INFO - Failure caused by Bash command failed. The command returned a non-zero exit code 125.
[2025-03-08T13:51:04.733+0000] {taskinstance.py:1226} INFO - Marking task as UP_FOR_RETRY. dag_id=pull_fire_incidents_dag, task_id=task_etl_fire_incident_using_bash, run_id=scheduled__2025-03-08T09:00:00+00:00, execution_date=20250308T090000, start_date=20250308T135104, end_date=20250308T135104
[2025-03-08T13:51:04.775+0000] {taskinstance.py:341} INFO - ::group::Post task execution logs
[2025-03-08T13:51:04.775+0000] {standard_task_runner.py:124} ERROR - Failed to execute job 338 for task task_etl_fire_incident_using_bash (Bash command failed. The command returned a non-zero exit code 125.; 105)
Traceback (most recent call last):
  File "/home/airflow/.local/lib/python3.12/site-packages/airflow/task/task_runner/standard_task_runner.py", line 117, in _start_by_fork
    ret = args.func(args, dag=self.dag)
          ^^^^^^^^^^^^^^^^^^^^^^^^^^^^^
  File "/home/airflow/.local/lib/python3.12/site-packages/airflow/cli/cli_config.py", line 49, in command
    return func(*args, **kwargs)
           ^^^^^^^^^^^^^^^^^^^^^
  File "/home/airflow/.local/lib/python3.12/site-packages/airflow/utils/cli.py", line 116, in wrapper
    return f(*args, **kwargs)
           ^^^^^^^^^^^^^^^^^^
  File "/home/airflow/.local/lib/python3.12/site-packages/airflow/cli/commands/task_command.py", line 483, in task_run
    task_return_code = _run_task_by_selected_method(args, _dag, ti)
                       ^^^^^^^^^^^^^^^^^^^^^^^^^^^^^^^^^^^^^^^^^^^^
  File "/home/airflow/.local/lib/python3.12/site-packages/airflow/cli/commands/task_command.py", line 256, in _run_task_by_selected_method
    return _run_raw_task(args, ti)
           ^^^^^^^^^^^^^^^^^^^^^^^
  File "/home/airflow/.local/lib/python3.12/site-packages/airflow/cli/commands/task_command.py", line 341, in _run_raw_task
    return ti._run_raw_task(
           ^^^^^^^^^^^^^^^^^
  File "/home/airflow/.local/lib/python3.12/site-packages/airflow/utils/session.py", line 97, in wrapper
    return func(*args, session=session, **kwargs)
           ^^^^^^^^^^^^^^^^^^^^^^^^^^^^^^^^^^^^^^
  File "/home/airflow/.local/lib/python3.12/site-packages/airflow/models/taskinstance.py", line 3006, in _run_raw_task
    return _run_raw_task(
           ^^^^^^^^^^^^^^
  File "/home/airflow/.local/lib/python3.12/site-packages/airflow/models/taskinstance.py", line 274, in _run_raw_task
    TaskInstance._execute_task_with_callbacks(
  File "/home/airflow/.local/lib/python3.12/site-packages/airflow/models/taskinstance.py", line 3161, in _execute_task_with_callbacks
    result = self._execute_task(context, task_orig)
             ^^^^^^^^^^^^^^^^^^^^^^^^^^^^^^^^^^^^^^
  File "/home/airflow/.local/lib/python3.12/site-packages/airflow/models/taskinstance.py", line 3185, in _execute_task
    return _execute_task(self, context, task_orig)
           ^^^^^^^^^^^^^^^^^^^^^^^^^^^^^^^^^^^^^^^
  File "/home/airflow/.local/lib/python3.12/site-packages/airflow/models/taskinstance.py", line 768, in _execute_task
    result = _execute_callable(context=context, **execute_callable_kwargs)
             ^^^^^^^^^^^^^^^^^^^^^^^^^^^^^^^^^^^^^^^^^^^^^^^^^^^^^^^^^^^^^
  File "/home/airflow/.local/lib/python3.12/site-packages/airflow/models/taskinstance.py", line 734, in _execute_callable
    return ExecutionCallableRunner(
           ^^^^^^^^^^^^^^^^^^^^^^^^
  File "/home/airflow/.local/lib/python3.12/site-packages/airflow/utils/operator_helpers.py", line 252, in run
    return self.func(*args, **kwargs)
           ^^^^^^^^^^^^^^^^^^^^^^^^^^
  File "/home/airflow/.local/lib/python3.12/site-packages/airflow/models/baseoperator.py", line 424, in wrapper
    return func(self, *args, **kwargs)
           ^^^^^^^^^^^^^^^^^^^^^^^^^^^
  File "/home/airflow/.local/lib/python3.12/site-packages/airflow/operators/bash.py", line 276, in execute
    raise AirflowException(
airflow.exceptions.AirflowException: Bash command failed. The command returned a non-zero exit code 125.
[2025-03-08T13:51:04.817+0000] {local_task_job_runner.py:266} INFO - Task exited with return code 1
[2025-03-08T13:51:04.837+0000] {taskinstance.py:3901} INFO - 0 downstream tasks scheduled from follow-on schedule check
[2025-03-08T13:51:04.839+0000] {local_task_job_runner.py:245} INFO - ::endgroup::
[2025-03-08T14:00:36.437+0000] {local_task_job_runner.py:123} INFO - ::group::Pre task execution logs
[2025-03-08T14:00:36.448+0000] {taskinstance.py:2614} INFO - Dependencies all met for dep_context=non-requeueable deps ti=<TaskInstance: pull_fire_incidents_dag.task_etl_fire_incident_using_bash scheduled__2025-03-08T09:00:00+00:00 [queued]>
[2025-03-08T14:00:36.453+0000] {taskinstance.py:2614} INFO - Dependencies all met for dep_context=requeueable deps ti=<TaskInstance: pull_fire_incidents_dag.task_etl_fire_incident_using_bash scheduled__2025-03-08T09:00:00+00:00 [queued]>
[2025-03-08T14:00:36.453+0000] {taskinstance.py:2867} INFO - Starting attempt 1 of 2
[2025-03-08T14:00:36.464+0000] {taskinstance.py:2890} INFO - Executing <Task(BashOperator): task_etl_fire_incident_using_bash> on 2025-03-08 09:00:00+00:00
[2025-03-08T14:00:36.471+0000] {warnings.py:112} WARNING - /home/***/.local/lib/python3.12/site-packages/***/task/task_runner/standard_task_runner.py:70: DeprecationWarning: This process (pid=77) is multi-threaded, use of fork() may lead to deadlocks in the child.
  pid = os.fork()

[2025-03-08T14:00:36.473+0000] {standard_task_runner.py:72} INFO - Started process 79 to run task
[2025-03-08T14:00:36.474+0000] {standard_task_runner.py:104} INFO - Running: ['***', 'tasks', 'run', 'pull_fire_incidents_dag', 'task_etl_fire_incident_using_bash', 'scheduled__2025-03-08T09:00:00+00:00', '--job-id', '342', '--raw', '--subdir', 'DAGS_FOLDER/fire_incidents_dag.py', '--cfg-path', '/tmp/tmp9wjdsacj']
[2025-03-08T14:00:36.475+0000] {standard_task_runner.py:105} INFO - Job 342: Subtask task_etl_fire_incident_using_bash
[2025-03-08T14:00:36.518+0000] {task_command.py:467} INFO - Running <TaskInstance: pull_fire_incidents_dag.task_etl_fire_incident_using_bash scheduled__2025-03-08T09:00:00+00:00 [running]> on host d9e6d015bc2a
[2025-03-08T14:00:36.586+0000] {taskinstance.py:3134} INFO - Exporting env vars: AIRFLOW_CTX_DAG_EMAIL='***@***.com' AIRFLOW_CTX_DAG_OWNER='***' AIRFLOW_CTX_DAG_ID='pull_fire_incidents_dag' AIRFLOW_CTX_TASK_ID='task_etl_fire_incident_using_bash' AIRFLOW_CTX_EXECUTION_DATE='2025-03-08T09:00:00+00:00' AIRFLOW_CTX_TRY_NUMBER='1' AIRFLOW_CTX_DAG_RUN_ID='scheduled__2025-03-08T09:00:00+00:00'
[2025-03-08T14:00:36.587+0000] {logging_mixin.py:190} INFO - Task instance is in running state
[2025-03-08T14:00:36.588+0000] {logging_mixin.py:190} INFO -  Previous state of the Task instance: queued
[2025-03-08T14:00:36.588+0000] {logging_mixin.py:190} INFO - Current task name:task_etl_fire_incident_using_bash state:running start_date:2025-03-08 14:00:36.448295+00:00
[2025-03-08T14:00:36.588+0000] {logging_mixin.py:190} INFO - Dag name:pull_fire_incidents_dag and current dag run status:running
[2025-03-08T14:00:36.588+0000] {taskinstance.py:732} INFO - ::endgroup::
[2025-03-08T14:00:36.589+0000] {subprocess.py:78} INFO - Tmp dir root location: /tmp
[2025-03-08T14:00:36.589+0000] {subprocess.py:88} INFO - Running command: ['/usr/bin/bash', '-c', 'docker run --rm \\--network=pg-network-fire-incidents \\nyc_fire_incidents:v001 \\--api_url=data.cityofnewyork.us \\--token=xoIfIdDlHq6gGzxqLqbUeMpsG \\--dataset_id=8m42-w767 \\--limit_rows=10000 \\--username=root \\--password=root \\--host_name=fire_incidents_db_container \\--port=5432 \\--database=fire_incidents_db \\--tbl_name=fire_incidents_tbl']
[2025-03-08T14:00:36.600+0000] {subprocess.py:99} INFO - Output:
[2025-03-08T14:00:36.625+0000] {subprocess.py:106} INFO - docker: Cannot connect to the Docker daemon at unix:///var/run/docker.sock. Is the docker daemon running?.
[2025-03-08T14:00:36.625+0000] {subprocess.py:106} INFO - See 'docker run --help'.
[2025-03-08T14:00:36.626+0000] {subprocess.py:110} INFO - Command exited with return code 125
[2025-03-08T14:00:36.634+0000] {taskinstance.py:3313} ERROR - Task failed with exception
Traceback (most recent call last):
  File "/home/airflow/.local/lib/python3.12/site-packages/airflow/models/taskinstance.py", line 768, in _execute_task
    result = _execute_callable(context=context, **execute_callable_kwargs)
             ^^^^^^^^^^^^^^^^^^^^^^^^^^^^^^^^^^^^^^^^^^^^^^^^^^^^^^^^^^^^^
  File "/home/airflow/.local/lib/python3.12/site-packages/airflow/models/taskinstance.py", line 734, in _execute_callable
    return ExecutionCallableRunner(
           ^^^^^^^^^^^^^^^^^^^^^^^^
  File "/home/airflow/.local/lib/python3.12/site-packages/airflow/utils/operator_helpers.py", line 252, in run
    return self.func(*args, **kwargs)
           ^^^^^^^^^^^^^^^^^^^^^^^^^^
  File "/home/airflow/.local/lib/python3.12/site-packages/airflow/models/baseoperator.py", line 424, in wrapper
    return func(self, *args, **kwargs)
           ^^^^^^^^^^^^^^^^^^^^^^^^^^^
  File "/home/airflow/.local/lib/python3.12/site-packages/airflow/operators/bash.py", line 276, in execute
    raise AirflowException(
airflow.exceptions.AirflowException: Bash command failed. The command returned a non-zero exit code 125.
[2025-03-08T14:00:36.640+0000] {logging_mixin.py:190} INFO - Task instance in failure state
[2025-03-08T14:00:36.640+0000] {logging_mixin.py:190} INFO - Task start:2025-03-08 14:00:36.448295+00:00 end:2025-03-08 14:00:36.640093+00:00 duration:0.191798
[2025-03-08T14:00:36.641+0000] {logging_mixin.py:190} INFO - Task:<Task(BashOperator): task_etl_fire_incident_using_bash> dag:<DAG: pull_fire_incidents_dag> dagrun:<DagRun pull_fire_incidents_dag @ 2025-03-08 09:00:00+00:00: scheduled__2025-03-08T09:00:00+00:00, state:running, queued_at: 2025-03-08 14:00:34.960023+00:00. externally triggered: False>
[2025-03-08T14:00:36.641+0000] {logging_mixin.py:190} INFO - Failure caused by Bash command failed. The command returned a non-zero exit code 125.
[2025-03-08T14:00:36.641+0000] {taskinstance.py:1226} INFO - Marking task as UP_FOR_RETRY. dag_id=pull_fire_incidents_dag, task_id=task_etl_fire_incident_using_bash, run_id=scheduled__2025-03-08T09:00:00+00:00, execution_date=20250308T090000, start_date=20250308T140036, end_date=20250308T140036
[2025-03-08T14:00:36.664+0000] {taskinstance.py:341} INFO - ::group::Post task execution logs
[2025-03-08T14:00:36.664+0000] {standard_task_runner.py:124} ERROR - Failed to execute job 342 for task task_etl_fire_incident_using_bash (Bash command failed. The command returned a non-zero exit code 125.; 79)
Traceback (most recent call last):
  File "/home/airflow/.local/lib/python3.12/site-packages/airflow/task/task_runner/standard_task_runner.py", line 117, in _start_by_fork
    ret = args.func(args, dag=self.dag)
          ^^^^^^^^^^^^^^^^^^^^^^^^^^^^^
  File "/home/airflow/.local/lib/python3.12/site-packages/airflow/cli/cli_config.py", line 49, in command
    return func(*args, **kwargs)
           ^^^^^^^^^^^^^^^^^^^^^
  File "/home/airflow/.local/lib/python3.12/site-packages/airflow/utils/cli.py", line 116, in wrapper
    return f(*args, **kwargs)
           ^^^^^^^^^^^^^^^^^^
  File "/home/airflow/.local/lib/python3.12/site-packages/airflow/cli/commands/task_command.py", line 483, in task_run
    task_return_code = _run_task_by_selected_method(args, _dag, ti)
                       ^^^^^^^^^^^^^^^^^^^^^^^^^^^^^^^^^^^^^^^^^^^^
  File "/home/airflow/.local/lib/python3.12/site-packages/airflow/cli/commands/task_command.py", line 256, in _run_task_by_selected_method
    return _run_raw_task(args, ti)
           ^^^^^^^^^^^^^^^^^^^^^^^
  File "/home/airflow/.local/lib/python3.12/site-packages/airflow/cli/commands/task_command.py", line 341, in _run_raw_task
    return ti._run_raw_task(
           ^^^^^^^^^^^^^^^^^
  File "/home/airflow/.local/lib/python3.12/site-packages/airflow/utils/session.py", line 97, in wrapper
    return func(*args, session=session, **kwargs)
           ^^^^^^^^^^^^^^^^^^^^^^^^^^^^^^^^^^^^^^
  File "/home/airflow/.local/lib/python3.12/site-packages/airflow/models/taskinstance.py", line 3006, in _run_raw_task
    return _run_raw_task(
           ^^^^^^^^^^^^^^
  File "/home/airflow/.local/lib/python3.12/site-packages/airflow/models/taskinstance.py", line 274, in _run_raw_task
    TaskInstance._execute_task_with_callbacks(
  File "/home/airflow/.local/lib/python3.12/site-packages/airflow/models/taskinstance.py", line 3161, in _execute_task_with_callbacks
    result = self._execute_task(context, task_orig)
             ^^^^^^^^^^^^^^^^^^^^^^^^^^^^^^^^^^^^^^
  File "/home/airflow/.local/lib/python3.12/site-packages/airflow/models/taskinstance.py", line 3185, in _execute_task
    return _execute_task(self, context, task_orig)
           ^^^^^^^^^^^^^^^^^^^^^^^^^^^^^^^^^^^^^^^
  File "/home/airflow/.local/lib/python3.12/site-packages/airflow/models/taskinstance.py", line 768, in _execute_task
    result = _execute_callable(context=context, **execute_callable_kwargs)
             ^^^^^^^^^^^^^^^^^^^^^^^^^^^^^^^^^^^^^^^^^^^^^^^^^^^^^^^^^^^^^
  File "/home/airflow/.local/lib/python3.12/site-packages/airflow/models/taskinstance.py", line 734, in _execute_callable
    return ExecutionCallableRunner(
           ^^^^^^^^^^^^^^^^^^^^^^^^
  File "/home/airflow/.local/lib/python3.12/site-packages/airflow/utils/operator_helpers.py", line 252, in run
    return self.func(*args, **kwargs)
           ^^^^^^^^^^^^^^^^^^^^^^^^^^
  File "/home/airflow/.local/lib/python3.12/site-packages/airflow/models/baseoperator.py", line 424, in wrapper
    return func(self, *args, **kwargs)
           ^^^^^^^^^^^^^^^^^^^^^^^^^^^
  File "/home/airflow/.local/lib/python3.12/site-packages/airflow/operators/bash.py", line 276, in execute
    raise AirflowException(
airflow.exceptions.AirflowException: Bash command failed. The command returned a non-zero exit code 125.
[2025-03-08T14:00:36.687+0000] {local_task_job_runner.py:266} INFO - Task exited with return code 1
[2025-03-08T14:00:36.709+0000] {taskinstance.py:3901} INFO - 0 downstream tasks scheduled from follow-on schedule check
[2025-03-08T14:00:36.711+0000] {local_task_job_runner.py:245} INFO - ::endgroup::
[2025-03-08T14:03:39.603+0000] {local_task_job_runner.py:123} INFO - ::group::Pre task execution logs
[2025-03-08T14:03:39.617+0000] {taskinstance.py:2614} INFO - Dependencies all met for dep_context=non-requeueable deps ti=<TaskInstance: pull_fire_incidents_dag.task_etl_fire_incident_using_bash scheduled__2025-03-08T09:00:00+00:00 [queued]>
[2025-03-08T14:03:39.624+0000] {taskinstance.py:2614} INFO - Dependencies all met for dep_context=requeueable deps ti=<TaskInstance: pull_fire_incidents_dag.task_etl_fire_incident_using_bash scheduled__2025-03-08T09:00:00+00:00 [queued]>
[2025-03-08T14:03:39.624+0000] {taskinstance.py:2867} INFO - Starting attempt 1 of 2
[2025-03-08T14:03:39.639+0000] {taskinstance.py:2890} INFO - Executing <Task(BashOperator): task_etl_fire_incident_using_bash> on 2025-03-08 09:00:00+00:00
[2025-03-08T14:03:39.646+0000] {warnings.py:112} WARNING - /home/***/.local/lib/python3.12/site-packages/***/task/task_runner/standard_task_runner.py:70: DeprecationWarning: This process (pid=97) is multi-threaded, use of fork() may lead to deadlocks in the child.
  pid = os.fork()

[2025-03-08T14:03:39.647+0000] {standard_task_runner.py:72} INFO - Started process 106 to run task
[2025-03-08T14:03:39.648+0000] {standard_task_runner.py:104} INFO - Running: ['***', 'tasks', 'run', 'pull_fire_incidents_dag', 'task_etl_fire_incident_using_bash', 'scheduled__2025-03-08T09:00:00+00:00', '--job-id', '344', '--raw', '--subdir', 'DAGS_FOLDER/fire_incidents_dag.py', '--cfg-path', '/tmp/tmp4vpa6qvb']
[2025-03-08T14:03:39.648+0000] {standard_task_runner.py:105} INFO - Job 344: Subtask task_etl_fire_incident_using_bash
[2025-03-08T14:03:39.689+0000] {task_command.py:467} INFO - Running <TaskInstance: pull_fire_incidents_dag.task_etl_fire_incident_using_bash scheduled__2025-03-08T09:00:00+00:00 [running]> on host 330b184cbfc0
[2025-03-08T14:03:39.773+0000] {taskinstance.py:3134} INFO - Exporting env vars: AIRFLOW_CTX_DAG_EMAIL='***@***.com' AIRFLOW_CTX_DAG_OWNER='***' AIRFLOW_CTX_DAG_ID='pull_fire_incidents_dag' AIRFLOW_CTX_TASK_ID='task_etl_fire_incident_using_bash' AIRFLOW_CTX_EXECUTION_DATE='2025-03-08T09:00:00+00:00' AIRFLOW_CTX_TRY_NUMBER='1' AIRFLOW_CTX_DAG_RUN_ID='scheduled__2025-03-08T09:00:00+00:00'
[2025-03-08T14:03:39.775+0000] {logging_mixin.py:190} INFO - Task instance is in running state
[2025-03-08T14:03:39.775+0000] {logging_mixin.py:190} INFO -  Previous state of the Task instance: queued
[2025-03-08T14:03:39.775+0000] {logging_mixin.py:190} INFO - Current task name:task_etl_fire_incident_using_bash state:running start_date:2025-03-08 14:03:39.617336+00:00
[2025-03-08T14:03:39.775+0000] {logging_mixin.py:190} INFO - Dag name:pull_fire_incidents_dag and current dag run status:running
[2025-03-08T14:03:39.776+0000] {taskinstance.py:732} INFO - ::endgroup::
[2025-03-08T14:03:39.776+0000] {subprocess.py:78} INFO - Tmp dir root location: /tmp
[2025-03-08T14:03:39.777+0000] {subprocess.py:88} INFO - Running command: ['/usr/bin/bash', '-c', 'docker run --rm \\--network=pg-network-fire-incidents \\nyc_fire_incidents:v001 \\--api_url=data.cityofnewyork.us \\--token=xoIfIdDlHq6gGzxqLqbUeMpsG \\--dataset_id=8m42-w767 \\--limit_rows=10000 \\--username=root \\--password=root \\--host_name=fire_incidents_db_container \\--port=5432 \\--database=fire_incidents_db \\--tbl_name=fire_incidents_tbl']
[2025-03-08T14:03:39.789+0000] {subprocess.py:99} INFO - Output:
[2025-03-08T14:03:49.419+0000] {subprocess.py:106} INFO - Traceback (most recent call last):
[2025-03-08T14:03:49.420+0000] {subprocess.py:106} INFO -   File "/usr/local/lib/python3.9/site-packages/sqlalchemy/engine/base.py", line 146, in __init__
[2025-03-08T14:03:49.421+0000] {subprocess.py:106} INFO - Connected to API...
[2025-03-08T14:03:49.421+0000] {subprocess.py:106} INFO -     self._dbapi_connection = engine.raw_connection()
[2025-03-08T14:03:49.422+0000] {subprocess.py:106} INFO -   File "/usr/local/lib/python3.9/site-packages/sqlalchemy/engine/base.py", line 3298, in raw_connection
[2025-03-08T14:03:49.422+0000] {subprocess.py:106} INFO -     return self.pool.connect()
[2025-03-08T14:03:49.422+0000] {subprocess.py:106} INFO -   File "/usr/local/lib/python3.9/site-packages/sqlalchemy/pool/base.py", line 449, in connect
[2025-03-08T14:03:49.423+0000] {subprocess.py:106} INFO -     return _ConnectionFairy._checkout(self)
[2025-03-08T14:03:49.423+0000] {subprocess.py:106} INFO -   File "/usr/local/lib/python3.9/site-packages/sqlalchemy/pool/base.py", line 1263, in _checkout
[2025-03-08T14:03:49.423+0000] {subprocess.py:106} INFO -     fairy = _ConnectionRecord.checkout(pool)
[2025-03-08T14:03:49.423+0000] {subprocess.py:106} INFO -   File "/usr/local/lib/python3.9/site-packages/sqlalchemy/pool/base.py", line 712, in checkout
[2025-03-08T14:03:49.424+0000] {subprocess.py:106} INFO -     rec = pool._do_get()
[2025-03-08T14:03:49.424+0000] {subprocess.py:106} INFO -   File "/usr/local/lib/python3.9/site-packages/sqlalchemy/pool/impl.py", line 180, in _do_get
[2025-03-08T14:03:49.424+0000] {subprocess.py:106} INFO -     self._dec_overflow()
[2025-03-08T14:03:49.424+0000] {subprocess.py:106} INFO -   File "/usr/local/lib/python3.9/site-packages/sqlalchemy/util/langhelpers.py", line 146, in __exit__
[2025-03-08T14:03:49.425+0000] {subprocess.py:106} INFO -     raise exc_value.with_traceback(exc_tb)
[2025-03-08T14:03:49.425+0000] {subprocess.py:106} INFO -   File "/usr/local/lib/python3.9/site-packages/sqlalchemy/pool/impl.py", line 177, in _do_get
[2025-03-08T14:03:49.425+0000] {subprocess.py:106} INFO -     return self._create_connection()
[2025-03-08T14:03:49.425+0000] {subprocess.py:106} INFO -   File "/usr/local/lib/python3.9/site-packages/sqlalchemy/pool/base.py", line 390, in _create_connection
[2025-03-08T14:03:49.426+0000] {subprocess.py:106} INFO -     return _ConnectionRecord(self)
[2025-03-08T14:03:49.426+0000] {subprocess.py:106} INFO -   File "/usr/local/lib/python3.9/site-packages/sqlalchemy/pool/base.py", line 674, in __init__
[2025-03-08T14:03:49.426+0000] {subprocess.py:106} INFO -     self.__connect()
[2025-03-08T14:03:49.427+0000] {subprocess.py:106} INFO -   File "/usr/local/lib/python3.9/site-packages/sqlalchemy/pool/base.py", line 901, in __connect
[2025-03-08T14:03:49.427+0000] {subprocess.py:106} INFO -     pool.logger.debug("Error on connect(): %s", e)
[2025-03-08T14:03:49.427+0000] {subprocess.py:106} INFO -   File "/usr/local/lib/python3.9/site-packages/sqlalchemy/util/langhelpers.py", line 146, in __exit__
[2025-03-08T14:03:49.427+0000] {subprocess.py:106} INFO -     raise exc_value.with_traceback(exc_tb)
[2025-03-08T14:03:49.428+0000] {subprocess.py:106} INFO -   File "/usr/local/lib/python3.9/site-packages/sqlalchemy/pool/base.py", line 896, in __connect
[2025-03-08T14:03:49.428+0000] {subprocess.py:106} INFO -     self.dbapi_connection = connection = pool._invoke_creator(self)
[2025-03-08T14:03:49.429+0000] {subprocess.py:106} INFO -   File "/usr/local/lib/python3.9/site-packages/sqlalchemy/engine/create.py", line 646, in connect
[2025-03-08T14:03:49.429+0000] {subprocess.py:106} INFO -     return dialect.connect(*cargs, **cparams)
[2025-03-08T14:03:49.429+0000] {subprocess.py:106} INFO -   File "/usr/local/lib/python3.9/site-packages/sqlalchemy/engine/default.py", line 622, in connect
[2025-03-08T14:03:49.430+0000] {subprocess.py:106} INFO -     return self.loaded_dbapi.connect(*cargs, **cparams)
[2025-03-08T14:03:49.430+0000] {subprocess.py:106} INFO -   File "/usr/local/lib/python3.9/site-packages/psycopg2/__init__.py", line 122, in connect
[2025-03-08T14:03:49.431+0000] {subprocess.py:106} INFO -     conn = _connect(dsn, connection_factory=connection_factory, **kwasync)
[2025-03-08T14:03:49.431+0000] {subprocess.py:106} INFO - psycopg2.OperationalError: could not translate host name "fire_incidents_db_container" to address: Name or service not known
[2025-03-08T14:03:49.432+0000] {subprocess.py:106} INFO - 
[2025-03-08T14:03:49.433+0000] {subprocess.py:106} INFO - 
[2025-03-08T14:03:49.434+0000] {subprocess.py:106} INFO - The above exception was the direct cause of the following exception:
[2025-03-08T14:03:49.434+0000] {subprocess.py:106} INFO - 
[2025-03-08T14:03:49.434+0000] {subprocess.py:106} INFO - Traceback (most recent call last):
[2025-03-08T14:03:49.435+0000] {subprocess.py:106} INFO -   File "/app/pull_fire_incidents.py", line 136, in <module>
[2025-03-08T14:03:49.435+0000] {subprocess.py:106} INFO -     pull_data_via_api(args)
[2025-03-08T14:03:49.435+0000] {subprocess.py:106} INFO -   File "/app/pull_fire_incidents.py", line 94, in pull_data_via_api
[2025-03-08T14:03:49.435+0000] {subprocess.py:106} INFO -     print(pd.io.sql.get_schema(df,name='fire_incidents_schema',con=engine))
[2025-03-08T14:03:49.436+0000] {subprocess.py:106} INFO -   File "/usr/local/lib/python3.9/site-packages/pandas/io/sql.py", line 2923, in get_schema
[2025-03-08T14:03:49.436+0000] {subprocess.py:106} INFO -     with pandasSQL_builder(con=con) as pandas_sql:
[2025-03-08T14:03:49.436+0000] {subprocess.py:106} INFO -   File "/usr/local/lib/python3.9/site-packages/pandas/io/sql.py", line 906, in pandasSQL_builder
[2025-03-08T14:03:49.436+0000] {subprocess.py:106} INFO -     return SQLDatabase(con, schema, need_transaction)
[2025-03-08T14:03:49.436+0000] {subprocess.py:106} INFO -   File "/usr/local/lib/python3.9/site-packages/pandas/io/sql.py", line 1636, in __init__
[2025-03-08T14:03:49.437+0000] {subprocess.py:106} INFO -     con = self.exit_stack.enter_context(con.connect())
[2025-03-08T14:03:49.437+0000] {subprocess.py:106} INFO -   File "/usr/local/lib/python3.9/site-packages/sqlalchemy/engine/base.py", line 3274, in connect
[2025-03-08T14:03:49.437+0000] {subprocess.py:106} INFO -     return self._connection_cls(self)
[2025-03-08T14:03:49.437+0000] {subprocess.py:106} INFO -   File "/usr/local/lib/python3.9/site-packages/sqlalchemy/engine/base.py", line 148, in __init__
[2025-03-08T14:03:49.438+0000] {subprocess.py:106} INFO -     Connection._handle_dbapi_exception_noconnection(
[2025-03-08T14:03:49.438+0000] {subprocess.py:106} INFO -   File "/usr/local/lib/python3.9/site-packages/sqlalchemy/engine/base.py", line 2439, in _handle_dbapi_exception_noconnection
[2025-03-08T14:03:49.438+0000] {subprocess.py:106} INFO -     raise sqlalchemy_exception.with_traceback(exc_info[2]) from e
[2025-03-08T14:03:49.438+0000] {subprocess.py:106} INFO -   File "/usr/local/lib/python3.9/site-packages/sqlalchemy/engine/base.py", line 146, in __init__
[2025-03-08T14:03:49.439+0000] {subprocess.py:106} INFO -     self._dbapi_connection = engine.raw_connection()
[2025-03-08T14:03:49.439+0000] {subprocess.py:106} INFO -   File "/usr/local/lib/python3.9/site-packages/sqlalchemy/engine/base.py", line 3298, in raw_connection
[2025-03-08T14:03:49.439+0000] {subprocess.py:106} INFO -     return self.pool.connect()
[2025-03-08T14:03:49.439+0000] {subprocess.py:106} INFO -   File "/usr/local/lib/python3.9/site-packages/sqlalchemy/pool/base.py", line 449, in connect
[2025-03-08T14:03:49.440+0000] {subprocess.py:106} INFO -     return _ConnectionFairy._checkout(self)
[2025-03-08T14:03:49.440+0000] {subprocess.py:106} INFO -   File "/usr/local/lib/python3.9/site-packages/sqlalchemy/pool/base.py", line 1263, in _checkout
[2025-03-08T14:03:49.440+0000] {subprocess.py:106} INFO -     fairy = _ConnectionRecord.checkout(pool)
[2025-03-08T14:03:49.441+0000] {subprocess.py:106} INFO -   File "/usr/local/lib/python3.9/site-packages/sqlalchemy/pool/base.py", line 712, in checkout
[2025-03-08T14:03:49.441+0000] {subprocess.py:106} INFO -     rec = pool._do_get()
[2025-03-08T14:03:49.441+0000] {subprocess.py:106} INFO -   File "/usr/local/lib/python3.9/site-packages/sqlalchemy/pool/impl.py", line 180, in _do_get
[2025-03-08T14:03:49.441+0000] {subprocess.py:106} INFO -     self._dec_overflow()
[2025-03-08T14:03:49.442+0000] {subprocess.py:106} INFO -   File "/usr/local/lib/python3.9/site-packages/sqlalchemy/util/langhelpers.py", line 146, in __exit__
[2025-03-08T14:03:49.442+0000] {subprocess.py:106} INFO -     raise exc_value.with_traceback(exc_tb)
[2025-03-08T14:03:49.442+0000] {subprocess.py:106} INFO -   File "/usr/local/lib/python3.9/site-packages/sqlalchemy/pool/impl.py", line 177, in _do_get
[2025-03-08T14:03:49.443+0000] {subprocess.py:106} INFO -     return self._create_connection()
[2025-03-08T14:03:49.443+0000] {subprocess.py:106} INFO -   File "/usr/local/lib/python3.9/site-packages/sqlalchemy/pool/base.py", line 390, in _create_connection
[2025-03-08T14:03:49.443+0000] {subprocess.py:106} INFO -     return _ConnectionRecord(self)
[2025-03-08T14:03:49.444+0000] {subprocess.py:106} INFO -   File "/usr/local/lib/python3.9/site-packages/sqlalchemy/pool/base.py", line 674, in __init__
[2025-03-08T14:03:49.444+0000] {subprocess.py:106} INFO -     self.__connect()
[2025-03-08T14:03:49.445+0000] {subprocess.py:106} INFO -   File "/usr/local/lib/python3.9/site-packages/sqlalchemy/pool/base.py", line 901, in __connect
[2025-03-08T14:03:49.445+0000] {subprocess.py:106} INFO -     pool.logger.debug("Error on connect(): %s", e)
[2025-03-08T14:03:49.445+0000] {subprocess.py:106} INFO -   File "/usr/local/lib/python3.9/site-packages/sqlalchemy/util/langhelpers.py", line 146, in __exit__
[2025-03-08T14:03:49.446+0000] {subprocess.py:106} INFO -     raise exc_value.with_traceback(exc_tb)
[2025-03-08T14:03:49.446+0000] {subprocess.py:106} INFO -   File "/usr/local/lib/python3.9/site-packages/sqlalchemy/pool/base.py", line 896, in __connect
[2025-03-08T14:03:49.446+0000] {subprocess.py:106} INFO -     self.dbapi_connection = connection = pool._invoke_creator(self)
[2025-03-08T14:03:49.446+0000] {subprocess.py:106} INFO -   File "/usr/local/lib/python3.9/site-packages/sqlalchemy/engine/create.py", line 646, in connect
[2025-03-08T14:03:49.447+0000] {subprocess.py:106} INFO -     return dialect.connect(*cargs, **cparams)
[2025-03-08T14:03:49.447+0000] {subprocess.py:106} INFO -   File "/usr/local/lib/python3.9/site-packages/sqlalchemy/engine/default.py", line 622, in connect
[2025-03-08T14:03:49.447+0000] {subprocess.py:106} INFO -     return self.loaded_dbapi.connect(*cargs, **cparams)
[2025-03-08T14:03:49.447+0000] {subprocess.py:106} INFO -   File "/usr/local/lib/python3.9/site-packages/psycopg2/__init__.py", line 122, in connect
[2025-03-08T14:03:49.448+0000] {subprocess.py:106} INFO -     conn = _connect(dsn, connection_factory=connection_factory, **kwasync)
[2025-03-08T14:03:49.448+0000] {subprocess.py:106} INFO - sqlalchemy.exc.OperationalError: (psycopg2.OperationalError) could not translate host name "fire_incidents_db_container" to address: Name or service not known
[2025-03-08T14:03:49.448+0000] {subprocess.py:106} INFO - 
[2025-03-08T14:03:49.448+0000] {subprocess.py:106} INFO - (Background on this error at: https://sqlalche.me/e/20/e3q8)
[2025-03-08T14:03:50.302+0000] {subprocess.py:110} INFO - Command exited with return code 1
[2025-03-08T14:03:50.313+0000] {taskinstance.py:3313} ERROR - Task failed with exception
Traceback (most recent call last):
  File "/home/airflow/.local/lib/python3.12/site-packages/airflow/models/taskinstance.py", line 768, in _execute_task
    result = _execute_callable(context=context, **execute_callable_kwargs)
             ^^^^^^^^^^^^^^^^^^^^^^^^^^^^^^^^^^^^^^^^^^^^^^^^^^^^^^^^^^^^^
  File "/home/airflow/.local/lib/python3.12/site-packages/airflow/models/taskinstance.py", line 734, in _execute_callable
    return ExecutionCallableRunner(
           ^^^^^^^^^^^^^^^^^^^^^^^^
  File "/home/airflow/.local/lib/python3.12/site-packages/airflow/utils/operator_helpers.py", line 252, in run
    return self.func(*args, **kwargs)
           ^^^^^^^^^^^^^^^^^^^^^^^^^^
  File "/home/airflow/.local/lib/python3.12/site-packages/airflow/models/baseoperator.py", line 424, in wrapper
    return func(self, *args, **kwargs)
           ^^^^^^^^^^^^^^^^^^^^^^^^^^^
  File "/home/airflow/.local/lib/python3.12/site-packages/airflow/operators/bash.py", line 276, in execute
    raise AirflowException(
airflow.exceptions.AirflowException: Bash command failed. The command returned a non-zero exit code 1.
[2025-03-08T14:03:50.322+0000] {logging_mixin.py:190} INFO - Task instance in failure state
[2025-03-08T14:03:50.322+0000] {logging_mixin.py:190} INFO - Task start:2025-03-08 14:03:39.617336+00:00 end:2025-03-08 14:03:50.321614+00:00 duration:10.704278
[2025-03-08T14:03:50.322+0000] {logging_mixin.py:190} INFO - Task:<Task(BashOperator): task_etl_fire_incident_using_bash> dag:<DAG: pull_fire_incidents_dag> dagrun:<DagRun pull_fire_incidents_dag @ 2025-03-08 09:00:00+00:00: scheduled__2025-03-08T09:00:00+00:00, state:running, queued_at: 2025-03-08 14:03:37.719769+00:00. externally triggered: False>
[2025-03-08T14:03:50.323+0000] {logging_mixin.py:190} INFO - Failure caused by Bash command failed. The command returned a non-zero exit code 1.
[2025-03-08T14:03:50.323+0000] {taskinstance.py:1226} INFO - Marking task as UP_FOR_RETRY. dag_id=pull_fire_incidents_dag, task_id=task_etl_fire_incident_using_bash, run_id=scheduled__2025-03-08T09:00:00+00:00, execution_date=20250308T090000, start_date=20250308T140339, end_date=20250308T140350
[2025-03-08T14:03:50.353+0000] {taskinstance.py:341} INFO - ::group::Post task execution logs
[2025-03-08T14:03:50.354+0000] {standard_task_runner.py:124} ERROR - Failed to execute job 344 for task task_etl_fire_incident_using_bash (Bash command failed. The command returned a non-zero exit code 1.; 106)
Traceback (most recent call last):
  File "/home/airflow/.local/lib/python3.12/site-packages/airflow/task/task_runner/standard_task_runner.py", line 117, in _start_by_fork
    ret = args.func(args, dag=self.dag)
          ^^^^^^^^^^^^^^^^^^^^^^^^^^^^^
  File "/home/airflow/.local/lib/python3.12/site-packages/airflow/cli/cli_config.py", line 49, in command
    return func(*args, **kwargs)
           ^^^^^^^^^^^^^^^^^^^^^
  File "/home/airflow/.local/lib/python3.12/site-packages/airflow/utils/cli.py", line 116, in wrapper
    return f(*args, **kwargs)
           ^^^^^^^^^^^^^^^^^^
  File "/home/airflow/.local/lib/python3.12/site-packages/airflow/cli/commands/task_command.py", line 483, in task_run
    task_return_code = _run_task_by_selected_method(args, _dag, ti)
                       ^^^^^^^^^^^^^^^^^^^^^^^^^^^^^^^^^^^^^^^^^^^^
  File "/home/airflow/.local/lib/python3.12/site-packages/airflow/cli/commands/task_command.py", line 256, in _run_task_by_selected_method
    return _run_raw_task(args, ti)
           ^^^^^^^^^^^^^^^^^^^^^^^
  File "/home/airflow/.local/lib/python3.12/site-packages/airflow/cli/commands/task_command.py", line 341, in _run_raw_task
    return ti._run_raw_task(
           ^^^^^^^^^^^^^^^^^
  File "/home/airflow/.local/lib/python3.12/site-packages/airflow/utils/session.py", line 97, in wrapper
    return func(*args, session=session, **kwargs)
           ^^^^^^^^^^^^^^^^^^^^^^^^^^^^^^^^^^^^^^
  File "/home/airflow/.local/lib/python3.12/site-packages/airflow/models/taskinstance.py", line 3006, in _run_raw_task
    return _run_raw_task(
           ^^^^^^^^^^^^^^
  File "/home/airflow/.local/lib/python3.12/site-packages/airflow/models/taskinstance.py", line 274, in _run_raw_task
    TaskInstance._execute_task_with_callbacks(
  File "/home/airflow/.local/lib/python3.12/site-packages/airflow/models/taskinstance.py", line 3161, in _execute_task_with_callbacks
    result = self._execute_task(context, task_orig)
             ^^^^^^^^^^^^^^^^^^^^^^^^^^^^^^^^^^^^^^
  File "/home/airflow/.local/lib/python3.12/site-packages/airflow/models/taskinstance.py", line 3185, in _execute_task
    return _execute_task(self, context, task_orig)
           ^^^^^^^^^^^^^^^^^^^^^^^^^^^^^^^^^^^^^^^
  File "/home/airflow/.local/lib/python3.12/site-packages/airflow/models/taskinstance.py", line 768, in _execute_task
    result = _execute_callable(context=context, **execute_callable_kwargs)
             ^^^^^^^^^^^^^^^^^^^^^^^^^^^^^^^^^^^^^^^^^^^^^^^^^^^^^^^^^^^^^
  File "/home/airflow/.local/lib/python3.12/site-packages/airflow/models/taskinstance.py", line 734, in _execute_callable
    return ExecutionCallableRunner(
           ^^^^^^^^^^^^^^^^^^^^^^^^
  File "/home/airflow/.local/lib/python3.12/site-packages/airflow/utils/operator_helpers.py", line 252, in run
    return self.func(*args, **kwargs)
           ^^^^^^^^^^^^^^^^^^^^^^^^^^
  File "/home/airflow/.local/lib/python3.12/site-packages/airflow/models/baseoperator.py", line 424, in wrapper
    return func(self, *args, **kwargs)
           ^^^^^^^^^^^^^^^^^^^^^^^^^^^
  File "/home/airflow/.local/lib/python3.12/site-packages/airflow/operators/bash.py", line 276, in execute
    raise AirflowException(
airflow.exceptions.AirflowException: Bash command failed. The command returned a non-zero exit code 1.
[2025-03-08T14:03:50.387+0000] {local_task_job_runner.py:266} INFO - Task exited with return code 1
[2025-03-08T14:03:50.406+0000] {taskinstance.py:3901} INFO - 0 downstream tasks scheduled from follow-on schedule check
[2025-03-08T14:03:50.408+0000] {local_task_job_runner.py:245} INFO - ::endgroup::
