[2025-02-25T23:11:45.770+0000] {processor.py:186} INFO - Started process (PID=43) to work on /opt/airflow/dags/__pycache__/fire_incidents_dag.py
[2025-02-25T23:11:45.774+0000] {processor.py:914} INFO - Processing file /opt/airflow/dags/__pycache__/fire_incidents_dag.py for tasks to queue
[2025-02-25T23:11:45.779+0000] {logging_mixin.py:190} INFO - [2025-02-25T23:11:45.779+0000] {dagbag.py:588} INFO - Filling up the DagBag from /opt/airflow/dags/__pycache__/fire_incidents_dag.py
[2025-02-25T23:11:45.791+0000] {logging_mixin.py:190} INFO - [2025-02-25T23:11:45.789+0000] {dagbag.py:387} ERROR - Failed to import: /opt/airflow/dags/__pycache__/fire_incidents_dag.py
Traceback (most recent call last):
  File "/home/airflow/.local/lib/python3.12/site-packages/airflow/models/dagbag.py", line 383, in parse
    loader.exec_module(new_module)
  File "<frozen importlib._bootstrap_external>", line 999, in exec_module
  File "<frozen importlib._bootstrap>", line 488, in _call_with_frames_removed
  File "/opt/airflow/dags/__pycache__/fire_incidents_dag.py", line 4, in <module>
    from pull_fire_incidents import pull_data_via_api
ModuleNotFoundError: No module named 'pull_fire_incidents'
[2025-02-25T23:11:45.791+0000] {processor.py:927} WARNING - No viable dags retrieved from /opt/airflow/dags/__pycache__/fire_incidents_dag.py
[2025-02-25T23:11:45.984+0000] {processor.py:208} INFO - Processing /opt/airflow/dags/__pycache__/fire_incidents_dag.py took 0.223 seconds
[2025-02-25T23:12:16.256+0000] {processor.py:186} INFO - Started process (PID=107) to work on /opt/airflow/dags/__pycache__/fire_incidents_dag.py
[2025-02-25T23:12:16.257+0000] {processor.py:914} INFO - Processing file /opt/airflow/dags/__pycache__/fire_incidents_dag.py for tasks to queue
[2025-02-25T23:12:16.261+0000] {logging_mixin.py:190} INFO - [2025-02-25T23:12:16.260+0000] {dagbag.py:588} INFO - Filling up the DagBag from /opt/airflow/dags/__pycache__/fire_incidents_dag.py
[2025-02-25T23:12:16.265+0000] {logging_mixin.py:190} INFO - [2025-02-25T23:12:16.264+0000] {dagbag.py:387} ERROR - Failed to import: /opt/airflow/dags/__pycache__/fire_incidents_dag.py
Traceback (most recent call last):
  File "/home/airflow/.local/lib/python3.12/site-packages/airflow/models/dagbag.py", line 383, in parse
    loader.exec_module(new_module)
  File "<frozen importlib._bootstrap_external>", line 999, in exec_module
  File "<frozen importlib._bootstrap>", line 488, in _call_with_frames_removed
  File "/opt/airflow/dags/__pycache__/fire_incidents_dag.py", line 4, in <module>
    from pull_fire_incidents import pull_data_via_api
ModuleNotFoundError: No module named 'pull_fire_incidents'
[2025-02-25T23:12:16.266+0000] {processor.py:927} WARNING - No viable dags retrieved from /opt/airflow/dags/__pycache__/fire_incidents_dag.py
[2025-02-25T23:12:16.289+0000] {processor.py:208} INFO - Processing /opt/airflow/dags/__pycache__/fire_incidents_dag.py took 0.046 seconds
[2025-02-25T23:12:46.597+0000] {processor.py:186} INFO - Started process (PID=171) to work on /opt/airflow/dags/__pycache__/fire_incidents_dag.py
[2025-02-25T23:12:46.599+0000] {processor.py:914} INFO - Processing file /opt/airflow/dags/__pycache__/fire_incidents_dag.py for tasks to queue
[2025-02-25T23:12:46.603+0000] {logging_mixin.py:190} INFO - [2025-02-25T23:12:46.602+0000] {dagbag.py:588} INFO - Filling up the DagBag from /opt/airflow/dags/__pycache__/fire_incidents_dag.py
[2025-02-25T23:12:46.609+0000] {logging_mixin.py:190} INFO - [2025-02-25T23:12:46.607+0000] {dagbag.py:387} ERROR - Failed to import: /opt/airflow/dags/__pycache__/fire_incidents_dag.py
Traceback (most recent call last):
  File "/home/airflow/.local/lib/python3.12/site-packages/airflow/models/dagbag.py", line 383, in parse
    loader.exec_module(new_module)
  File "<frozen importlib._bootstrap_external>", line 999, in exec_module
  File "<frozen importlib._bootstrap>", line 488, in _call_with_frames_removed
  File "/opt/airflow/dags/__pycache__/fire_incidents_dag.py", line 4, in <module>
    from pull_fire_incidents import pull_data_via_api
ModuleNotFoundError: No module named 'pull_fire_incidents'
[2025-02-25T23:12:46.610+0000] {processor.py:927} WARNING - No viable dags retrieved from /opt/airflow/dags/__pycache__/fire_incidents_dag.py
[2025-02-25T23:12:46.626+0000] {processor.py:208} INFO - Processing /opt/airflow/dags/__pycache__/fire_incidents_dag.py took 0.041 seconds
[2025-02-25T23:13:17.028+0000] {processor.py:186} INFO - Started process (PID=235) to work on /opt/airflow/dags/__pycache__/fire_incidents_dag.py
[2025-02-25T23:13:17.029+0000] {processor.py:914} INFO - Processing file /opt/airflow/dags/__pycache__/fire_incidents_dag.py for tasks to queue
[2025-02-25T23:13:17.032+0000] {logging_mixin.py:190} INFO - [2025-02-25T23:13:17.031+0000] {dagbag.py:588} INFO - Filling up the DagBag from /opt/airflow/dags/__pycache__/fire_incidents_dag.py
[2025-02-25T23:13:17.035+0000] {logging_mixin.py:190} INFO - [2025-02-25T23:13:17.034+0000] {dagbag.py:387} ERROR - Failed to import: /opt/airflow/dags/__pycache__/fire_incidents_dag.py
Traceback (most recent call last):
  File "/home/airflow/.local/lib/python3.12/site-packages/airflow/models/dagbag.py", line 383, in parse
    loader.exec_module(new_module)
  File "<frozen importlib._bootstrap_external>", line 999, in exec_module
  File "<frozen importlib._bootstrap>", line 488, in _call_with_frames_removed
  File "/opt/airflow/dags/__pycache__/fire_incidents_dag.py", line 4, in <module>
    from pull_fire_incidents import pull_data_via_api
ModuleNotFoundError: No module named 'pull_fire_incidents'
[2025-02-25T23:13:17.035+0000] {processor.py:927} WARNING - No viable dags retrieved from /opt/airflow/dags/__pycache__/fire_incidents_dag.py
[2025-02-25T23:13:17.052+0000] {processor.py:208} INFO - Processing /opt/airflow/dags/__pycache__/fire_incidents_dag.py took 0.031 seconds
[2025-02-25T23:13:47.740+0000] {processor.py:186} INFO - Started process (PID=299) to work on /opt/airflow/dags/__pycache__/fire_incidents_dag.py
[2025-02-25T23:13:47.741+0000] {processor.py:914} INFO - Processing file /opt/airflow/dags/__pycache__/fire_incidents_dag.py for tasks to queue
[2025-02-25T23:13:47.742+0000] {logging_mixin.py:190} INFO - [2025-02-25T23:13:47.742+0000] {dagbag.py:588} INFO - Filling up the DagBag from /opt/airflow/dags/__pycache__/fire_incidents_dag.py
[2025-02-25T23:13:47.744+0000] {logging_mixin.py:190} INFO - [2025-02-25T23:13:47.744+0000] {dagbag.py:387} ERROR - Failed to import: /opt/airflow/dags/__pycache__/fire_incidents_dag.py
Traceback (most recent call last):
  File "/home/airflow/.local/lib/python3.12/site-packages/airflow/models/dagbag.py", line 383, in parse
    loader.exec_module(new_module)
  File "<frozen importlib._bootstrap_external>", line 999, in exec_module
  File "<frozen importlib._bootstrap>", line 488, in _call_with_frames_removed
  File "/opt/airflow/dags/__pycache__/fire_incidents_dag.py", line 4, in <module>
    from pull_fire_incidents import pull_data_via_api
ModuleNotFoundError: No module named 'pull_fire_incidents'
[2025-02-25T23:13:47.745+0000] {processor.py:927} WARNING - No viable dags retrieved from /opt/airflow/dags/__pycache__/fire_incidents_dag.py
[2025-02-25T23:13:47.757+0000] {processor.py:208} INFO - Processing /opt/airflow/dags/__pycache__/fire_incidents_dag.py took 0.021 seconds
[2025-02-25T23:14:18.277+0000] {processor.py:186} INFO - Started process (PID=363) to work on /opt/airflow/dags/__pycache__/fire_incidents_dag.py
[2025-02-25T23:14:18.277+0000] {processor.py:914} INFO - Processing file /opt/airflow/dags/__pycache__/fire_incidents_dag.py for tasks to queue
[2025-02-25T23:14:18.279+0000] {logging_mixin.py:190} INFO - [2025-02-25T23:14:18.279+0000] {dagbag.py:588} INFO - Filling up the DagBag from /opt/airflow/dags/__pycache__/fire_incidents_dag.py
[2025-02-25T23:14:18.281+0000] {logging_mixin.py:190} INFO - [2025-02-25T23:14:18.280+0000] {dagbag.py:387} ERROR - Failed to import: /opt/airflow/dags/__pycache__/fire_incidents_dag.py
Traceback (most recent call last):
  File "/home/airflow/.local/lib/python3.12/site-packages/airflow/models/dagbag.py", line 383, in parse
    loader.exec_module(new_module)
  File "<frozen importlib._bootstrap_external>", line 999, in exec_module
  File "<frozen importlib._bootstrap>", line 488, in _call_with_frames_removed
  File "/opt/airflow/dags/__pycache__/fire_incidents_dag.py", line 4, in <module>
    from pull_fire_incidents import pull_data_via_api
ModuleNotFoundError: No module named 'pull_fire_incidents'
[2025-02-25T23:14:18.281+0000] {processor.py:927} WARNING - No viable dags retrieved from /opt/airflow/dags/__pycache__/fire_incidents_dag.py
[2025-02-25T23:14:18.295+0000] {processor.py:208} INFO - Processing /opt/airflow/dags/__pycache__/fire_incidents_dag.py took 0.023 seconds
[2025-02-25T23:14:48.586+0000] {processor.py:186} INFO - Started process (PID=427) to work on /opt/airflow/dags/__pycache__/fire_incidents_dag.py
[2025-02-25T23:14:48.587+0000] {processor.py:914} INFO - Processing file /opt/airflow/dags/__pycache__/fire_incidents_dag.py for tasks to queue
[2025-02-25T23:14:48.589+0000] {logging_mixin.py:190} INFO - [2025-02-25T23:14:48.589+0000] {dagbag.py:588} INFO - Filling up the DagBag from /opt/airflow/dags/__pycache__/fire_incidents_dag.py
[2025-02-25T23:14:48.592+0000] {logging_mixin.py:190} INFO - [2025-02-25T23:14:48.591+0000] {dagbag.py:387} ERROR - Failed to import: /opt/airflow/dags/__pycache__/fire_incidents_dag.py
Traceback (most recent call last):
  File "/home/airflow/.local/lib/python3.12/site-packages/airflow/models/dagbag.py", line 383, in parse
    loader.exec_module(new_module)
  File "<frozen importlib._bootstrap_external>", line 999, in exec_module
  File "<frozen importlib._bootstrap>", line 488, in _call_with_frames_removed
  File "/opt/airflow/dags/__pycache__/fire_incidents_dag.py", line 4, in <module>
    from pull_fire_incidents import pull_data_via_api
ModuleNotFoundError: No module named 'pull_fire_incidents'
[2025-02-25T23:14:48.592+0000] {processor.py:927} WARNING - No viable dags retrieved from /opt/airflow/dags/__pycache__/fire_incidents_dag.py
[2025-02-25T23:14:48.608+0000] {processor.py:208} INFO - Processing /opt/airflow/dags/__pycache__/fire_incidents_dag.py took 0.027 seconds
[2025-02-25T23:15:18.632+0000] {processor.py:186} INFO - Started process (PID=491) to work on /opt/airflow/dags/__pycache__/fire_incidents_dag.py
[2025-02-25T23:15:18.633+0000] {processor.py:914} INFO - Processing file /opt/airflow/dags/__pycache__/fire_incidents_dag.py for tasks to queue
[2025-02-25T23:15:18.635+0000] {logging_mixin.py:190} INFO - [2025-02-25T23:15:18.635+0000] {dagbag.py:588} INFO - Filling up the DagBag from /opt/airflow/dags/__pycache__/fire_incidents_dag.py
[2025-02-25T23:15:18.637+0000] {logging_mixin.py:190} INFO - [2025-02-25T23:15:18.637+0000] {dagbag.py:387} ERROR - Failed to import: /opt/airflow/dags/__pycache__/fire_incidents_dag.py
Traceback (most recent call last):
  File "/home/airflow/.local/lib/python3.12/site-packages/airflow/models/dagbag.py", line 383, in parse
    loader.exec_module(new_module)
  File "<frozen importlib._bootstrap_external>", line 999, in exec_module
  File "<frozen importlib._bootstrap>", line 488, in _call_with_frames_removed
  File "/opt/airflow/dags/__pycache__/fire_incidents_dag.py", line 4, in <module>
    from pull_fire_incidents import pull_data_via_api
ModuleNotFoundError: No module named 'pull_fire_incidents'
[2025-02-25T23:15:18.638+0000] {processor.py:927} WARNING - No viable dags retrieved from /opt/airflow/dags/__pycache__/fire_incidents_dag.py
[2025-02-25T23:15:18.651+0000] {processor.py:208} INFO - Processing /opt/airflow/dags/__pycache__/fire_incidents_dag.py took 0.023 seconds
[2025-02-25T23:15:49.274+0000] {processor.py:186} INFO - Started process (PID=555) to work on /opt/airflow/dags/__pycache__/fire_incidents_dag.py
[2025-02-25T23:15:49.275+0000] {processor.py:914} INFO - Processing file /opt/airflow/dags/__pycache__/fire_incidents_dag.py for tasks to queue
[2025-02-25T23:15:49.277+0000] {logging_mixin.py:190} INFO - [2025-02-25T23:15:49.277+0000] {dagbag.py:588} INFO - Filling up the DagBag from /opt/airflow/dags/__pycache__/fire_incidents_dag.py
[2025-02-25T23:15:49.279+0000] {logging_mixin.py:190} INFO - [2025-02-25T23:15:49.279+0000] {dagbag.py:387} ERROR - Failed to import: /opt/airflow/dags/__pycache__/fire_incidents_dag.py
Traceback (most recent call last):
  File "/home/airflow/.local/lib/python3.12/site-packages/airflow/models/dagbag.py", line 383, in parse
    loader.exec_module(new_module)
  File "<frozen importlib._bootstrap_external>", line 999, in exec_module
  File "<frozen importlib._bootstrap>", line 488, in _call_with_frames_removed
  File "/opt/airflow/dags/__pycache__/fire_incidents_dag.py", line 4, in <module>
    from pull_fire_incidents import pull_data_via_api
ModuleNotFoundError: No module named 'pull_fire_incidents'
[2025-02-25T23:15:49.279+0000] {processor.py:927} WARNING - No viable dags retrieved from /opt/airflow/dags/__pycache__/fire_incidents_dag.py
[2025-02-25T23:15:49.292+0000] {processor.py:208} INFO - Processing /opt/airflow/dags/__pycache__/fire_incidents_dag.py took 0.021 seconds
[2025-02-25T23:16:19.590+0000] {processor.py:186} INFO - Started process (PID=619) to work on /opt/airflow/dags/__pycache__/fire_incidents_dag.py
[2025-02-25T23:16:19.590+0000] {processor.py:914} INFO - Processing file /opt/airflow/dags/__pycache__/fire_incidents_dag.py for tasks to queue
[2025-02-25T23:16:19.592+0000] {logging_mixin.py:190} INFO - [2025-02-25T23:16:19.592+0000] {dagbag.py:588} INFO - Filling up the DagBag from /opt/airflow/dags/__pycache__/fire_incidents_dag.py
[2025-02-25T23:16:19.594+0000] {logging_mixin.py:190} INFO - [2025-02-25T23:16:19.593+0000] {dagbag.py:387} ERROR - Failed to import: /opt/airflow/dags/__pycache__/fire_incidents_dag.py
Traceback (most recent call last):
  File "/home/airflow/.local/lib/python3.12/site-packages/airflow/models/dagbag.py", line 383, in parse
    loader.exec_module(new_module)
  File "<frozen importlib._bootstrap_external>", line 999, in exec_module
  File "<frozen importlib._bootstrap>", line 488, in _call_with_frames_removed
  File "/opt/airflow/dags/__pycache__/fire_incidents_dag.py", line 4, in <module>
    from pull_fire_incidents import pull_data_via_api
ModuleNotFoundError: No module named 'pull_fire_incidents'
[2025-02-25T23:16:19.594+0000] {processor.py:927} WARNING - No viable dags retrieved from /opt/airflow/dags/__pycache__/fire_incidents_dag.py
[2025-02-25T23:16:19.607+0000] {processor.py:208} INFO - Processing /opt/airflow/dags/__pycache__/fire_incidents_dag.py took 0.022 seconds
[2025-02-25T23:16:50.109+0000] {processor.py:186} INFO - Started process (PID=683) to work on /opt/airflow/dags/__pycache__/fire_incidents_dag.py
[2025-02-25T23:16:50.110+0000] {processor.py:914} INFO - Processing file /opt/airflow/dags/__pycache__/fire_incidents_dag.py for tasks to queue
[2025-02-25T23:16:50.111+0000] {logging_mixin.py:190} INFO - [2025-02-25T23:16:50.111+0000] {dagbag.py:588} INFO - Filling up the DagBag from /opt/airflow/dags/__pycache__/fire_incidents_dag.py
[2025-02-25T23:16:50.114+0000] {logging_mixin.py:190} INFO - [2025-02-25T23:16:50.113+0000] {dagbag.py:387} ERROR - Failed to import: /opt/airflow/dags/__pycache__/fire_incidents_dag.py
Traceback (most recent call last):
  File "/home/airflow/.local/lib/python3.12/site-packages/airflow/models/dagbag.py", line 383, in parse
    loader.exec_module(new_module)
  File "<frozen importlib._bootstrap_external>", line 999, in exec_module
  File "<frozen importlib._bootstrap>", line 488, in _call_with_frames_removed
  File "/opt/airflow/dags/__pycache__/fire_incidents_dag.py", line 4, in <module>
    from pull_fire_incidents import pull_data_via_api
ModuleNotFoundError: No module named 'pull_fire_incidents'
[2025-02-25T23:16:50.114+0000] {processor.py:927} WARNING - No viable dags retrieved from /opt/airflow/dags/__pycache__/fire_incidents_dag.py
[2025-02-25T23:16:50.131+0000] {processor.py:208} INFO - Processing /opt/airflow/dags/__pycache__/fire_incidents_dag.py took 0.026 seconds
[2025-02-25T23:17:20.668+0000] {processor.py:186} INFO - Started process (PID=747) to work on /opt/airflow/dags/__pycache__/fire_incidents_dag.py
[2025-02-25T23:17:20.668+0000] {processor.py:914} INFO - Processing file /opt/airflow/dags/__pycache__/fire_incidents_dag.py for tasks to queue
[2025-02-25T23:17:20.670+0000] {logging_mixin.py:190} INFO - [2025-02-25T23:17:20.670+0000] {dagbag.py:588} INFO - Filling up the DagBag from /opt/airflow/dags/__pycache__/fire_incidents_dag.py
[2025-02-25T23:17:20.672+0000] {logging_mixin.py:190} INFO - [2025-02-25T23:17:20.672+0000] {dagbag.py:387} ERROR - Failed to import: /opt/airflow/dags/__pycache__/fire_incidents_dag.py
Traceback (most recent call last):
  File "/home/airflow/.local/lib/python3.12/site-packages/airflow/models/dagbag.py", line 383, in parse
    loader.exec_module(new_module)
  File "<frozen importlib._bootstrap_external>", line 999, in exec_module
  File "<frozen importlib._bootstrap>", line 488, in _call_with_frames_removed
  File "/opt/airflow/dags/__pycache__/fire_incidents_dag.py", line 4, in <module>
    from pull_fire_incidents import pull_data_via_api
ModuleNotFoundError: No module named 'pull_fire_incidents'
[2025-02-25T23:17:20.672+0000] {processor.py:927} WARNING - No viable dags retrieved from /opt/airflow/dags/__pycache__/fire_incidents_dag.py
[2025-02-25T23:17:20.685+0000] {processor.py:208} INFO - Processing /opt/airflow/dags/__pycache__/fire_incidents_dag.py took 0.022 seconds
[2025-02-25T23:17:51.236+0000] {processor.py:186} INFO - Started process (PID=811) to work on /opt/airflow/dags/__pycache__/fire_incidents_dag.py
[2025-02-25T23:17:51.237+0000] {processor.py:914} INFO - Processing file /opt/airflow/dags/__pycache__/fire_incidents_dag.py for tasks to queue
[2025-02-25T23:17:51.239+0000] {logging_mixin.py:190} INFO - [2025-02-25T23:17:51.238+0000] {dagbag.py:588} INFO - Filling up the DagBag from /opt/airflow/dags/__pycache__/fire_incidents_dag.py
[2025-02-25T23:17:51.241+0000] {logging_mixin.py:190} INFO - [2025-02-25T23:17:51.240+0000] {dagbag.py:387} ERROR - Failed to import: /opt/airflow/dags/__pycache__/fire_incidents_dag.py
Traceback (most recent call last):
  File "/home/airflow/.local/lib/python3.12/site-packages/airflow/models/dagbag.py", line 383, in parse
    loader.exec_module(new_module)
  File "<frozen importlib._bootstrap_external>", line 999, in exec_module
  File "<frozen importlib._bootstrap>", line 488, in _call_with_frames_removed
  File "/opt/airflow/dags/__pycache__/fire_incidents_dag.py", line 4, in <module>
    from pull_fire_incidents import pull_data_via_api
ModuleNotFoundError: No module named 'pull_fire_incidents'
[2025-02-25T23:17:51.241+0000] {processor.py:927} WARNING - No viable dags retrieved from /opt/airflow/dags/__pycache__/fire_incidents_dag.py
[2025-02-25T23:17:51.255+0000] {processor.py:208} INFO - Processing /opt/airflow/dags/__pycache__/fire_incidents_dag.py took 0.024 seconds
[2025-02-25T23:18:21.910+0000] {processor.py:186} INFO - Started process (PID=875) to work on /opt/airflow/dags/__pycache__/fire_incidents_dag.py
[2025-02-25T23:18:21.913+0000] {processor.py:914} INFO - Processing file /opt/airflow/dags/__pycache__/fire_incidents_dag.py for tasks to queue
[2025-02-25T23:18:21.919+0000] {logging_mixin.py:190} INFO - [2025-02-25T23:18:21.918+0000] {dagbag.py:588} INFO - Filling up the DagBag from /opt/airflow/dags/__pycache__/fire_incidents_dag.py
[2025-02-25T23:18:21.923+0000] {logging_mixin.py:190} INFO - [2025-02-25T23:18:21.922+0000] {dagbag.py:387} ERROR - Failed to import: /opt/airflow/dags/__pycache__/fire_incidents_dag.py
Traceback (most recent call last):
  File "/home/airflow/.local/lib/python3.12/site-packages/airflow/models/dagbag.py", line 383, in parse
    loader.exec_module(new_module)
  File "<frozen importlib._bootstrap_external>", line 999, in exec_module
  File "<frozen importlib._bootstrap>", line 488, in _call_with_frames_removed
  File "/opt/airflow/dags/__pycache__/fire_incidents_dag.py", line 4, in <module>
    from pull_fire_incidents import pull_data_via_api
ModuleNotFoundError: No module named 'pull_fire_incidents'
[2025-02-25T23:18:21.924+0000] {processor.py:927} WARNING - No viable dags retrieved from /opt/airflow/dags/__pycache__/fire_incidents_dag.py
[2025-02-25T23:18:21.941+0000] {processor.py:208} INFO - Processing /opt/airflow/dags/__pycache__/fire_incidents_dag.py took 0.046 seconds
[2025-02-25T23:18:52.674+0000] {processor.py:186} INFO - Started process (PID=939) to work on /opt/airflow/dags/__pycache__/fire_incidents_dag.py
[2025-02-25T23:18:52.675+0000] {processor.py:914} INFO - Processing file /opt/airflow/dags/__pycache__/fire_incidents_dag.py for tasks to queue
[2025-02-25T23:18:52.679+0000] {logging_mixin.py:190} INFO - [2025-02-25T23:18:52.678+0000] {dagbag.py:588} INFO - Filling up the DagBag from /opt/airflow/dags/__pycache__/fire_incidents_dag.py
[2025-02-25T23:18:52.683+0000] {logging_mixin.py:190} INFO - [2025-02-25T23:18:52.682+0000] {dagbag.py:387} ERROR - Failed to import: /opt/airflow/dags/__pycache__/fire_incidents_dag.py
Traceback (most recent call last):
  File "/home/airflow/.local/lib/python3.12/site-packages/airflow/models/dagbag.py", line 383, in parse
    loader.exec_module(new_module)
  File "<frozen importlib._bootstrap_external>", line 999, in exec_module
  File "<frozen importlib._bootstrap>", line 488, in _call_with_frames_removed
  File "/opt/airflow/dags/__pycache__/fire_incidents_dag.py", line 4, in <module>
    from pull_fire_incidents import pull_data_via_api
ModuleNotFoundError: No module named 'pull_fire_incidents'
[2025-02-25T23:18:52.684+0000] {processor.py:927} WARNING - No viable dags retrieved from /opt/airflow/dags/__pycache__/fire_incidents_dag.py
[2025-02-25T23:18:52.699+0000] {processor.py:208} INFO - Processing /opt/airflow/dags/__pycache__/fire_incidents_dag.py took 0.034 seconds
[2025-02-25T23:19:22.898+0000] {processor.py:186} INFO - Started process (PID=1003) to work on /opt/airflow/dags/__pycache__/fire_incidents_dag.py
[2025-02-25T23:19:22.899+0000] {processor.py:914} INFO - Processing file /opt/airflow/dags/__pycache__/fire_incidents_dag.py for tasks to queue
[2025-02-25T23:19:22.901+0000] {logging_mixin.py:190} INFO - [2025-02-25T23:19:22.901+0000] {dagbag.py:588} INFO - Filling up the DagBag from /opt/airflow/dags/__pycache__/fire_incidents_dag.py
[2025-02-25T23:19:22.903+0000] {logging_mixin.py:190} INFO - [2025-02-25T23:19:22.903+0000] {dagbag.py:387} ERROR - Failed to import: /opt/airflow/dags/__pycache__/fire_incidents_dag.py
Traceback (most recent call last):
  File "/home/airflow/.local/lib/python3.12/site-packages/airflow/models/dagbag.py", line 383, in parse
    loader.exec_module(new_module)
  File "<frozen importlib._bootstrap_external>", line 999, in exec_module
  File "<frozen importlib._bootstrap>", line 488, in _call_with_frames_removed
  File "/opt/airflow/dags/__pycache__/fire_incidents_dag.py", line 4, in <module>
    from pull_fire_incidents import pull_data_via_api
ModuleNotFoundError: No module named 'pull_fire_incidents'
[2025-02-25T23:19:22.904+0000] {processor.py:927} WARNING - No viable dags retrieved from /opt/airflow/dags/__pycache__/fire_incidents_dag.py
[2025-02-25T23:19:22.917+0000] {processor.py:208} INFO - Processing /opt/airflow/dags/__pycache__/fire_incidents_dag.py took 0.022 seconds
[2025-02-25T23:19:53.035+0000] {processor.py:186} INFO - Started process (PID=1067) to work on /opt/airflow/dags/__pycache__/fire_incidents_dag.py
[2025-02-25T23:19:53.036+0000] {processor.py:914} INFO - Processing file /opt/airflow/dags/__pycache__/fire_incidents_dag.py for tasks to queue
[2025-02-25T23:19:53.039+0000] {logging_mixin.py:190} INFO - [2025-02-25T23:19:53.039+0000] {dagbag.py:588} INFO - Filling up the DagBag from /opt/airflow/dags/__pycache__/fire_incidents_dag.py
[2025-02-25T23:19:53.044+0000] {logging_mixin.py:190} INFO - [2025-02-25T23:19:53.043+0000] {dagbag.py:387} ERROR - Failed to import: /opt/airflow/dags/__pycache__/fire_incidents_dag.py
Traceback (most recent call last):
  File "/home/airflow/.local/lib/python3.12/site-packages/airflow/models/dagbag.py", line 383, in parse
    loader.exec_module(new_module)
  File "<frozen importlib._bootstrap_external>", line 999, in exec_module
  File "<frozen importlib._bootstrap>", line 488, in _call_with_frames_removed
  File "/opt/airflow/dags/__pycache__/fire_incidents_dag.py", line 4, in <module>
    from pull_fire_incidents import pull_data_via_api
ModuleNotFoundError: No module named 'pull_fire_incidents'
[2025-02-25T23:19:53.045+0000] {processor.py:927} WARNING - No viable dags retrieved from /opt/airflow/dags/__pycache__/fire_incidents_dag.py
[2025-02-25T23:19:53.065+0000] {processor.py:208} INFO - Processing /opt/airflow/dags/__pycache__/fire_incidents_dag.py took 0.051 seconds
[2025-02-25T23:20:23.164+0000] {processor.py:186} INFO - Started process (PID=1131) to work on /opt/airflow/dags/__pycache__/fire_incidents_dag.py
[2025-02-25T23:20:23.165+0000] {processor.py:914} INFO - Processing file /opt/airflow/dags/__pycache__/fire_incidents_dag.py for tasks to queue
[2025-02-25T23:20:23.167+0000] {logging_mixin.py:190} INFO - [2025-02-25T23:20:23.167+0000] {dagbag.py:588} INFO - Filling up the DagBag from /opt/airflow/dags/__pycache__/fire_incidents_dag.py
[2025-02-25T23:20:23.171+0000] {logging_mixin.py:190} INFO - [2025-02-25T23:20:23.170+0000] {dagbag.py:387} ERROR - Failed to import: /opt/airflow/dags/__pycache__/fire_incidents_dag.py
Traceback (most recent call last):
  File "/home/airflow/.local/lib/python3.12/site-packages/airflow/models/dagbag.py", line 383, in parse
    loader.exec_module(new_module)
  File "<frozen importlib._bootstrap_external>", line 999, in exec_module
  File "<frozen importlib._bootstrap>", line 488, in _call_with_frames_removed
  File "/opt/airflow/dags/__pycache__/fire_incidents_dag.py", line 4, in <module>
    from pull_fire_incidents import pull_data_via_api
ModuleNotFoundError: No module named 'pull_fire_incidents'
[2025-02-25T23:20:23.172+0000] {processor.py:927} WARNING - No viable dags retrieved from /opt/airflow/dags/__pycache__/fire_incidents_dag.py
[2025-02-25T23:20:23.188+0000] {processor.py:208} INFO - Processing /opt/airflow/dags/__pycache__/fire_incidents_dag.py took 0.030 seconds
[2025-02-25T23:20:53.609+0000] {processor.py:186} INFO - Started process (PID=1195) to work on /opt/airflow/dags/__pycache__/fire_incidents_dag.py
[2025-02-25T23:20:53.610+0000] {processor.py:914} INFO - Processing file /opt/airflow/dags/__pycache__/fire_incidents_dag.py for tasks to queue
[2025-02-25T23:20:53.611+0000] {logging_mixin.py:190} INFO - [2025-02-25T23:20:53.611+0000] {dagbag.py:588} INFO - Filling up the DagBag from /opt/airflow/dags/__pycache__/fire_incidents_dag.py
[2025-02-25T23:20:53.614+0000] {logging_mixin.py:190} INFO - [2025-02-25T23:20:53.613+0000] {dagbag.py:387} ERROR - Failed to import: /opt/airflow/dags/__pycache__/fire_incidents_dag.py
Traceback (most recent call last):
  File "/home/airflow/.local/lib/python3.12/site-packages/airflow/models/dagbag.py", line 383, in parse
    loader.exec_module(new_module)
  File "<frozen importlib._bootstrap_external>", line 999, in exec_module
  File "<frozen importlib._bootstrap>", line 488, in _call_with_frames_removed
  File "/opt/airflow/dags/__pycache__/fire_incidents_dag.py", line 4, in <module>
    from pull_fire_incidents import pull_data_via_api
ModuleNotFoundError: No module named 'pull_fire_incidents'
[2025-02-25T23:20:53.614+0000] {processor.py:927} WARNING - No viable dags retrieved from /opt/airflow/dags/__pycache__/fire_incidents_dag.py
[2025-02-25T23:20:53.629+0000] {processor.py:208} INFO - Processing /opt/airflow/dags/__pycache__/fire_incidents_dag.py took 0.025 seconds
[2025-02-25T23:21:24.395+0000] {processor.py:186} INFO - Started process (PID=1259) to work on /opt/airflow/dags/__pycache__/fire_incidents_dag.py
[2025-02-25T23:21:24.398+0000] {processor.py:914} INFO - Processing file /opt/airflow/dags/__pycache__/fire_incidents_dag.py for tasks to queue
[2025-02-25T23:21:24.402+0000] {logging_mixin.py:190} INFO - [2025-02-25T23:21:24.401+0000] {dagbag.py:588} INFO - Filling up the DagBag from /opt/airflow/dags/__pycache__/fire_incidents_dag.py
[2025-02-25T23:21:24.405+0000] {logging_mixin.py:190} INFO - [2025-02-25T23:21:24.404+0000] {dagbag.py:387} ERROR - Failed to import: /opt/airflow/dags/__pycache__/fire_incidents_dag.py
Traceback (most recent call last):
  File "/home/airflow/.local/lib/python3.12/site-packages/airflow/models/dagbag.py", line 383, in parse
    loader.exec_module(new_module)
  File "<frozen importlib._bootstrap_external>", line 999, in exec_module
  File "<frozen importlib._bootstrap>", line 488, in _call_with_frames_removed
  File "/opt/airflow/dags/__pycache__/fire_incidents_dag.py", line 4, in <module>
    from pull_fire_incidents import pull_data_via_api
ModuleNotFoundError: No module named 'pull_fire_incidents'
[2025-02-25T23:21:24.405+0000] {processor.py:927} WARNING - No viable dags retrieved from /opt/airflow/dags/__pycache__/fire_incidents_dag.py
[2025-02-25T23:21:24.421+0000] {processor.py:208} INFO - Processing /opt/airflow/dags/__pycache__/fire_incidents_dag.py took 0.038 seconds
[2025-02-25T23:21:54.976+0000] {processor.py:186} INFO - Started process (PID=1323) to work on /opt/airflow/dags/__pycache__/fire_incidents_dag.py
[2025-02-25T23:21:54.978+0000] {processor.py:914} INFO - Processing file /opt/airflow/dags/__pycache__/fire_incidents_dag.py for tasks to queue
[2025-02-25T23:21:54.981+0000] {logging_mixin.py:190} INFO - [2025-02-25T23:21:54.981+0000] {dagbag.py:588} INFO - Filling up the DagBag from /opt/airflow/dags/__pycache__/fire_incidents_dag.py
[2025-02-25T23:21:54.986+0000] {logging_mixin.py:190} INFO - [2025-02-25T23:21:54.985+0000] {dagbag.py:387} ERROR - Failed to import: /opt/airflow/dags/__pycache__/fire_incidents_dag.py
Traceback (most recent call last):
  File "/home/airflow/.local/lib/python3.12/site-packages/airflow/models/dagbag.py", line 383, in parse
    loader.exec_module(new_module)
  File "<frozen importlib._bootstrap_external>", line 999, in exec_module
  File "<frozen importlib._bootstrap>", line 488, in _call_with_frames_removed
  File "/opt/airflow/dags/__pycache__/fire_incidents_dag.py", line 4, in <module>
    from pull_fire_incidents import pull_data_via_api
ModuleNotFoundError: No module named 'pull_fire_incidents'
[2025-02-25T23:21:54.987+0000] {processor.py:927} WARNING - No viable dags retrieved from /opt/airflow/dags/__pycache__/fire_incidents_dag.py
[2025-02-25T23:21:55.015+0000] {processor.py:208} INFO - Processing /opt/airflow/dags/__pycache__/fire_incidents_dag.py took 0.051 seconds
[2025-02-25T23:22:25.352+0000] {processor.py:186} INFO - Started process (PID=1387) to work on /opt/airflow/dags/__pycache__/fire_incidents_dag.py
[2025-02-25T23:22:25.354+0000] {processor.py:914} INFO - Processing file /opt/airflow/dags/__pycache__/fire_incidents_dag.py for tasks to queue
[2025-02-25T23:22:25.356+0000] {logging_mixin.py:190} INFO - [2025-02-25T23:22:25.356+0000] {dagbag.py:588} INFO - Filling up the DagBag from /opt/airflow/dags/__pycache__/fire_incidents_dag.py
[2025-02-25T23:22:25.361+0000] {logging_mixin.py:190} INFO - [2025-02-25T23:22:25.360+0000] {dagbag.py:387} ERROR - Failed to import: /opt/airflow/dags/__pycache__/fire_incidents_dag.py
Traceback (most recent call last):
  File "/home/airflow/.local/lib/python3.12/site-packages/airflow/models/dagbag.py", line 383, in parse
    loader.exec_module(new_module)
  File "<frozen importlib._bootstrap_external>", line 999, in exec_module
  File "<frozen importlib._bootstrap>", line 488, in _call_with_frames_removed
  File "/opt/airflow/dags/__pycache__/fire_incidents_dag.py", line 4, in <module>
    from pull_fire_incidents import pull_data_via_api
ModuleNotFoundError: No module named 'pull_fire_incidents'
[2025-02-25T23:22:25.362+0000] {processor.py:927} WARNING - No viable dags retrieved from /opt/airflow/dags/__pycache__/fire_incidents_dag.py
[2025-02-25T23:22:25.374+0000] {processor.py:208} INFO - Processing /opt/airflow/dags/__pycache__/fire_incidents_dag.py took 0.030 seconds
[2025-02-25T23:22:55.818+0000] {processor.py:186} INFO - Started process (PID=1451) to work on /opt/airflow/dags/__pycache__/fire_incidents_dag.py
[2025-02-25T23:22:55.819+0000] {processor.py:914} INFO - Processing file /opt/airflow/dags/__pycache__/fire_incidents_dag.py for tasks to queue
[2025-02-25T23:22:55.822+0000] {logging_mixin.py:190} INFO - [2025-02-25T23:22:55.822+0000] {dagbag.py:588} INFO - Filling up the DagBag from /opt/airflow/dags/__pycache__/fire_incidents_dag.py
[2025-02-25T23:22:55.828+0000] {logging_mixin.py:190} INFO - [2025-02-25T23:22:55.826+0000] {dagbag.py:387} ERROR - Failed to import: /opt/airflow/dags/__pycache__/fire_incidents_dag.py
Traceback (most recent call last):
  File "/home/airflow/.local/lib/python3.12/site-packages/airflow/models/dagbag.py", line 383, in parse
    loader.exec_module(new_module)
  File "<frozen importlib._bootstrap_external>", line 999, in exec_module
  File "<frozen importlib._bootstrap>", line 488, in _call_with_frames_removed
  File "/opt/airflow/dags/__pycache__/fire_incidents_dag.py", line 4, in <module>
    from pull_fire_incidents import pull_data_via_api
ModuleNotFoundError: No module named 'pull_fire_incidents'
[2025-02-25T23:22:55.828+0000] {processor.py:927} WARNING - No viable dags retrieved from /opt/airflow/dags/__pycache__/fire_incidents_dag.py
[2025-02-25T23:22:55.851+0000] {processor.py:208} INFO - Processing /opt/airflow/dags/__pycache__/fire_incidents_dag.py took 0.042 seconds
[2025-02-25T23:23:26.146+0000] {processor.py:186} INFO - Started process (PID=1515) to work on /opt/airflow/dags/__pycache__/fire_incidents_dag.py
[2025-02-25T23:23:26.147+0000] {processor.py:914} INFO - Processing file /opt/airflow/dags/__pycache__/fire_incidents_dag.py for tasks to queue
[2025-02-25T23:23:26.149+0000] {logging_mixin.py:190} INFO - [2025-02-25T23:23:26.149+0000] {dagbag.py:588} INFO - Filling up the DagBag from /opt/airflow/dags/__pycache__/fire_incidents_dag.py
[2025-02-25T23:23:26.152+0000] {logging_mixin.py:190} INFO - [2025-02-25T23:23:26.151+0000] {dagbag.py:387} ERROR - Failed to import: /opt/airflow/dags/__pycache__/fire_incidents_dag.py
Traceback (most recent call last):
  File "/home/airflow/.local/lib/python3.12/site-packages/airflow/models/dagbag.py", line 383, in parse
    loader.exec_module(new_module)
  File "<frozen importlib._bootstrap_external>", line 999, in exec_module
  File "<frozen importlib._bootstrap>", line 488, in _call_with_frames_removed
  File "/opt/airflow/dags/__pycache__/fire_incidents_dag.py", line 4, in <module>
    from pull_fire_incidents import pull_data_via_api
ModuleNotFoundError: No module named 'pull_fire_incidents'
[2025-02-25T23:23:26.153+0000] {processor.py:927} WARNING - No viable dags retrieved from /opt/airflow/dags/__pycache__/fire_incidents_dag.py
[2025-02-25T23:23:26.171+0000] {processor.py:208} INFO - Processing /opt/airflow/dags/__pycache__/fire_incidents_dag.py took 0.032 seconds
[2025-02-25T23:23:56.697+0000] {processor.py:186} INFO - Started process (PID=1579) to work on /opt/airflow/dags/__pycache__/fire_incidents_dag.py
[2025-02-25T23:23:56.698+0000] {processor.py:914} INFO - Processing file /opt/airflow/dags/__pycache__/fire_incidents_dag.py for tasks to queue
[2025-02-25T23:23:56.699+0000] {logging_mixin.py:190} INFO - [2025-02-25T23:23:56.699+0000] {dagbag.py:588} INFO - Filling up the DagBag from /opt/airflow/dags/__pycache__/fire_incidents_dag.py
[2025-02-25T23:23:56.701+0000] {logging_mixin.py:190} INFO - [2025-02-25T23:23:56.701+0000] {dagbag.py:387} ERROR - Failed to import: /opt/airflow/dags/__pycache__/fire_incidents_dag.py
Traceback (most recent call last):
  File "/home/airflow/.local/lib/python3.12/site-packages/airflow/models/dagbag.py", line 383, in parse
    loader.exec_module(new_module)
  File "<frozen importlib._bootstrap_external>", line 999, in exec_module
  File "<frozen importlib._bootstrap>", line 488, in _call_with_frames_removed
  File "/opt/airflow/dags/__pycache__/fire_incidents_dag.py", line 4, in <module>
    from pull_fire_incidents import pull_data_via_api
ModuleNotFoundError: No module named 'pull_fire_incidents'
[2025-02-25T23:23:56.702+0000] {processor.py:927} WARNING - No viable dags retrieved from /opt/airflow/dags/__pycache__/fire_incidents_dag.py
[2025-02-25T23:23:56.715+0000] {processor.py:208} INFO - Processing /opt/airflow/dags/__pycache__/fire_incidents_dag.py took 0.022 seconds
[2025-02-25T23:24:27.300+0000] {processor.py:186} INFO - Started process (PID=1643) to work on /opt/airflow/dags/__pycache__/fire_incidents_dag.py
[2025-02-25T23:24:27.301+0000] {processor.py:914} INFO - Processing file /opt/airflow/dags/__pycache__/fire_incidents_dag.py for tasks to queue
[2025-02-25T23:24:27.303+0000] {logging_mixin.py:190} INFO - [2025-02-25T23:24:27.303+0000] {dagbag.py:588} INFO - Filling up the DagBag from /opt/airflow/dags/__pycache__/fire_incidents_dag.py
[2025-02-25T23:24:27.306+0000] {logging_mixin.py:190} INFO - [2025-02-25T23:24:27.305+0000] {dagbag.py:387} ERROR - Failed to import: /opt/airflow/dags/__pycache__/fire_incidents_dag.py
Traceback (most recent call last):
  File "/home/airflow/.local/lib/python3.12/site-packages/airflow/models/dagbag.py", line 383, in parse
    loader.exec_module(new_module)
  File "<frozen importlib._bootstrap_external>", line 999, in exec_module
  File "<frozen importlib._bootstrap>", line 488, in _call_with_frames_removed
  File "/opt/airflow/dags/__pycache__/fire_incidents_dag.py", line 4, in <module>
    from pull_fire_incidents import pull_data_via_api
ModuleNotFoundError: No module named 'pull_fire_incidents'
[2025-02-25T23:24:27.306+0000] {processor.py:927} WARNING - No viable dags retrieved from /opt/airflow/dags/__pycache__/fire_incidents_dag.py
[2025-02-25T23:24:27.323+0000] {processor.py:208} INFO - Processing /opt/airflow/dags/__pycache__/fire_incidents_dag.py took 0.028 seconds
[2025-02-25T23:24:57.894+0000] {processor.py:186} INFO - Started process (PID=1707) to work on /opt/airflow/dags/__pycache__/fire_incidents_dag.py
[2025-02-25T23:24:57.895+0000] {processor.py:914} INFO - Processing file /opt/airflow/dags/__pycache__/fire_incidents_dag.py for tasks to queue
[2025-02-25T23:24:57.896+0000] {logging_mixin.py:190} INFO - [2025-02-25T23:24:57.896+0000] {dagbag.py:588} INFO - Filling up the DagBag from /opt/airflow/dags/__pycache__/fire_incidents_dag.py
[2025-02-25T23:24:57.899+0000] {logging_mixin.py:190} INFO - [2025-02-25T23:24:57.898+0000] {dagbag.py:387} ERROR - Failed to import: /opt/airflow/dags/__pycache__/fire_incidents_dag.py
Traceback (most recent call last):
  File "/home/airflow/.local/lib/python3.12/site-packages/airflow/models/dagbag.py", line 383, in parse
    loader.exec_module(new_module)
  File "<frozen importlib._bootstrap_external>", line 999, in exec_module
  File "<frozen importlib._bootstrap>", line 488, in _call_with_frames_removed
  File "/opt/airflow/dags/__pycache__/fire_incidents_dag.py", line 4, in <module>
    from pull_fire_incidents import pull_data_via_api
ModuleNotFoundError: No module named 'pull_fire_incidents'
[2025-02-25T23:24:57.899+0000] {processor.py:927} WARNING - No viable dags retrieved from /opt/airflow/dags/__pycache__/fire_incidents_dag.py
[2025-02-25T23:24:57.912+0000] {processor.py:208} INFO - Processing /opt/airflow/dags/__pycache__/fire_incidents_dag.py took 0.022 seconds
[2025-02-25T23:25:28.282+0000] {processor.py:186} INFO - Started process (PID=1771) to work on /opt/airflow/dags/__pycache__/fire_incidents_dag.py
[2025-02-25T23:25:28.283+0000] {processor.py:914} INFO - Processing file /opt/airflow/dags/__pycache__/fire_incidents_dag.py for tasks to queue
[2025-02-25T23:25:28.285+0000] {logging_mixin.py:190} INFO - [2025-02-25T23:25:28.285+0000] {dagbag.py:588} INFO - Filling up the DagBag from /opt/airflow/dags/__pycache__/fire_incidents_dag.py
[2025-02-25T23:25:28.288+0000] {logging_mixin.py:190} INFO - [2025-02-25T23:25:28.287+0000] {dagbag.py:387} ERROR - Failed to import: /opt/airflow/dags/__pycache__/fire_incidents_dag.py
Traceback (most recent call last):
  File "/home/airflow/.local/lib/python3.12/site-packages/airflow/models/dagbag.py", line 383, in parse
    loader.exec_module(new_module)
  File "<frozen importlib._bootstrap_external>", line 999, in exec_module
  File "<frozen importlib._bootstrap>", line 488, in _call_with_frames_removed
  File "/opt/airflow/dags/__pycache__/fire_incidents_dag.py", line 4, in <module>
    from pull_fire_incidents import pull_data_via_api
ModuleNotFoundError: No module named 'pull_fire_incidents'
[2025-02-25T23:25:28.288+0000] {processor.py:927} WARNING - No viable dags retrieved from /opt/airflow/dags/__pycache__/fire_incidents_dag.py
[2025-02-25T23:25:28.301+0000] {processor.py:208} INFO - Processing /opt/airflow/dags/__pycache__/fire_incidents_dag.py took 0.025 seconds
