[2025-02-25T22:56:45.614+0000] {processor.py:186} INFO - Started process (PID=44) to work on /opt/airflow/dags/fire_incidents_dag.py
[2025-02-25T22:56:45.622+0000] {processor.py:914} INFO - Processing file /opt/airflow/dags/fire_incidents_dag.py for tasks to queue
[2025-02-25T22:56:45.833+0000] {logging_mixin.py:190} INFO - [2025-02-25T22:56:45.833+0000] {dagbag.py:588} INFO - Filling up the DagBag from /opt/airflow/dags/fire_incidents_dag.py
[2025-02-25T22:56:45.931+0000] {logging_mixin.py:190} INFO - [2025-02-25T22:56:45.929+0000] {dagbag.py:387} ERROR - Failed to import: /opt/airflow/dags/fire_incidents_dag.py
Traceback (most recent call last):
  File "/home/airflow/.local/lib/python3.12/site-packages/airflow/models/dagbag.py", line 383, in parse
    loader.exec_module(new_module)
  File "<frozen importlib._bootstrap_external>", line 999, in exec_module
  File "<frozen importlib._bootstrap>", line 488, in _call_with_frames_removed
  File "/opt/airflow/dags/fire_incidents_dag.py", line 4, in <module>
    from pull_fire_incidents import pull_data_via_api
ModuleNotFoundError: No module named 'pull_fire_incidents'
[2025-02-25T22:56:45.932+0000] {processor.py:927} WARNING - No viable dags retrieved from /opt/airflow/dags/fire_incidents_dag.py
[2025-02-25T22:56:45.985+0000] {processor.py:208} INFO - Processing /opt/airflow/dags/fire_incidents_dag.py took 0.397 seconds
[2025-02-25T22:57:16.759+0000] {processor.py:186} INFO - Started process (PID=108) to work on /opt/airflow/dags/fire_incidents_dag.py
[2025-02-25T22:57:16.865+0000] {processor.py:914} INFO - Processing file /opt/airflow/dags/fire_incidents_dag.py for tasks to queue
[2025-02-25T22:57:16.866+0000] {logging_mixin.py:190} INFO - [2025-02-25T22:57:16.866+0000] {dagbag.py:588} INFO - Filling up the DagBag from /opt/airflow/dags/fire_incidents_dag.py
[2025-02-25T22:57:16.870+0000] {logging_mixin.py:190} INFO - [2025-02-25T22:57:16.869+0000] {dagbag.py:387} ERROR - Failed to import: /opt/airflow/dags/fire_incidents_dag.py
Traceback (most recent call last):
  File "/home/airflow/.local/lib/python3.12/site-packages/airflow/models/dagbag.py", line 383, in parse
    loader.exec_module(new_module)
  File "<frozen importlib._bootstrap_external>", line 999, in exec_module
  File "<frozen importlib._bootstrap>", line 488, in _call_with_frames_removed
  File "/opt/airflow/dags/fire_incidents_dag.py", line 4, in <module>
    from pull_fire_incidents import pull_data_via_api
ModuleNotFoundError: No module named 'pull_fire_incidents'
[2025-02-25T22:57:16.870+0000] {processor.py:927} WARNING - No viable dags retrieved from /opt/airflow/dags/fire_incidents_dag.py
[2025-02-25T22:57:16.887+0000] {processor.py:208} INFO - Processing /opt/airflow/dags/fire_incidents_dag.py took 0.132 seconds
[2025-02-25T22:57:47.359+0000] {processor.py:186} INFO - Started process (PID=165) to work on /opt/airflow/dags/fire_incidents_dag.py
[2025-02-25T22:57:47.362+0000] {processor.py:914} INFO - Processing file /opt/airflow/dags/fire_incidents_dag.py for tasks to queue
[2025-02-25T22:57:47.368+0000] {logging_mixin.py:190} INFO - [2025-02-25T22:57:47.368+0000] {dagbag.py:588} INFO - Filling up the DagBag from /opt/airflow/dags/fire_incidents_dag.py
[2025-02-25T22:57:47.378+0000] {logging_mixin.py:190} INFO - [2025-02-25T22:57:47.376+0000] {dagbag.py:387} ERROR - Failed to import: /opt/airflow/dags/fire_incidents_dag.py
Traceback (most recent call last):
  File "/home/airflow/.local/lib/python3.12/site-packages/airflow/models/dagbag.py", line 383, in parse
    loader.exec_module(new_module)
  File "<frozen importlib._bootstrap_external>", line 999, in exec_module
  File "<frozen importlib._bootstrap>", line 488, in _call_with_frames_removed
  File "/opt/airflow/dags/fire_incidents_dag.py", line 4, in <module>
    from pull_fire_incidents import pull_data_via_api
ModuleNotFoundError: No module named 'pull_fire_incidents'
[2025-02-25T22:57:47.380+0000] {processor.py:927} WARNING - No viable dags retrieved from /opt/airflow/dags/fire_incidents_dag.py
[2025-02-25T22:57:47.408+0000] {processor.py:208} INFO - Processing /opt/airflow/dags/fire_incidents_dag.py took 0.055 seconds
[2025-02-25T22:58:17.652+0000] {processor.py:186} INFO - Started process (PID=229) to work on /opt/airflow/dags/fire_incidents_dag.py
[2025-02-25T22:58:17.654+0000] {processor.py:914} INFO - Processing file /opt/airflow/dags/fire_incidents_dag.py for tasks to queue
[2025-02-25T22:58:17.665+0000] {logging_mixin.py:190} INFO - [2025-02-25T22:58:17.665+0000] {dagbag.py:588} INFO - Filling up the DagBag from /opt/airflow/dags/fire_incidents_dag.py
[2025-02-25T22:58:17.668+0000] {logging_mixin.py:190} INFO - [2025-02-25T22:58:17.667+0000] {dagbag.py:387} ERROR - Failed to import: /opt/airflow/dags/fire_incidents_dag.py
Traceback (most recent call last):
  File "/home/airflow/.local/lib/python3.12/site-packages/airflow/models/dagbag.py", line 383, in parse
    loader.exec_module(new_module)
  File "<frozen importlib._bootstrap_external>", line 999, in exec_module
  File "<frozen importlib._bootstrap>", line 488, in _call_with_frames_removed
  File "/opt/airflow/dags/fire_incidents_dag.py", line 4, in <module>
    from pull_fire_incidents import pull_data_via_api
ModuleNotFoundError: No module named 'pull_fire_incidents'
[2025-02-25T22:58:17.668+0000] {processor.py:927} WARNING - No viable dags retrieved from /opt/airflow/dags/fire_incidents_dag.py
[2025-02-25T22:58:17.688+0000] {processor.py:208} INFO - Processing /opt/airflow/dags/fire_incidents_dag.py took 0.044 seconds
[2025-02-25T22:58:47.986+0000] {processor.py:186} INFO - Started process (PID=293) to work on /opt/airflow/dags/fire_incidents_dag.py
[2025-02-25T22:58:47.988+0000] {processor.py:914} INFO - Processing file /opt/airflow/dags/fire_incidents_dag.py for tasks to queue
[2025-02-25T22:58:47.991+0000] {logging_mixin.py:190} INFO - [2025-02-25T22:58:47.991+0000] {dagbag.py:588} INFO - Filling up the DagBag from /opt/airflow/dags/fire_incidents_dag.py
[2025-02-25T22:58:47.996+0000] {logging_mixin.py:190} INFO - [2025-02-25T22:58:47.995+0000] {dagbag.py:387} ERROR - Failed to import: /opt/airflow/dags/fire_incidents_dag.py
Traceback (most recent call last):
  File "/home/airflow/.local/lib/python3.12/site-packages/airflow/models/dagbag.py", line 383, in parse
    loader.exec_module(new_module)
  File "<frozen importlib._bootstrap_external>", line 999, in exec_module
  File "<frozen importlib._bootstrap>", line 488, in _call_with_frames_removed
  File "/opt/airflow/dags/fire_incidents_dag.py", line 4, in <module>
    from pull_fire_incidents import pull_data_via_api
ModuleNotFoundError: No module named 'pull_fire_incidents'
[2025-02-25T22:58:47.996+0000] {processor.py:927} WARNING - No viable dags retrieved from /opt/airflow/dags/fire_incidents_dag.py
[2025-02-25T22:58:48.013+0000] {processor.py:208} INFO - Processing /opt/airflow/dags/fire_incidents_dag.py took 0.039 seconds
[2025-02-25T22:59:18.937+0000] {processor.py:186} INFO - Started process (PID=357) to work on /opt/airflow/dags/fire_incidents_dag.py
[2025-02-25T22:59:18.938+0000] {processor.py:914} INFO - Processing file /opt/airflow/dags/fire_incidents_dag.py for tasks to queue
[2025-02-25T22:59:18.940+0000] {logging_mixin.py:190} INFO - [2025-02-25T22:59:18.940+0000] {dagbag.py:588} INFO - Filling up the DagBag from /opt/airflow/dags/fire_incidents_dag.py
[2025-02-25T22:59:18.944+0000] {logging_mixin.py:190} INFO - [2025-02-25T22:59:18.943+0000] {dagbag.py:387} ERROR - Failed to import: /opt/airflow/dags/fire_incidents_dag.py
Traceback (most recent call last):
  File "/home/airflow/.local/lib/python3.12/site-packages/airflow/models/dagbag.py", line 383, in parse
    loader.exec_module(new_module)
  File "<frozen importlib._bootstrap_external>", line 999, in exec_module
  File "<frozen importlib._bootstrap>", line 488, in _call_with_frames_removed
  File "/opt/airflow/dags/fire_incidents_dag.py", line 4, in <module>
    from pull_fire_incidents import pull_data_via_api
ModuleNotFoundError: No module named 'pull_fire_incidents'
[2025-02-25T22:59:18.945+0000] {processor.py:927} WARNING - No viable dags retrieved from /opt/airflow/dags/fire_incidents_dag.py
[2025-02-25T22:59:18.967+0000] {processor.py:208} INFO - Processing /opt/airflow/dags/fire_incidents_dag.py took 0.132 seconds
[2025-02-25T22:59:49.432+0000] {processor.py:186} INFO - Started process (PID=420) to work on /opt/airflow/dags/fire_incidents_dag.py
[2025-02-25T22:59:49.433+0000] {processor.py:914} INFO - Processing file /opt/airflow/dags/fire_incidents_dag.py for tasks to queue
[2025-02-25T22:59:49.435+0000] {logging_mixin.py:190} INFO - [2025-02-25T22:59:49.435+0000] {dagbag.py:588} INFO - Filling up the DagBag from /opt/airflow/dags/fire_incidents_dag.py
[2025-02-25T22:59:49.437+0000] {logging_mixin.py:190} INFO - [2025-02-25T22:59:49.437+0000] {dagbag.py:387} ERROR - Failed to import: /opt/airflow/dags/fire_incidents_dag.py
Traceback (most recent call last):
  File "/home/airflow/.local/lib/python3.12/site-packages/airflow/models/dagbag.py", line 383, in parse
    loader.exec_module(new_module)
  File "<frozen importlib._bootstrap_external>", line 999, in exec_module
  File "<frozen importlib._bootstrap>", line 488, in _call_with_frames_removed
  File "/opt/airflow/dags/fire_incidents_dag.py", line 4, in <module>
    from pull_fire_incidents import pull_data_via_api
ModuleNotFoundError: No module named 'pull_fire_incidents'
[2025-02-25T22:59:49.438+0000] {processor.py:927} WARNING - No viable dags retrieved from /opt/airflow/dags/fire_incidents_dag.py
[2025-02-25T22:59:49.454+0000] {processor.py:208} INFO - Processing /opt/airflow/dags/fire_incidents_dag.py took 0.027 seconds
[2025-02-25T23:00:19.529+0000] {processor.py:186} INFO - Started process (PID=484) to work on /opt/airflow/dags/fire_incidents_dag.py
[2025-02-25T23:00:19.530+0000] {processor.py:914} INFO - Processing file /opt/airflow/dags/fire_incidents_dag.py for tasks to queue
[2025-02-25T23:00:19.533+0000] {logging_mixin.py:190} INFO - [2025-02-25T23:00:19.532+0000] {dagbag.py:588} INFO - Filling up the DagBag from /opt/airflow/dags/fire_incidents_dag.py
[2025-02-25T23:00:19.537+0000] {logging_mixin.py:190} INFO - [2025-02-25T23:00:19.535+0000] {dagbag.py:387} ERROR - Failed to import: /opt/airflow/dags/fire_incidents_dag.py
Traceback (most recent call last):
  File "/home/airflow/.local/lib/python3.12/site-packages/airflow/models/dagbag.py", line 383, in parse
    loader.exec_module(new_module)
  File "<frozen importlib._bootstrap_external>", line 999, in exec_module
  File "<frozen importlib._bootstrap>", line 488, in _call_with_frames_removed
  File "/opt/airflow/dags/fire_incidents_dag.py", line 4, in <module>
    from pull_fire_incidents import pull_data_via_api
ModuleNotFoundError: No module named 'pull_fire_incidents'
[2025-02-25T23:00:19.537+0000] {processor.py:927} WARNING - No viable dags retrieved from /opt/airflow/dags/fire_incidents_dag.py
[2025-02-25T23:00:19.557+0000] {processor.py:208} INFO - Processing /opt/airflow/dags/fire_incidents_dag.py took 0.039 seconds
[2025-02-25T23:00:49.751+0000] {processor.py:186} INFO - Started process (PID=548) to work on /opt/airflow/dags/fire_incidents_dag.py
[2025-02-25T23:00:49.753+0000] {processor.py:914} INFO - Processing file /opt/airflow/dags/fire_incidents_dag.py for tasks to queue
[2025-02-25T23:00:49.754+0000] {logging_mixin.py:190} INFO - [2025-02-25T23:00:49.754+0000] {dagbag.py:588} INFO - Filling up the DagBag from /opt/airflow/dags/fire_incidents_dag.py
[2025-02-25T23:00:49.757+0000] {logging_mixin.py:190} INFO - [2025-02-25T23:00:49.756+0000] {dagbag.py:387} ERROR - Failed to import: /opt/airflow/dags/fire_incidents_dag.py
Traceback (most recent call last):
  File "/home/airflow/.local/lib/python3.12/site-packages/airflow/models/dagbag.py", line 383, in parse
    loader.exec_module(new_module)
  File "<frozen importlib._bootstrap_external>", line 999, in exec_module
  File "<frozen importlib._bootstrap>", line 488, in _call_with_frames_removed
  File "/opt/airflow/dags/fire_incidents_dag.py", line 4, in <module>
    from pull_fire_incidents import pull_data_via_api
ModuleNotFoundError: No module named 'pull_fire_incidents'
[2025-02-25T23:00:49.757+0000] {processor.py:927} WARNING - No viable dags retrieved from /opt/airflow/dags/fire_incidents_dag.py
[2025-02-25T23:00:49.777+0000] {processor.py:208} INFO - Processing /opt/airflow/dags/fire_incidents_dag.py took 0.032 seconds
[2025-02-25T23:01:19.982+0000] {processor.py:186} INFO - Started process (PID=612) to work on /opt/airflow/dags/fire_incidents_dag.py
[2025-02-25T23:01:19.983+0000] {processor.py:914} INFO - Processing file /opt/airflow/dags/fire_incidents_dag.py for tasks to queue
[2025-02-25T23:01:19.984+0000] {logging_mixin.py:190} INFO - [2025-02-25T23:01:19.984+0000] {dagbag.py:588} INFO - Filling up the DagBag from /opt/airflow/dags/fire_incidents_dag.py
[2025-02-25T23:01:19.986+0000] {logging_mixin.py:190} INFO - [2025-02-25T23:01:19.986+0000] {dagbag.py:387} ERROR - Failed to import: /opt/airflow/dags/fire_incidents_dag.py
Traceback (most recent call last):
  File "/home/airflow/.local/lib/python3.12/site-packages/airflow/models/dagbag.py", line 383, in parse
    loader.exec_module(new_module)
  File "<frozen importlib._bootstrap_external>", line 999, in exec_module
  File "<frozen importlib._bootstrap>", line 488, in _call_with_frames_removed
  File "/opt/airflow/dags/fire_incidents_dag.py", line 4, in <module>
    from pull_fire_incidents import pull_data_via_api
ModuleNotFoundError: No module named 'pull_fire_incidents'
[2025-02-25T23:01:19.987+0000] {processor.py:927} WARNING - No viable dags retrieved from /opt/airflow/dags/fire_incidents_dag.py
[2025-02-25T23:01:20.001+0000] {processor.py:208} INFO - Processing /opt/airflow/dags/fire_incidents_dag.py took 0.023 seconds
[2025-02-25T23:01:50.455+0000] {processor.py:186} INFO - Started process (PID=676) to work on /opt/airflow/dags/fire_incidents_dag.py
[2025-02-25T23:01:50.457+0000] {processor.py:914} INFO - Processing file /opt/airflow/dags/fire_incidents_dag.py for tasks to queue
[2025-02-25T23:01:50.459+0000] {logging_mixin.py:190} INFO - [2025-02-25T23:01:50.459+0000] {dagbag.py:588} INFO - Filling up the DagBag from /opt/airflow/dags/fire_incidents_dag.py
[2025-02-25T23:01:50.464+0000] {logging_mixin.py:190} INFO - [2025-02-25T23:01:50.462+0000] {dagbag.py:387} ERROR - Failed to import: /opt/airflow/dags/fire_incidents_dag.py
Traceback (most recent call last):
  File "/home/airflow/.local/lib/python3.12/site-packages/airflow/models/dagbag.py", line 383, in parse
    loader.exec_module(new_module)
  File "<frozen importlib._bootstrap_external>", line 999, in exec_module
  File "<frozen importlib._bootstrap>", line 488, in _call_with_frames_removed
  File "/opt/airflow/dags/fire_incidents_dag.py", line 4, in <module>
    from pull_fire_incidents import pull_data_via_api
ModuleNotFoundError: No module named 'pull_fire_incidents'
[2025-02-25T23:01:50.464+0000] {processor.py:927} WARNING - No viable dags retrieved from /opt/airflow/dags/fire_incidents_dag.py
[2025-02-25T23:01:50.480+0000] {processor.py:208} INFO - Processing /opt/airflow/dags/fire_incidents_dag.py took 0.031 seconds
[2025-02-25T23:02:20.735+0000] {processor.py:186} INFO - Started process (PID=739) to work on /opt/airflow/dags/fire_incidents_dag.py
[2025-02-25T23:02:20.736+0000] {processor.py:914} INFO - Processing file /opt/airflow/dags/fire_incidents_dag.py for tasks to queue
[2025-02-25T23:02:20.740+0000] {logging_mixin.py:190} INFO - [2025-02-25T23:02:20.739+0000] {dagbag.py:588} INFO - Filling up the DagBag from /opt/airflow/dags/fire_incidents_dag.py
[2025-02-25T23:02:20.746+0000] {logging_mixin.py:190} INFO - [2025-02-25T23:02:20.744+0000] {dagbag.py:387} ERROR - Failed to import: /opt/airflow/dags/fire_incidents_dag.py
Traceback (most recent call last):
  File "/home/airflow/.local/lib/python3.12/site-packages/airflow/models/dagbag.py", line 383, in parse
    loader.exec_module(new_module)
  File "<frozen importlib._bootstrap_external>", line 999, in exec_module
  File "<frozen importlib._bootstrap>", line 488, in _call_with_frames_removed
  File "/opt/airflow/dags/fire_incidents_dag.py", line 4, in <module>
    from pull_fire_incidents import pull_data_via_api
ModuleNotFoundError: No module named 'pull_fire_incidents'
[2025-02-25T23:02:20.747+0000] {processor.py:927} WARNING - No viable dags retrieved from /opt/airflow/dags/fire_incidents_dag.py
[2025-02-25T23:02:20.762+0000] {processor.py:208} INFO - Processing /opt/airflow/dags/fire_incidents_dag.py took 0.038 seconds
[2025-02-25T23:02:51.178+0000] {processor.py:186} INFO - Started process (PID=803) to work on /opt/airflow/dags/fire_incidents_dag.py
[2025-02-25T23:02:51.180+0000] {processor.py:914} INFO - Processing file /opt/airflow/dags/fire_incidents_dag.py for tasks to queue
[2025-02-25T23:02:51.183+0000] {logging_mixin.py:190} INFO - [2025-02-25T23:02:51.182+0000] {dagbag.py:588} INFO - Filling up the DagBag from /opt/airflow/dags/fire_incidents_dag.py
[2025-02-25T23:02:51.188+0000] {logging_mixin.py:190} INFO - [2025-02-25T23:02:51.186+0000] {dagbag.py:387} ERROR - Failed to import: /opt/airflow/dags/fire_incidents_dag.py
Traceback (most recent call last):
  File "/home/airflow/.local/lib/python3.12/site-packages/airflow/models/dagbag.py", line 383, in parse
    loader.exec_module(new_module)
  File "<frozen importlib._bootstrap_external>", line 999, in exec_module
  File "<frozen importlib._bootstrap>", line 488, in _call_with_frames_removed
  File "/opt/airflow/dags/fire_incidents_dag.py", line 4, in <module>
    from pull_fire_incidents import pull_data_via_api
ModuleNotFoundError: No module named 'pull_fire_incidents'
[2025-02-25T23:02:51.189+0000] {processor.py:927} WARNING - No viable dags retrieved from /opt/airflow/dags/fire_incidents_dag.py
[2025-02-25T23:02:51.208+0000] {processor.py:208} INFO - Processing /opt/airflow/dags/fire_incidents_dag.py took 0.040 seconds
[2025-02-25T23:03:21.851+0000] {processor.py:186} INFO - Started process (PID=867) to work on /opt/airflow/dags/fire_incidents_dag.py
[2025-02-25T23:03:21.852+0000] {processor.py:914} INFO - Processing file /opt/airflow/dags/fire_incidents_dag.py for tasks to queue
[2025-02-25T23:03:21.857+0000] {logging_mixin.py:190} INFO - [2025-02-25T23:03:21.856+0000] {dagbag.py:588} INFO - Filling up the DagBag from /opt/airflow/dags/fire_incidents_dag.py
[2025-02-25T23:03:21.862+0000] {logging_mixin.py:190} INFO - [2025-02-25T23:03:21.861+0000] {dagbag.py:387} ERROR - Failed to import: /opt/airflow/dags/fire_incidents_dag.py
Traceback (most recent call last):
  File "/home/airflow/.local/lib/python3.12/site-packages/airflow/models/dagbag.py", line 383, in parse
    loader.exec_module(new_module)
  File "<frozen importlib._bootstrap_external>", line 999, in exec_module
  File "<frozen importlib._bootstrap>", line 488, in _call_with_frames_removed
  File "/opt/airflow/dags/fire_incidents_dag.py", line 4, in <module>
    from pull_fire_incidents import pull_data_via_api
ModuleNotFoundError: No module named 'pull_fire_incidents'
[2025-02-25T23:03:21.862+0000] {processor.py:927} WARNING - No viable dags retrieved from /opt/airflow/dags/fire_incidents_dag.py
[2025-02-25T23:03:21.876+0000] {processor.py:208} INFO - Processing /opt/airflow/dags/fire_incidents_dag.py took 0.036 seconds
[2025-02-25T23:03:52.519+0000] {processor.py:186} INFO - Started process (PID=931) to work on /opt/airflow/dags/fire_incidents_dag.py
[2025-02-25T23:03:52.520+0000] {processor.py:914} INFO - Processing file /opt/airflow/dags/fire_incidents_dag.py for tasks to queue
[2025-02-25T23:03:52.522+0000] {logging_mixin.py:190} INFO - [2025-02-25T23:03:52.522+0000] {dagbag.py:588} INFO - Filling up the DagBag from /opt/airflow/dags/fire_incidents_dag.py
[2025-02-25T23:03:52.525+0000] {logging_mixin.py:190} INFO - [2025-02-25T23:03:52.524+0000] {dagbag.py:387} ERROR - Failed to import: /opt/airflow/dags/fire_incidents_dag.py
Traceback (most recent call last):
  File "/home/airflow/.local/lib/python3.12/site-packages/airflow/models/dagbag.py", line 383, in parse
    loader.exec_module(new_module)
  File "<frozen importlib._bootstrap_external>", line 999, in exec_module
  File "<frozen importlib._bootstrap>", line 488, in _call_with_frames_removed
  File "/opt/airflow/dags/fire_incidents_dag.py", line 4, in <module>
    from pull_fire_incidents import pull_data_via_api
ModuleNotFoundError: No module named 'pull_fire_incidents'
[2025-02-25T23:03:52.525+0000] {processor.py:927} WARNING - No viable dags retrieved from /opt/airflow/dags/fire_incidents_dag.py
[2025-02-25T23:03:52.541+0000] {processor.py:208} INFO - Processing /opt/airflow/dags/fire_incidents_dag.py took 0.026 seconds
[2025-02-25T23:04:22.826+0000] {processor.py:186} INFO - Started process (PID=996) to work on /opt/airflow/dags/fire_incidents_dag.py
[2025-02-25T23:04:22.827+0000] {processor.py:914} INFO - Processing file /opt/airflow/dags/fire_incidents_dag.py for tasks to queue
[2025-02-25T23:04:22.828+0000] {logging_mixin.py:190} INFO - [2025-02-25T23:04:22.828+0000] {dagbag.py:588} INFO - Filling up the DagBag from /opt/airflow/dags/fire_incidents_dag.py
[2025-02-25T23:04:22.831+0000] {logging_mixin.py:190} INFO - [2025-02-25T23:04:22.830+0000] {dagbag.py:387} ERROR - Failed to import: /opt/airflow/dags/fire_incidents_dag.py
Traceback (most recent call last):
  File "/home/airflow/.local/lib/python3.12/site-packages/airflow/models/dagbag.py", line 383, in parse
    loader.exec_module(new_module)
  File "<frozen importlib._bootstrap_external>", line 999, in exec_module
  File "<frozen importlib._bootstrap>", line 488, in _call_with_frames_removed
  File "/opt/airflow/dags/fire_incidents_dag.py", line 4, in <module>
    from pull_fire_incidents import pull_data_via_api
ModuleNotFoundError: No module named 'pull_fire_incidents'
[2025-02-25T23:04:22.831+0000] {processor.py:927} WARNING - No viable dags retrieved from /opt/airflow/dags/fire_incidents_dag.py
[2025-02-25T23:04:22.844+0000] {processor.py:208} INFO - Processing /opt/airflow/dags/fire_incidents_dag.py took 0.022 seconds
[2025-02-25T23:04:53.062+0000] {processor.py:186} INFO - Started process (PID=1060) to work on /opt/airflow/dags/fire_incidents_dag.py
[2025-02-25T23:04:53.063+0000] {processor.py:914} INFO - Processing file /opt/airflow/dags/fire_incidents_dag.py for tasks to queue
[2025-02-25T23:04:53.065+0000] {logging_mixin.py:190} INFO - [2025-02-25T23:04:53.065+0000] {dagbag.py:588} INFO - Filling up the DagBag from /opt/airflow/dags/fire_incidents_dag.py
[2025-02-25T23:04:53.068+0000] {logging_mixin.py:190} INFO - [2025-02-25T23:04:53.067+0000] {dagbag.py:387} ERROR - Failed to import: /opt/airflow/dags/fire_incidents_dag.py
Traceback (most recent call last):
  File "/home/airflow/.local/lib/python3.12/site-packages/airflow/models/dagbag.py", line 383, in parse
    loader.exec_module(new_module)
  File "<frozen importlib._bootstrap_external>", line 999, in exec_module
  File "<frozen importlib._bootstrap>", line 488, in _call_with_frames_removed
  File "/opt/airflow/dags/fire_incidents_dag.py", line 4, in <module>
    from pull_fire_incidents import pull_data_via_api
ModuleNotFoundError: No module named 'pull_fire_incidents'
[2025-02-25T23:04:53.068+0000] {processor.py:927} WARNING - No viable dags retrieved from /opt/airflow/dags/fire_incidents_dag.py
[2025-02-25T23:04:53.083+0000] {processor.py:208} INFO - Processing /opt/airflow/dags/fire_incidents_dag.py took 0.027 seconds
[2025-02-25T23:05:19.729+0000] {processor.py:186} INFO - Started process (PID=1117) to work on /opt/airflow/dags/fire_incidents_dag.py
[2025-02-25T23:05:19.730+0000] {processor.py:914} INFO - Processing file /opt/airflow/dags/fire_incidents_dag.py for tasks to queue
[2025-02-25T23:05:19.731+0000] {logging_mixin.py:190} INFO - [2025-02-25T23:05:19.731+0000] {dagbag.py:588} INFO - Filling up the DagBag from /opt/airflow/dags/fire_incidents_dag.py
[2025-02-25T23:05:19.735+0000] {logging_mixin.py:190} INFO - [2025-02-25T23:05:19.734+0000] {dagbag.py:387} ERROR - Failed to import: /opt/airflow/dags/fire_incidents_dag.py
Traceback (most recent call last):
  File "/home/airflow/.local/lib/python3.12/site-packages/airflow/models/dagbag.py", line 383, in parse
    loader.exec_module(new_module)
  File "<frozen importlib._bootstrap_external>", line 999, in exec_module
  File "<frozen importlib._bootstrap>", line 488, in _call_with_frames_removed
  File "/opt/airflow/dags/fire_incidents_dag.py", line 4, in <module>
    from etl.pull_fire_incidents import pull_data_via_api
ModuleNotFoundError: No module named 'etl'
[2025-02-25T23:05:19.735+0000] {processor.py:927} WARNING - No viable dags retrieved from /opt/airflow/dags/fire_incidents_dag.py
[2025-02-25T23:05:19.751+0000] {processor.py:208} INFO - Processing /opt/airflow/dags/fire_incidents_dag.py took 0.026 seconds
[2025-02-25T23:05:27.228+0000] {processor.py:186} INFO - Started process (PID=1136) to work on /opt/airflow/dags/fire_incidents_dag.py
[2025-02-25T23:05:27.229+0000] {processor.py:914} INFO - Processing file /opt/airflow/dags/fire_incidents_dag.py for tasks to queue
[2025-02-25T23:05:27.231+0000] {logging_mixin.py:190} INFO - [2025-02-25T23:05:27.231+0000] {dagbag.py:588} INFO - Filling up the DagBag from /opt/airflow/dags/fire_incidents_dag.py
[2025-02-25T23:05:27.235+0000] {logging_mixin.py:190} INFO - [2025-02-25T23:05:27.234+0000] {dagbag.py:387} ERROR - Failed to import: /opt/airflow/dags/fire_incidents_dag.py
Traceback (most recent call last):
  File "/home/airflow/.local/lib/python3.12/site-packages/airflow/models/dagbag.py", line 383, in parse
    loader.exec_module(new_module)
  File "<frozen importlib._bootstrap_external>", line 999, in exec_module
  File "<frozen importlib._bootstrap>", line 488, in _call_with_frames_removed
  File "/opt/airflow/dags/fire_incidents_dag.py", line 4, in <module>
    from etl.pull_fire_incidents import pull_data_via_api
ModuleNotFoundError: No module named 'etl'
[2025-02-25T23:05:27.236+0000] {processor.py:927} WARNING - No viable dags retrieved from /opt/airflow/dags/fire_incidents_dag.py
[2025-02-25T23:05:27.253+0000] {processor.py:208} INFO - Processing /opt/airflow/dags/fire_incidents_dag.py took 0.029 seconds
[2025-02-25T23:05:57.929+0000] {processor.py:186} INFO - Started process (PID=1199) to work on /opt/airflow/dags/fire_incidents_dag.py
[2025-02-25T23:05:57.930+0000] {processor.py:914} INFO - Processing file /opt/airflow/dags/fire_incidents_dag.py for tasks to queue
[2025-02-25T23:05:57.931+0000] {logging_mixin.py:190} INFO - [2025-02-25T23:05:57.931+0000] {dagbag.py:588} INFO - Filling up the DagBag from /opt/airflow/dags/fire_incidents_dag.py
[2025-02-25T23:05:57.934+0000] {logging_mixin.py:190} INFO - [2025-02-25T23:05:57.933+0000] {dagbag.py:387} ERROR - Failed to import: /opt/airflow/dags/fire_incidents_dag.py
Traceback (most recent call last):
  File "/home/airflow/.local/lib/python3.12/site-packages/airflow/models/dagbag.py", line 383, in parse
    loader.exec_module(new_module)
  File "<frozen importlib._bootstrap_external>", line 999, in exec_module
  File "<frozen importlib._bootstrap>", line 488, in _call_with_frames_removed
  File "/opt/airflow/dags/fire_incidents_dag.py", line 4, in <module>
    from etl.pull_fire_incidents import pull_data_via_api
ModuleNotFoundError: No module named 'etl'
[2025-02-25T23:05:57.934+0000] {processor.py:927} WARNING - No viable dags retrieved from /opt/airflow/dags/fire_incidents_dag.py
[2025-02-25T23:05:57.947+0000] {processor.py:208} INFO - Processing /opt/airflow/dags/fire_incidents_dag.py took 0.022 seconds
[2025-02-25T23:06:11.890+0000] {processor.py:186} INFO - Started process (PID=1218) to work on /opt/airflow/dags/fire_incidents_dag.py
[2025-02-25T23:06:11.892+0000] {processor.py:914} INFO - Processing file /opt/airflow/dags/fire_incidents_dag.py for tasks to queue
[2025-02-25T23:06:11.894+0000] {logging_mixin.py:190} INFO - [2025-02-25T23:06:11.894+0000] {dagbag.py:588} INFO - Filling up the DagBag from /opt/airflow/dags/fire_incidents_dag.py
[2025-02-25T23:06:11.902+0000] {logging_mixin.py:190} INFO - [2025-02-25T23:06:11.897+0000] {dagbag.py:387} ERROR - Failed to import: /opt/airflow/dags/fire_incidents_dag.py
Traceback (most recent call last):
  File "/home/airflow/.local/lib/python3.12/site-packages/airflow/models/dagbag.py", line 383, in parse
    loader.exec_module(new_module)
  File "<frozen importlib._bootstrap_external>", line 999, in exec_module
  File "<frozen importlib._bootstrap>", line 488, in _call_with_frames_removed
  File "/opt/airflow/dags/fire_incidents_dag.py", line 31, in <module>
    python_callable=pull_data_via_api,
                    ^^^^^^^^^^^^^^^^^
NameError: name 'pull_data_via_api' is not defined
[2025-02-25T23:06:11.906+0000] {processor.py:927} WARNING - No viable dags retrieved from /opt/airflow/dags/fire_incidents_dag.py
[2025-02-25T23:06:11.919+0000] {processor.py:208} INFO - Processing /opt/airflow/dags/fire_incidents_dag.py took 0.034 seconds
[2025-02-25T23:06:22.083+0000] {processor.py:186} INFO - Started process (PID=1249) to work on /opt/airflow/dags/fire_incidents_dag.py
[2025-02-25T23:06:22.084+0000] {processor.py:914} INFO - Processing file /opt/airflow/dags/fire_incidents_dag.py for tasks to queue
[2025-02-25T23:06:22.086+0000] {logging_mixin.py:190} INFO - [2025-02-25T23:06:22.086+0000] {dagbag.py:588} INFO - Filling up the DagBag from /opt/airflow/dags/fire_incidents_dag.py
[2025-02-25T23:06:22.122+0000] {logging_mixin.py:190} INFO - [2025-02-25T23:06:22.089+0000] {dagbag.py:387} ERROR - Failed to import: /opt/airflow/dags/fire_incidents_dag.py
Traceback (most recent call last):
  File "/home/airflow/.local/lib/python3.12/site-packages/airflow/models/dagbag.py", line 383, in parse
    loader.exec_module(new_module)
  File "<frozen importlib._bootstrap_external>", line 999, in exec_module
  File "<frozen importlib._bootstrap>", line 488, in _call_with_frames_removed
  File "/opt/airflow/dags/fire_incidents_dag.py", line 29, in <module>
    etl_task = PythonOperator(
               ^^^^^^^^^^^^^^^
  File "/home/airflow/.local/lib/python3.12/site-packages/airflow/models/baseoperator.py", line 491, in apply_defaults
    raise AirflowException(f"missing keyword argument {missing_args.pop()!r}")
airflow.exceptions.AirflowException: missing keyword argument 'python_callable'
[2025-02-25T23:06:22.122+0000] {processor.py:927} WARNING - No viable dags retrieved from /opt/airflow/dags/fire_incidents_dag.py
[2025-02-25T23:06:22.138+0000] {processor.py:208} INFO - Processing /opt/airflow/dags/fire_incidents_dag.py took 0.059 seconds
[2025-02-25T23:06:52.709+0000] {processor.py:186} INFO - Started process (PID=1309) to work on /opt/airflow/dags/fire_incidents_dag.py
[2025-02-25T23:06:52.711+0000] {processor.py:914} INFO - Processing file /opt/airflow/dags/fire_incidents_dag.py for tasks to queue
[2025-02-25T23:06:52.714+0000] {logging_mixin.py:190} INFO - [2025-02-25T23:06:52.714+0000] {dagbag.py:588} INFO - Filling up the DagBag from /opt/airflow/dags/fire_incidents_dag.py
[2025-02-25T23:06:52.721+0000] {logging_mixin.py:190} INFO - [2025-02-25T23:06:52.719+0000] {dagbag.py:387} ERROR - Failed to import: /opt/airflow/dags/fire_incidents_dag.py
Traceback (most recent call last):
  File "/home/airflow/.local/lib/python3.12/site-packages/airflow/models/dagbag.py", line 383, in parse
    loader.exec_module(new_module)
  File "<frozen importlib._bootstrap_external>", line 999, in exec_module
  File "<frozen importlib._bootstrap>", line 488, in _call_with_frames_removed
  File "/opt/airflow/dags/fire_incidents_dag.py", line 29, in <module>
    etl_task = PythonOperator(
               ^^^^^^^^^^^^^^^
  File "/home/airflow/.local/lib/python3.12/site-packages/airflow/models/baseoperator.py", line 491, in apply_defaults
    raise AirflowException(f"missing keyword argument {missing_args.pop()!r}")
airflow.exceptions.AirflowException: missing keyword argument 'python_callable'
[2025-02-25T23:06:52.722+0000] {processor.py:927} WARNING - No viable dags retrieved from /opt/airflow/dags/fire_incidents_dag.py
[2025-02-25T23:06:52.739+0000] {processor.py:208} INFO - Processing /opt/airflow/dags/fire_incidents_dag.py took 0.040 seconds
[2025-02-25T23:07:23.071+0000] {processor.py:186} INFO - Started process (PID=1373) to work on /opt/airflow/dags/fire_incidents_dag.py
[2025-02-25T23:07:23.072+0000] {processor.py:914} INFO - Processing file /opt/airflow/dags/fire_incidents_dag.py for tasks to queue
[2025-02-25T23:07:23.074+0000] {logging_mixin.py:190} INFO - [2025-02-25T23:07:23.074+0000] {dagbag.py:588} INFO - Filling up the DagBag from /opt/airflow/dags/fire_incidents_dag.py
[2025-02-25T23:07:23.078+0000] {logging_mixin.py:190} INFO - [2025-02-25T23:07:23.076+0000] {dagbag.py:387} ERROR - Failed to import: /opt/airflow/dags/fire_incidents_dag.py
Traceback (most recent call last):
  File "/home/airflow/.local/lib/python3.12/site-packages/airflow/models/dagbag.py", line 383, in parse
    loader.exec_module(new_module)
  File "<frozen importlib._bootstrap_external>", line 999, in exec_module
  File "<frozen importlib._bootstrap>", line 488, in _call_with_frames_removed
  File "/opt/airflow/dags/fire_incidents_dag.py", line 29, in <module>
    etl_task = PythonOperator(
               ^^^^^^^^^^^^^^^
  File "/home/airflow/.local/lib/python3.12/site-packages/airflow/models/baseoperator.py", line 491, in apply_defaults
    raise AirflowException(f"missing keyword argument {missing_args.pop()!r}")
airflow.exceptions.AirflowException: missing keyword argument 'python_callable'
[2025-02-25T23:07:23.078+0000] {processor.py:927} WARNING - No viable dags retrieved from /opt/airflow/dags/fire_incidents_dag.py
[2025-02-25T23:07:23.092+0000] {processor.py:208} INFO - Processing /opt/airflow/dags/fire_incidents_dag.py took 0.025 seconds
[2025-02-25T23:07:53.333+0000] {processor.py:186} INFO - Started process (PID=1437) to work on /opt/airflow/dags/fire_incidents_dag.py
[2025-02-25T23:07:53.334+0000] {processor.py:914} INFO - Processing file /opt/airflow/dags/fire_incidents_dag.py for tasks to queue
[2025-02-25T23:07:53.336+0000] {logging_mixin.py:190} INFO - [2025-02-25T23:07:53.335+0000] {dagbag.py:588} INFO - Filling up the DagBag from /opt/airflow/dags/fire_incidents_dag.py
[2025-02-25T23:07:53.341+0000] {logging_mixin.py:190} INFO - [2025-02-25T23:07:53.339+0000] {dagbag.py:387} ERROR - Failed to import: /opt/airflow/dags/fire_incidents_dag.py
Traceback (most recent call last):
  File "/home/airflow/.local/lib/python3.12/site-packages/airflow/models/dagbag.py", line 383, in parse
    loader.exec_module(new_module)
  File "<frozen importlib._bootstrap_external>", line 999, in exec_module
  File "<frozen importlib._bootstrap>", line 488, in _call_with_frames_removed
  File "/opt/airflow/dags/fire_incidents_dag.py", line 29, in <module>
    etl_task = PythonOperator(
               ^^^^^^^^^^^^^^^
  File "/home/airflow/.local/lib/python3.12/site-packages/airflow/models/baseoperator.py", line 491, in apply_defaults
    raise AirflowException(f"missing keyword argument {missing_args.pop()!r}")
airflow.exceptions.AirflowException: missing keyword argument 'python_callable'
[2025-02-25T23:07:53.342+0000] {processor.py:927} WARNING - No viable dags retrieved from /opt/airflow/dags/fire_incidents_dag.py
[2025-02-25T23:07:53.356+0000] {processor.py:208} INFO - Processing /opt/airflow/dags/fire_incidents_dag.py took 0.027 seconds
[2025-02-25T23:08:23.864+0000] {processor.py:186} INFO - Started process (PID=1501) to work on /opt/airflow/dags/fire_incidents_dag.py
[2025-02-25T23:08:23.864+0000] {processor.py:914} INFO - Processing file /opt/airflow/dags/fire_incidents_dag.py for tasks to queue
[2025-02-25T23:08:23.866+0000] {logging_mixin.py:190} INFO - [2025-02-25T23:08:23.866+0000] {dagbag.py:588} INFO - Filling up the DagBag from /opt/airflow/dags/fire_incidents_dag.py
[2025-02-25T23:08:23.871+0000] {logging_mixin.py:190} INFO - [2025-02-25T23:08:23.870+0000] {dagbag.py:387} ERROR - Failed to import: /opt/airflow/dags/fire_incidents_dag.py
Traceback (most recent call last):
  File "/home/airflow/.local/lib/python3.12/site-packages/airflow/models/dagbag.py", line 383, in parse
    loader.exec_module(new_module)
  File "<frozen importlib._bootstrap_external>", line 999, in exec_module
  File "<frozen importlib._bootstrap>", line 488, in _call_with_frames_removed
  File "/opt/airflow/dags/fire_incidents_dag.py", line 29, in <module>
    etl_task = PythonOperator(
               ^^^^^^^^^^^^^^^
  File "/home/airflow/.local/lib/python3.12/site-packages/airflow/models/baseoperator.py", line 491, in apply_defaults
    raise AirflowException(f"missing keyword argument {missing_args.pop()!r}")
airflow.exceptions.AirflowException: missing keyword argument 'python_callable'
[2025-02-25T23:08:23.872+0000] {processor.py:927} WARNING - No viable dags retrieved from /opt/airflow/dags/fire_incidents_dag.py
[2025-02-25T23:08:23.889+0000] {processor.py:208} INFO - Processing /opt/airflow/dags/fire_incidents_dag.py took 0.029 seconds
[2025-02-25T23:08:45.254+0000] {processor.py:186} INFO - Started process (PID=1539) to work on /opt/airflow/dags/fire_incidents_dag.py
[2025-02-25T23:08:45.256+0000] {processor.py:914} INFO - Processing file /opt/airflow/dags/fire_incidents_dag.py for tasks to queue
[2025-02-25T23:08:45.259+0000] {logging_mixin.py:190} INFO - [2025-02-25T23:08:45.258+0000] {dagbag.py:588} INFO - Filling up the DagBag from /opt/airflow/dags/fire_incidents_dag.py
[2025-02-25T23:08:45.265+0000] {logging_mixin.py:190} INFO - [2025-02-25T23:08:45.264+0000] {dagbag.py:387} ERROR - Failed to import: /opt/airflow/dags/fire_incidents_dag.py
Traceback (most recent call last):
  File "/home/airflow/.local/lib/python3.12/site-packages/airflow/models/dagbag.py", line 383, in parse
    loader.exec_module(new_module)
  File "<frozen importlib._bootstrap_external>", line 999, in exec_module
  File "<frozen importlib._bootstrap>", line 488, in _call_with_frames_removed
  File "/opt/airflow/dags/fire_incidents_dag.py", line 4, in <module>
    from pull_fire_incidents import pull_data_via_api
  File "/opt/airflow/dags/pull_fire_incidents.py", line 14, in <module>
    from sodapy import Socrata
ModuleNotFoundError: No module named 'sodapy'
[2025-02-25T23:08:45.266+0000] {processor.py:927} WARNING - No viable dags retrieved from /opt/airflow/dags/fire_incidents_dag.py
[2025-02-25T23:08:45.286+0000] {processor.py:208} INFO - Processing /opt/airflow/dags/fire_incidents_dag.py took 0.040 seconds
[2025-02-25T23:09:15.315+0000] {processor.py:186} INFO - Started process (PID=1603) to work on /opt/airflow/dags/fire_incidents_dag.py
[2025-02-25T23:09:15.317+0000] {processor.py:914} INFO - Processing file /opt/airflow/dags/fire_incidents_dag.py for tasks to queue
[2025-02-25T23:09:15.319+0000] {logging_mixin.py:190} INFO - [2025-02-25T23:09:15.319+0000] {dagbag.py:588} INFO - Filling up the DagBag from /opt/airflow/dags/fire_incidents_dag.py
[2025-02-25T23:09:15.324+0000] {logging_mixin.py:190} INFO - [2025-02-25T23:09:15.323+0000] {dagbag.py:387} ERROR - Failed to import: /opt/airflow/dags/fire_incidents_dag.py
Traceback (most recent call last):
  File "/home/airflow/.local/lib/python3.12/site-packages/airflow/models/dagbag.py", line 383, in parse
    loader.exec_module(new_module)
  File "<frozen importlib._bootstrap_external>", line 999, in exec_module
  File "<frozen importlib._bootstrap>", line 488, in _call_with_frames_removed
  File "/opt/airflow/dags/fire_incidents_dag.py", line 4, in <module>
    from pull_fire_incidents import pull_data_via_api
  File "/opt/airflow/dags/pull_fire_incidents.py", line 14, in <module>
    from sodapy import Socrata
ModuleNotFoundError: No module named 'sodapy'
[2025-02-25T23:09:15.324+0000] {processor.py:927} WARNING - No viable dags retrieved from /opt/airflow/dags/fire_incidents_dag.py
[2025-02-25T23:09:15.343+0000] {processor.py:208} INFO - Processing /opt/airflow/dags/fire_incidents_dag.py took 0.034 seconds
