[2025-03-09T15:41:45.398+0000] {local_task_job_runner.py:123} INFO - ::group::Pre task execution logs
[2025-03-09T15:41:45.414+0000] {taskinstance.py:2614} INFO - Dependencies all met for dep_context=non-requeueable deps ti=<TaskInstance: etl_fire_incidents_dag.transform_data manual__2025-03-09T15:41:33.243162+00:00 [queued]>
[2025-03-09T15:41:45.421+0000] {taskinstance.py:2614} INFO - Dependencies all met for dep_context=requeueable deps ti=<TaskInstance: etl_fire_incidents_dag.transform_data manual__2025-03-09T15:41:33.243162+00:00 [queued]>
[2025-03-09T15:41:45.421+0000] {taskinstance.py:2867} INFO - Starting attempt 1 of 2
[2025-03-09T15:41:45.432+0000] {taskinstance.py:2890} INFO - Executing <Task(PythonOperator): transform_data> on 2025-03-09 15:41:33.243162+00:00
[2025-03-09T15:41:45.440+0000] {warnings.py:112} WARNING - /home/***/.local/lib/python3.12/site-packages/***/task/task_runner/standard_task_runner.py:70: DeprecationWarning: This process (pid=17635) is multi-threaded, use of fork() may lead to deadlocks in the child.
  pid = os.fork()

[2025-03-09T15:41:45.441+0000] {standard_task_runner.py:72} INFO - Started process 17637 to run task
[2025-03-09T15:41:45.441+0000] {standard_task_runner.py:104} INFO - Running: ['***', 'tasks', 'run', 'etl_fire_incidents_dag', 'transform_data', 'manual__2025-03-09T15:41:33.243162+00:00', '--job-id', '501', '--raw', '--subdir', 'DAGS_FOLDER/fire_incidents_dag.py', '--cfg-path', '/tmp/tmpgzt1r2at']
[2025-03-09T15:41:45.442+0000] {standard_task_runner.py:105} INFO - Job 501: Subtask transform_data
[2025-03-09T15:41:45.474+0000] {task_command.py:467} INFO - Running <TaskInstance: etl_fire_incidents_dag.transform_data manual__2025-03-09T15:41:33.243162+00:00 [running]> on host fad361e322ea
[2025-03-09T15:41:45.544+0000] {taskinstance.py:3134} INFO - Exporting env vars: AIRFLOW_CTX_DAG_EMAIL='***@***.com' AIRFLOW_CTX_DAG_OWNER='***' AIRFLOW_CTX_DAG_ID='etl_fire_incidents_dag' AIRFLOW_CTX_TASK_ID='transform_data' AIRFLOW_CTX_EXECUTION_DATE='2025-03-09T15:41:33.243162+00:00' AIRFLOW_CTX_TRY_NUMBER='1' AIRFLOW_CTX_DAG_RUN_ID='manual__2025-03-09T15:41:33.243162+00:00'
[2025-03-09T15:41:45.545+0000] {logging_mixin.py:190} INFO - Task instance is in running state
[2025-03-09T15:41:45.545+0000] {logging_mixin.py:190} INFO -  Previous state of the Task instance: queued
[2025-03-09T15:41:45.545+0000] {logging_mixin.py:190} INFO - Current task name:transform_data state:running start_date:2025-03-09 15:41:45.414821+00:00
[2025-03-09T15:41:45.545+0000] {logging_mixin.py:190} INFO - Dag name:etl_fire_incidents_dag and current dag run status:running
[2025-03-09T15:41:45.545+0000] {taskinstance.py:732} INFO - ::endgroup::
[2025-03-09T15:41:45.554+0000] {taskinstance.py:3313} ERROR - Task failed with exception
Traceback (most recent call last):
  File "/home/airflow/.local/lib/python3.12/site-packages/airflow/models/taskinstance.py", line 768, in _execute_task
    result = _execute_callable(context=context, **execute_callable_kwargs)
             ^^^^^^^^^^^^^^^^^^^^^^^^^^^^^^^^^^^^^^^^^^^^^^^^^^^^^^^^^^^^^
  File "/home/airflow/.local/lib/python3.12/site-packages/airflow/models/taskinstance.py", line 734, in _execute_callable
    return ExecutionCallableRunner(
           ^^^^^^^^^^^^^^^^^^^^^^^^
  File "/home/airflow/.local/lib/python3.12/site-packages/airflow/utils/operator_helpers.py", line 252, in run
    return self.func(*args, **kwargs)
           ^^^^^^^^^^^^^^^^^^^^^^^^^^
  File "/home/airflow/.local/lib/python3.12/site-packages/airflow/models/baseoperator.py", line 424, in wrapper
    return func(self, *args, **kwargs)
           ^^^^^^^^^^^^^^^^^^^^^^^^^^^
  File "/home/airflow/.local/lib/python3.12/site-packages/airflow/operators/python.py", line 238, in execute
    return_value = self.execute_callable()
                   ^^^^^^^^^^^^^^^^^^^^^^^
  File "/home/airflow/.local/lib/python3.12/site-packages/airflow/operators/python.py", line 256, in execute_callable
    return runner.run(*self.op_args, **self.op_kwargs)
           ^^^^^^^^^^^^^^^^^^^^^^^^^^^^^^^^^^^^^^^^^^^
  File "/home/airflow/.local/lib/python3.12/site-packages/airflow/utils/operator_helpers.py", line 252, in run
    return self.func(*args, **kwargs)
           ^^^^^^^^^^^^^^^^^^^^^^^^^^
  File "/opt/airflow/dags/fire_incidents_dag.py", line 99, in transform_data
    json_transformed_data = transform_fire_incidents_data(extracted_data)
                            ^^^^^^^^^^^^^^^^^^^^^^^^^^^^^^^^^^^^^^^^^^^^^
  File "/opt/airflow/dags/pull_fire_incidents.py", line 140, in transform_fire_incidents_data
    df = pd.read_json(json_data)
         ^^^^^^^^^^^^^^^^^^^^^^^
  File "/home/airflow/.local/lib/python3.12/site-packages/pandas/io/json/_json.py", line 780, in read_json
    json_reader = JsonReader(
                  ^^^^^^^^^^^
  File "/home/airflow/.local/lib/python3.12/site-packages/pandas/io/json/_json.py", line 893, in __init__
    data = self._get_data_from_filepath(filepath_or_buffer)
           ^^^^^^^^^^^^^^^^^^^^^^^^^^^^^^^^^^^^^^^^^^^^^^^^
  File "/home/airflow/.local/lib/python3.12/site-packages/pandas/io/json/_json.py", line 933, in _get_data_from_filepath
    self.handles = get_handle(
                   ^^^^^^^^^^^
  File "/home/airflow/.local/lib/python3.12/site-packages/pandas/io/common.py", line 718, in get_handle
    ioargs = _get_filepath_or_buffer(
             ^^^^^^^^^^^^^^^^^^^^^^^^
  File "/home/airflow/.local/lib/python3.12/site-packages/pandas/io/common.py", line 460, in _get_filepath_or_buffer
    raise ValueError(msg)
ValueError: Invalid file path or buffer object type: <class 'NoneType'>
[2025-03-09T15:41:45.563+0000] {logging_mixin.py:190} INFO - Task instance in failure state
[2025-03-09T15:41:45.564+0000] {logging_mixin.py:190} INFO - Task start:2025-03-09 15:41:45.414821+00:00 end:2025-03-09 15:41:45.563492+00:00 duration:0.148671
[2025-03-09T15:41:45.564+0000] {logging_mixin.py:190} INFO - Task:<Task(PythonOperator): transform_data> dag:<DAG: etl_fire_incidents_dag> dagrun:<DagRun etl_fire_incidents_dag @ 2025-03-09 15:41:33.243162+00:00: manual__2025-03-09T15:41:33.243162+00:00, state:running, queued_at: 2025-03-09 15:41:33.253545+00:00. externally triggered: True>
[2025-03-09T15:41:45.564+0000] {logging_mixin.py:190} INFO - Failure caused by Invalid file path or buffer object type: <class 'NoneType'>
[2025-03-09T15:41:45.565+0000] {taskinstance.py:1226} INFO - Marking task as UP_FOR_RETRY. dag_id=etl_fire_incidents_dag, task_id=transform_data, run_id=manual__2025-03-09T15:41:33.243162+00:00, execution_date=20250309T154133, start_date=20250309T154145, end_date=20250309T154145
[2025-03-09T15:41:45.588+0000] {taskinstance.py:341} INFO - ::group::Post task execution logs
[2025-03-09T15:41:45.588+0000] {standard_task_runner.py:124} ERROR - Failed to execute job 501 for task transform_data (Invalid file path or buffer object type: <class 'NoneType'>; 17637)
Traceback (most recent call last):
  File "/home/airflow/.local/lib/python3.12/site-packages/airflow/task/task_runner/standard_task_runner.py", line 117, in _start_by_fork
    ret = args.func(args, dag=self.dag)
          ^^^^^^^^^^^^^^^^^^^^^^^^^^^^^
  File "/home/airflow/.local/lib/python3.12/site-packages/airflow/cli/cli_config.py", line 49, in command
    return func(*args, **kwargs)
           ^^^^^^^^^^^^^^^^^^^^^
  File "/home/airflow/.local/lib/python3.12/site-packages/airflow/utils/cli.py", line 116, in wrapper
    return f(*args, **kwargs)
           ^^^^^^^^^^^^^^^^^^
  File "/home/airflow/.local/lib/python3.12/site-packages/airflow/cli/commands/task_command.py", line 483, in task_run
    task_return_code = _run_task_by_selected_method(args, _dag, ti)
                       ^^^^^^^^^^^^^^^^^^^^^^^^^^^^^^^^^^^^^^^^^^^^
  File "/home/airflow/.local/lib/python3.12/site-packages/airflow/cli/commands/task_command.py", line 256, in _run_task_by_selected_method
    return _run_raw_task(args, ti)
           ^^^^^^^^^^^^^^^^^^^^^^^
  File "/home/airflow/.local/lib/python3.12/site-packages/airflow/cli/commands/task_command.py", line 341, in _run_raw_task
    return ti._run_raw_task(
           ^^^^^^^^^^^^^^^^^
  File "/home/airflow/.local/lib/python3.12/site-packages/airflow/utils/session.py", line 97, in wrapper
    return func(*args, session=session, **kwargs)
           ^^^^^^^^^^^^^^^^^^^^^^^^^^^^^^^^^^^^^^
  File "/home/airflow/.local/lib/python3.12/site-packages/airflow/models/taskinstance.py", line 3006, in _run_raw_task
    return _run_raw_task(
           ^^^^^^^^^^^^^^
  File "/home/airflow/.local/lib/python3.12/site-packages/airflow/models/taskinstance.py", line 274, in _run_raw_task
    TaskInstance._execute_task_with_callbacks(
  File "/home/airflow/.local/lib/python3.12/site-packages/airflow/models/taskinstance.py", line 3161, in _execute_task_with_callbacks
    result = self._execute_task(context, task_orig)
             ^^^^^^^^^^^^^^^^^^^^^^^^^^^^^^^^^^^^^^
  File "/home/airflow/.local/lib/python3.12/site-packages/airflow/models/taskinstance.py", line 3185, in _execute_task
    return _execute_task(self, context, task_orig)
           ^^^^^^^^^^^^^^^^^^^^^^^^^^^^^^^^^^^^^^^
  File "/home/airflow/.local/lib/python3.12/site-packages/airflow/models/taskinstance.py", line 768, in _execute_task
    result = _execute_callable(context=context, **execute_callable_kwargs)
             ^^^^^^^^^^^^^^^^^^^^^^^^^^^^^^^^^^^^^^^^^^^^^^^^^^^^^^^^^^^^^
  File "/home/airflow/.local/lib/python3.12/site-packages/airflow/models/taskinstance.py", line 734, in _execute_callable
    return ExecutionCallableRunner(
           ^^^^^^^^^^^^^^^^^^^^^^^^
  File "/home/airflow/.local/lib/python3.12/site-packages/airflow/utils/operator_helpers.py", line 252, in run
    return self.func(*args, **kwargs)
           ^^^^^^^^^^^^^^^^^^^^^^^^^^
  File "/home/airflow/.local/lib/python3.12/site-packages/airflow/models/baseoperator.py", line 424, in wrapper
    return func(self, *args, **kwargs)
           ^^^^^^^^^^^^^^^^^^^^^^^^^^^
  File "/home/airflow/.local/lib/python3.12/site-packages/airflow/operators/python.py", line 238, in execute
    return_value = self.execute_callable()
                   ^^^^^^^^^^^^^^^^^^^^^^^
  File "/home/airflow/.local/lib/python3.12/site-packages/airflow/operators/python.py", line 256, in execute_callable
    return runner.run(*self.op_args, **self.op_kwargs)
           ^^^^^^^^^^^^^^^^^^^^^^^^^^^^^^^^^^^^^^^^^^^
  File "/home/airflow/.local/lib/python3.12/site-packages/airflow/utils/operator_helpers.py", line 252, in run
    return self.func(*args, **kwargs)
           ^^^^^^^^^^^^^^^^^^^^^^^^^^
  File "/opt/airflow/dags/fire_incidents_dag.py", line 99, in transform_data
    json_transformed_data = transform_fire_incidents_data(extracted_data)
                            ^^^^^^^^^^^^^^^^^^^^^^^^^^^^^^^^^^^^^^^^^^^^^
  File "/opt/airflow/dags/pull_fire_incidents.py", line 140, in transform_fire_incidents_data
    df = pd.read_json(json_data)
         ^^^^^^^^^^^^^^^^^^^^^^^
  File "/home/airflow/.local/lib/python3.12/site-packages/pandas/io/json/_json.py", line 780, in read_json
    json_reader = JsonReader(
                  ^^^^^^^^^^^
  File "/home/airflow/.local/lib/python3.12/site-packages/pandas/io/json/_json.py", line 893, in __init__
    data = self._get_data_from_filepath(filepath_or_buffer)
           ^^^^^^^^^^^^^^^^^^^^^^^^^^^^^^^^^^^^^^^^^^^^^^^^
  File "/home/airflow/.local/lib/python3.12/site-packages/pandas/io/json/_json.py", line 933, in _get_data_from_filepath
    self.handles = get_handle(
                   ^^^^^^^^^^^
  File "/home/airflow/.local/lib/python3.12/site-packages/pandas/io/common.py", line 718, in get_handle
    ioargs = _get_filepath_or_buffer(
             ^^^^^^^^^^^^^^^^^^^^^^^^
  File "/home/airflow/.local/lib/python3.12/site-packages/pandas/io/common.py", line 460, in _get_filepath_or_buffer
    raise ValueError(msg)
ValueError: Invalid file path or buffer object type: <class 'NoneType'>
[2025-03-09T15:41:45.615+0000] {local_task_job_runner.py:266} INFO - Task exited with return code 1
[2025-03-09T15:41:45.624+0000] {local_task_job_runner.py:245} INFO - ::endgroup::
