[2025-03-08T17:19:18.864+0000] {local_task_job_runner.py:123} INFO - ::group::Pre task execution logs
[2025-03-08T17:19:18.885+0000] {taskinstance.py:2614} INFO - Dependencies all met for dep_context=non-requeueable deps ti=<TaskInstance: etl_fire_incidents_dag.extract_data manual__2025-03-08T17:19:04.057034+00:00 [queued]>
[2025-03-08T17:19:18.893+0000] {taskinstance.py:2614} INFO - Dependencies all met for dep_context=requeueable deps ti=<TaskInstance: etl_fire_incidents_dag.extract_data manual__2025-03-08T17:19:04.057034+00:00 [queued]>
[2025-03-08T17:19:18.893+0000] {taskinstance.py:2867} INFO - Starting attempt 1 of 2
[2025-03-08T17:19:18.912+0000] {taskinstance.py:2890} INFO - Executing <Task(PythonOperator): extract_data> on 2025-03-08 17:19:04.057034+00:00
[2025-03-08T17:19:18.919+0000] {warnings.py:112} WARNING - /home/***/.local/lib/python3.12/site-packages/***/task/task_runner/standard_task_runner.py:70: DeprecationWarning: This process (pid=134) is multi-threaded, use of fork() may lead to deadlocks in the child.
  pid = os.fork()

[2025-03-08T17:19:18.920+0000] {standard_task_runner.py:72} INFO - Started process 136 to run task
[2025-03-08T17:19:18.920+0000] {standard_task_runner.py:104} INFO - Running: ['***', 'tasks', 'run', 'etl_fire_incidents_dag', 'extract_data', 'manual__2025-03-08T17:19:04.057034+00:00', '--job-id', '367', '--raw', '--subdir', 'DAGS_FOLDER/fire_incidents_dag.py', '--cfg-path', '/tmp/tmp7xi6tyh8']
[2025-03-08T17:19:18.921+0000] {standard_task_runner.py:105} INFO - Job 367: Subtask extract_data
[2025-03-08T17:19:18.958+0000] {task_command.py:467} INFO - Running <TaskInstance: etl_fire_incidents_dag.extract_data manual__2025-03-08T17:19:04.057034+00:00 [running]> on host d7bd1a3e1de9
[2025-03-08T17:19:19.024+0000] {taskinstance.py:3134} INFO - Exporting env vars: AIRFLOW_CTX_DAG_EMAIL='***@***.com' AIRFLOW_CTX_DAG_OWNER='***' AIRFLOW_CTX_DAG_ID='etl_fire_incidents_dag' AIRFLOW_CTX_TASK_ID='extract_data' AIRFLOW_CTX_EXECUTION_DATE='2025-03-08T17:19:04.057034+00:00' AIRFLOW_CTX_TRY_NUMBER='1' AIRFLOW_CTX_DAG_RUN_ID='manual__2025-03-08T17:19:04.057034+00:00'
[2025-03-08T17:19:19.025+0000] {logging_mixin.py:190} INFO - Task instance is in running state
[2025-03-08T17:19:19.025+0000] {logging_mixin.py:190} INFO -  Previous state of the Task instance: queued
[2025-03-08T17:19:19.026+0000] {logging_mixin.py:190} INFO - Current task name:extract_data state:running start_date:2025-03-08 17:19:18.885411+00:00
[2025-03-08T17:19:19.026+0000] {logging_mixin.py:190} INFO - Dag name:etl_fire_incidents_dag and current dag run status:running
[2025-03-08T17:19:19.026+0000] {taskinstance.py:732} INFO - ::endgroup::
[2025-03-08T17:19:19.033+0000] {taskinstance.py:3313} ERROR - Task failed with exception
Traceback (most recent call last):
  File "/home/airflow/.local/lib/python3.12/site-packages/airflow/models/taskinstance.py", line 768, in _execute_task
    result = _execute_callable(context=context, **execute_callable_kwargs)
             ^^^^^^^^^^^^^^^^^^^^^^^^^^^^^^^^^^^^^^^^^^^^^^^^^^^^^^^^^^^^^
  File "/home/airflow/.local/lib/python3.12/site-packages/airflow/models/taskinstance.py", line 734, in _execute_callable
    return ExecutionCallableRunner(
           ^^^^^^^^^^^^^^^^^^^^^^^^
  File "/home/airflow/.local/lib/python3.12/site-packages/airflow/utils/operator_helpers.py", line 252, in run
    return self.func(*args, **kwargs)
           ^^^^^^^^^^^^^^^^^^^^^^^^^^
  File "/home/airflow/.local/lib/python3.12/site-packages/airflow/models/baseoperator.py", line 424, in wrapper
    return func(self, *args, **kwargs)
           ^^^^^^^^^^^^^^^^^^^^^^^^^^^
  File "/home/airflow/.local/lib/python3.12/site-packages/airflow/operators/python.py", line 238, in execute
    return_value = self.execute_callable()
                   ^^^^^^^^^^^^^^^^^^^^^^^
  File "/home/airflow/.local/lib/python3.12/site-packages/airflow/operators/python.py", line 256, in execute_callable
    return runner.run(*self.op_args, **self.op_kwargs)
           ^^^^^^^^^^^^^^^^^^^^^^^^^^^^^^^^^^^^^^^^^^^
  File "/home/airflow/.local/lib/python3.12/site-packages/airflow/utils/operator_helpers.py", line 252, in run
    return self.func(*args, **kwargs)
           ^^^^^^^^^^^^^^^^^^^^^^^^^^
  File "/opt/airflow/dags/pull_fire_incidents.py", line 89, in extract_fire_incidents_data
    api_url = parameters.api_url
              ^^^^^^^^^^^^^^^^^^
AttributeError: 'NoneType' object has no attribute 'api_url'
[2025-03-08T17:19:19.044+0000] {logging_mixin.py:190} INFO - Task instance in failure state
[2025-03-08T17:19:19.045+0000] {logging_mixin.py:190} INFO - Task start:2025-03-08 17:19:18.885411+00:00 end:2025-03-08 17:19:19.044309+00:00 duration:0.158898
[2025-03-08T17:19:19.045+0000] {logging_mixin.py:190} INFO - Task:<Task(PythonOperator): extract_data> dag:<DAG: etl_fire_incidents_dag> dagrun:<DagRun etl_fire_incidents_dag @ 2025-03-08 17:19:04.057034+00:00: manual__2025-03-08T17:19:04.057034+00:00, state:running, queued_at: 2025-03-08 17:19:04.119840+00:00. externally triggered: True>
[2025-03-08T17:19:19.045+0000] {logging_mixin.py:190} INFO - Failure caused by 'NoneType' object has no attribute 'api_url'
[2025-03-08T17:19:19.045+0000] {taskinstance.py:1226} INFO - Marking task as UP_FOR_RETRY. dag_id=etl_fire_incidents_dag, task_id=extract_data, run_id=manual__2025-03-08T17:19:04.057034+00:00, execution_date=20250308T171904, start_date=20250308T171918, end_date=20250308T171919
[2025-03-08T17:19:19.071+0000] {taskinstance.py:341} INFO - ::group::Post task execution logs
[2025-03-08T17:19:19.072+0000] {standard_task_runner.py:124} ERROR - Failed to execute job 367 for task extract_data ('NoneType' object has no attribute 'api_url'; 136)
Traceback (most recent call last):
  File "/home/airflow/.local/lib/python3.12/site-packages/airflow/task/task_runner/standard_task_runner.py", line 117, in _start_by_fork
    ret = args.func(args, dag=self.dag)
          ^^^^^^^^^^^^^^^^^^^^^^^^^^^^^
  File "/home/airflow/.local/lib/python3.12/site-packages/airflow/cli/cli_config.py", line 49, in command
    return func(*args, **kwargs)
           ^^^^^^^^^^^^^^^^^^^^^
  File "/home/airflow/.local/lib/python3.12/site-packages/airflow/utils/cli.py", line 116, in wrapper
    return f(*args, **kwargs)
           ^^^^^^^^^^^^^^^^^^
  File "/home/airflow/.local/lib/python3.12/site-packages/airflow/cli/commands/task_command.py", line 483, in task_run
    task_return_code = _run_task_by_selected_method(args, _dag, ti)
                       ^^^^^^^^^^^^^^^^^^^^^^^^^^^^^^^^^^^^^^^^^^^^
  File "/home/airflow/.local/lib/python3.12/site-packages/airflow/cli/commands/task_command.py", line 256, in _run_task_by_selected_method
    return _run_raw_task(args, ti)
           ^^^^^^^^^^^^^^^^^^^^^^^
  File "/home/airflow/.local/lib/python3.12/site-packages/airflow/cli/commands/task_command.py", line 341, in _run_raw_task
    return ti._run_raw_task(
           ^^^^^^^^^^^^^^^^^
  File "/home/airflow/.local/lib/python3.12/site-packages/airflow/utils/session.py", line 97, in wrapper
    return func(*args, session=session, **kwargs)
           ^^^^^^^^^^^^^^^^^^^^^^^^^^^^^^^^^^^^^^
  File "/home/airflow/.local/lib/python3.12/site-packages/airflow/models/taskinstance.py", line 3006, in _run_raw_task
    return _run_raw_task(
           ^^^^^^^^^^^^^^
  File "/home/airflow/.local/lib/python3.12/site-packages/airflow/models/taskinstance.py", line 274, in _run_raw_task
    TaskInstance._execute_task_with_callbacks(
  File "/home/airflow/.local/lib/python3.12/site-packages/airflow/models/taskinstance.py", line 3161, in _execute_task_with_callbacks
    result = self._execute_task(context, task_orig)
             ^^^^^^^^^^^^^^^^^^^^^^^^^^^^^^^^^^^^^^
  File "/home/airflow/.local/lib/python3.12/site-packages/airflow/models/taskinstance.py", line 3185, in _execute_task
    return _execute_task(self, context, task_orig)
           ^^^^^^^^^^^^^^^^^^^^^^^^^^^^^^^^^^^^^^^
  File "/home/airflow/.local/lib/python3.12/site-packages/airflow/models/taskinstance.py", line 768, in _execute_task
    result = _execute_callable(context=context, **execute_callable_kwargs)
             ^^^^^^^^^^^^^^^^^^^^^^^^^^^^^^^^^^^^^^^^^^^^^^^^^^^^^^^^^^^^^
  File "/home/airflow/.local/lib/python3.12/site-packages/airflow/models/taskinstance.py", line 734, in _execute_callable
    return ExecutionCallableRunner(
           ^^^^^^^^^^^^^^^^^^^^^^^^
  File "/home/airflow/.local/lib/python3.12/site-packages/airflow/utils/operator_helpers.py", line 252, in run
    return self.func(*args, **kwargs)
           ^^^^^^^^^^^^^^^^^^^^^^^^^^
  File "/home/airflow/.local/lib/python3.12/site-packages/airflow/models/baseoperator.py", line 424, in wrapper
    return func(self, *args, **kwargs)
           ^^^^^^^^^^^^^^^^^^^^^^^^^^^
  File "/home/airflow/.local/lib/python3.12/site-packages/airflow/operators/python.py", line 238, in execute
    return_value = self.execute_callable()
                   ^^^^^^^^^^^^^^^^^^^^^^^
  File "/home/airflow/.local/lib/python3.12/site-packages/airflow/operators/python.py", line 256, in execute_callable
    return runner.run(*self.op_args, **self.op_kwargs)
           ^^^^^^^^^^^^^^^^^^^^^^^^^^^^^^^^^^^^^^^^^^^
  File "/home/airflow/.local/lib/python3.12/site-packages/airflow/utils/operator_helpers.py", line 252, in run
    return self.func(*args, **kwargs)
           ^^^^^^^^^^^^^^^^^^^^^^^^^^
  File "/opt/airflow/dags/pull_fire_incidents.py", line 89, in extract_fire_incidents_data
    api_url = parameters.api_url
              ^^^^^^^^^^^^^^^^^^
AttributeError: 'NoneType' object has no attribute 'api_url'
[2025-03-08T17:19:19.094+0000] {local_task_job_runner.py:266} INFO - Task exited with return code 1
[2025-03-08T17:19:19.112+0000] {taskinstance.py:3901} INFO - 0 downstream tasks scheduled from follow-on schedule check
[2025-03-08T17:19:19.119+0000] {local_task_job_runner.py:245} INFO - ::endgroup::
