[2025-03-08T18:12:22.472+0000] {local_task_job_runner.py:123} INFO - ::group::Pre task execution logs
[2025-03-08T18:12:22.485+0000] {taskinstance.py:2614} INFO - Dependencies all met for dep_context=non-requeueable deps ti=<TaskInstance: etl_fire_incidents_dag.task_etl_fire_incident_using_bash scheduled__2025-03-08T15:00:00+00:00 [queued]>
[2025-03-08T18:12:22.491+0000] {taskinstance.py:2614} INFO - Dependencies all met for dep_context=requeueable deps ti=<TaskInstance: etl_fire_incidents_dag.task_etl_fire_incident_using_bash scheduled__2025-03-08T15:00:00+00:00 [queued]>
[2025-03-08T18:12:22.491+0000] {taskinstance.py:2867} INFO - Starting attempt 1 of 2
[2025-03-08T18:12:22.520+0000] {taskinstance.py:2890} INFO - Executing <Task(BashOperator): task_etl_fire_incident_using_bash> on 2025-03-08 15:00:00+00:00
[2025-03-08T18:12:22.536+0000] {warnings.py:112} WARNING - /home/***/.local/lib/python3.12/site-packages/***/task/task_runner/standard_task_runner.py:70: DeprecationWarning: This process (pid=118) is multi-threaded, use of fork() may lead to deadlocks in the child.
  pid = os.fork()

[2025-03-08T18:12:22.538+0000] {standard_task_runner.py:72} INFO - Started process 120 to run task
[2025-03-08T18:12:22.539+0000] {standard_task_runner.py:104} INFO - Running: ['***', 'tasks', 'run', 'etl_fire_incidents_dag', 'task_etl_fire_incident_using_bash', 'scheduled__2025-03-08T15:00:00+00:00', '--job-id', '448', '--raw', '--subdir', 'DAGS_FOLDER/fire_incidents_dag.py', '--cfg-path', '/tmp/tmp0h64jf8w']
[2025-03-08T18:12:22.540+0000] {standard_task_runner.py:105} INFO - Job 448: Subtask task_etl_fire_incident_using_bash
[2025-03-08T18:12:22.592+0000] {task_command.py:467} INFO - Running <TaskInstance: etl_fire_incidents_dag.task_etl_fire_incident_using_bash scheduled__2025-03-08T15:00:00+00:00 [running]> on host fad361e322ea
[2025-03-08T18:12:22.663+0000] {taskinstance.py:3134} INFO - Exporting env vars: AIRFLOW_CTX_DAG_EMAIL='***@***.com' AIRFLOW_CTX_DAG_OWNER='***' AIRFLOW_CTX_DAG_ID='etl_fire_incidents_dag' AIRFLOW_CTX_TASK_ID='task_etl_fire_incident_using_bash' AIRFLOW_CTX_EXECUTION_DATE='2025-03-08T15:00:00+00:00' AIRFLOW_CTX_TRY_NUMBER='1' AIRFLOW_CTX_DAG_RUN_ID='scheduled__2025-03-08T15:00:00+00:00'
[2025-03-08T18:12:22.664+0000] {logging_mixin.py:190} INFO - Task instance is in running state
[2025-03-08T18:12:22.664+0000] {logging_mixin.py:190} INFO -  Previous state of the Task instance: queued
[2025-03-08T18:12:22.665+0000] {logging_mixin.py:190} INFO - Current task name:task_etl_fire_incident_using_bash state:running start_date:2025-03-08 18:12:22.486001+00:00
[2025-03-08T18:12:22.665+0000] {logging_mixin.py:190} INFO - Dag name:etl_fire_incidents_dag and current dag run status:running
[2025-03-08T18:12:22.665+0000] {taskinstance.py:732} INFO - ::endgroup::
[2025-03-08T18:12:22.666+0000] {subprocess.py:78} INFO - Tmp dir root location: /tmp
[2025-03-08T18:12:22.666+0000] {subprocess.py:88} INFO - Running command: ['/usr/bin/bash', '-c', 'docker run --rm \\--network=pg-network-fire-incidents \\nyc_fire_incidents:v001 \\--api_url=data.cityofnewyork.us \\--token=xoIfIdDlHq6gGzxqLqbUeMpsG \\--dataset_id=8m42-w767 \\--limit_rows=10000 \\--username=root \\--password=root \\--host_name=fire_incidents_db_container \\--port=5432 \\--database=fire_incidents_db \\--tbl_name=fire_incidents_tbl']
[2025-03-08T18:12:22.682+0000] {subprocess.py:99} INFO - Output:
[2025-03-08T18:12:26.961+0000] {subprocess.py:106} INFO - Traceback (most recent call last):
[2025-03-08T18:12:26.961+0000] {subprocess.py:106} INFO -   File "/app/pull_fire_incidents.py", line 22, in <module>
[2025-03-08T18:12:26.961+0000] {subprocess.py:106} INFO -     from ***.models import TaskInstance
[2025-03-08T18:12:26.961+0000] {subprocess.py:106} INFO - ModuleNotFoundError: No module named '***'
[2025-03-08T18:12:27.522+0000] {subprocess.py:110} INFO - Command exited with return code 1
[2025-03-08T18:12:27.531+0000] {taskinstance.py:3313} ERROR - Task failed with exception
Traceback (most recent call last):
  File "/home/airflow/.local/lib/python3.12/site-packages/airflow/models/taskinstance.py", line 768, in _execute_task
    result = _execute_callable(context=context, **execute_callable_kwargs)
             ^^^^^^^^^^^^^^^^^^^^^^^^^^^^^^^^^^^^^^^^^^^^^^^^^^^^^^^^^^^^^
  File "/home/airflow/.local/lib/python3.12/site-packages/airflow/models/taskinstance.py", line 734, in _execute_callable
    return ExecutionCallableRunner(
           ^^^^^^^^^^^^^^^^^^^^^^^^
  File "/home/airflow/.local/lib/python3.12/site-packages/airflow/utils/operator_helpers.py", line 252, in run
    return self.func(*args, **kwargs)
           ^^^^^^^^^^^^^^^^^^^^^^^^^^
  File "/home/airflow/.local/lib/python3.12/site-packages/airflow/models/baseoperator.py", line 424, in wrapper
    return func(self, *args, **kwargs)
           ^^^^^^^^^^^^^^^^^^^^^^^^^^^
  File "/home/airflow/.local/lib/python3.12/site-packages/airflow/operators/bash.py", line 276, in execute
    raise AirflowException(
airflow.exceptions.AirflowException: Bash command failed. The command returned a non-zero exit code 1.
[2025-03-08T18:12:27.544+0000] {logging_mixin.py:190} INFO - Task instance in failure state
[2025-03-08T18:12:27.544+0000] {logging_mixin.py:190} INFO - Task start:2025-03-08 18:12:22.486001+00:00 end:2025-03-08 18:12:27.543712+00:00 duration:5.057711
[2025-03-08T18:12:27.544+0000] {logging_mixin.py:190} INFO - Task:<Task(BashOperator): task_etl_fire_incident_using_bash> dag:<DAG: etl_fire_incidents_dag> dagrun:<DagRun etl_fire_incidents_dag @ 2025-03-08 15:00:00+00:00: scheduled__2025-03-08T15:00:00+00:00, state:running, queued_at: 2025-03-08 18:12:16.716203+00:00. externally triggered: False>
[2025-03-08T18:12:27.544+0000] {logging_mixin.py:190} INFO - Failure caused by Bash command failed. The command returned a non-zero exit code 1.
[2025-03-08T18:12:27.545+0000] {taskinstance.py:1226} INFO - Marking task as UP_FOR_RETRY. dag_id=etl_fire_incidents_dag, task_id=task_etl_fire_incident_using_bash, run_id=scheduled__2025-03-08T15:00:00+00:00, execution_date=20250308T150000, start_date=20250308T181222, end_date=20250308T181227
[2025-03-08T18:12:27.586+0000] {taskinstance.py:341} INFO - ::group::Post task execution logs
[2025-03-08T18:12:27.587+0000] {standard_task_runner.py:124} ERROR - Failed to execute job 448 for task task_etl_fire_incident_using_bash (Bash command failed. The command returned a non-zero exit code 1.; 120)
Traceback (most recent call last):
  File "/home/airflow/.local/lib/python3.12/site-packages/airflow/task/task_runner/standard_task_runner.py", line 117, in _start_by_fork
    ret = args.func(args, dag=self.dag)
          ^^^^^^^^^^^^^^^^^^^^^^^^^^^^^
  File "/home/airflow/.local/lib/python3.12/site-packages/airflow/cli/cli_config.py", line 49, in command
    return func(*args, **kwargs)
           ^^^^^^^^^^^^^^^^^^^^^
  File "/home/airflow/.local/lib/python3.12/site-packages/airflow/utils/cli.py", line 116, in wrapper
    return f(*args, **kwargs)
           ^^^^^^^^^^^^^^^^^^
  File "/home/airflow/.local/lib/python3.12/site-packages/airflow/cli/commands/task_command.py", line 483, in task_run
    task_return_code = _run_task_by_selected_method(args, _dag, ti)
                       ^^^^^^^^^^^^^^^^^^^^^^^^^^^^^^^^^^^^^^^^^^^^
  File "/home/airflow/.local/lib/python3.12/site-packages/airflow/cli/commands/task_command.py", line 256, in _run_task_by_selected_method
    return _run_raw_task(args, ti)
           ^^^^^^^^^^^^^^^^^^^^^^^
  File "/home/airflow/.local/lib/python3.12/site-packages/airflow/cli/commands/task_command.py", line 341, in _run_raw_task
    return ti._run_raw_task(
           ^^^^^^^^^^^^^^^^^
  File "/home/airflow/.local/lib/python3.12/site-packages/airflow/utils/session.py", line 97, in wrapper
    return func(*args, session=session, **kwargs)
           ^^^^^^^^^^^^^^^^^^^^^^^^^^^^^^^^^^^^^^
  File "/home/airflow/.local/lib/python3.12/site-packages/airflow/models/taskinstance.py", line 3006, in _run_raw_task
    return _run_raw_task(
           ^^^^^^^^^^^^^^
  File "/home/airflow/.local/lib/python3.12/site-packages/airflow/models/taskinstance.py", line 274, in _run_raw_task
    TaskInstance._execute_task_with_callbacks(
  File "/home/airflow/.local/lib/python3.12/site-packages/airflow/models/taskinstance.py", line 3161, in _execute_task_with_callbacks
    result = self._execute_task(context, task_orig)
             ^^^^^^^^^^^^^^^^^^^^^^^^^^^^^^^^^^^^^^
  File "/home/airflow/.local/lib/python3.12/site-packages/airflow/models/taskinstance.py", line 3185, in _execute_task
    return _execute_task(self, context, task_orig)
           ^^^^^^^^^^^^^^^^^^^^^^^^^^^^^^^^^^^^^^^
  File "/home/airflow/.local/lib/python3.12/site-packages/airflow/models/taskinstance.py", line 768, in _execute_task
    result = _execute_callable(context=context, **execute_callable_kwargs)
             ^^^^^^^^^^^^^^^^^^^^^^^^^^^^^^^^^^^^^^^^^^^^^^^^^^^^^^^^^^^^^
  File "/home/airflow/.local/lib/python3.12/site-packages/airflow/models/taskinstance.py", line 734, in _execute_callable
    return ExecutionCallableRunner(
           ^^^^^^^^^^^^^^^^^^^^^^^^
  File "/home/airflow/.local/lib/python3.12/site-packages/airflow/utils/operator_helpers.py", line 252, in run
    return self.func(*args, **kwargs)
           ^^^^^^^^^^^^^^^^^^^^^^^^^^
  File "/home/airflow/.local/lib/python3.12/site-packages/airflow/models/baseoperator.py", line 424, in wrapper
    return func(self, *args, **kwargs)
           ^^^^^^^^^^^^^^^^^^^^^^^^^^^
  File "/home/airflow/.local/lib/python3.12/site-packages/airflow/operators/bash.py", line 276, in execute
    raise AirflowException(
airflow.exceptions.AirflowException: Bash command failed. The command returned a non-zero exit code 1.
[2025-03-08T18:12:27.617+0000] {local_task_job_runner.py:266} INFO - Task exited with return code 1
[2025-03-08T18:12:27.636+0000] {taskinstance.py:3901} INFO - 0 downstream tasks scheduled from follow-on schedule check
[2025-03-08T18:12:27.643+0000] {local_task_job_runner.py:245} INFO - ::endgroup::
[2025-03-08T18:23:23.492+0000] {local_task_job_runner.py:123} INFO - ::group::Pre task execution logs
[2025-03-08T18:23:23.630+0000] {taskinstance.py:2614} INFO - Dependencies all met for dep_context=non-requeueable deps ti=<TaskInstance: etl_fire_incidents_dag.task_etl_fire_incident_using_bash scheduled__2025-03-08T15:00:00+00:00 [queued]>
[2025-03-08T18:23:23.636+0000] {taskinstance.py:2614} INFO - Dependencies all met for dep_context=requeueable deps ti=<TaskInstance: etl_fire_incidents_dag.task_etl_fire_incident_using_bash scheduled__2025-03-08T15:00:00+00:00 [queued]>
[2025-03-08T18:23:23.636+0000] {taskinstance.py:2867} INFO - Starting attempt 1 of 2
[2025-03-08T18:23:23.647+0000] {taskinstance.py:2890} INFO - Executing <Task(BashOperator): task_etl_fire_incident_using_bash> on 2025-03-08 15:00:00+00:00
[2025-03-08T18:23:23.653+0000] {warnings.py:112} WARNING - /home/***/.local/lib/python3.12/site-packages/***/task/task_runner/standard_task_runner.py:70: DeprecationWarning: This process (pid=348) is multi-threaded, use of fork() may lead to deadlocks in the child.
  pid = os.fork()

[2025-03-08T18:23:23.654+0000] {standard_task_runner.py:72} INFO - Started process 350 to run task
[2025-03-08T18:23:23.654+0000] {standard_task_runner.py:104} INFO - Running: ['***', 'tasks', 'run', 'etl_fire_incidents_dag', 'task_etl_fire_incident_using_bash', 'scheduled__2025-03-08T15:00:00+00:00', '--job-id', '454', '--raw', '--subdir', 'DAGS_FOLDER/fire_incidents_dag.py', '--cfg-path', '/tmp/tmpdnhwivo1']
[2025-03-08T18:23:23.655+0000] {standard_task_runner.py:105} INFO - Job 454: Subtask task_etl_fire_incident_using_bash
[2025-03-08T18:23:23.691+0000] {task_command.py:467} INFO - Running <TaskInstance: etl_fire_incidents_dag.task_etl_fire_incident_using_bash scheduled__2025-03-08T15:00:00+00:00 [running]> on host fad361e322ea
[2025-03-08T18:23:23.765+0000] {taskinstance.py:3134} INFO - Exporting env vars: AIRFLOW_CTX_DAG_EMAIL='***@***.com' AIRFLOW_CTX_DAG_OWNER='***' AIRFLOW_CTX_DAG_ID='etl_fire_incidents_dag' AIRFLOW_CTX_TASK_ID='task_etl_fire_incident_using_bash' AIRFLOW_CTX_EXECUTION_DATE='2025-03-08T15:00:00+00:00' AIRFLOW_CTX_TRY_NUMBER='1' AIRFLOW_CTX_DAG_RUN_ID='scheduled__2025-03-08T15:00:00+00:00'
[2025-03-08T18:23:23.767+0000] {logging_mixin.py:190} INFO - Task instance is in running state
[2025-03-08T18:23:23.768+0000] {logging_mixin.py:190} INFO -  Previous state of the Task instance: queued
[2025-03-08T18:23:23.768+0000] {logging_mixin.py:190} INFO - Current task name:task_etl_fire_incident_using_bash state:running start_date:2025-03-08 18:23:23.630654+00:00
[2025-03-08T18:23:23.768+0000] {logging_mixin.py:190} INFO - Dag name:etl_fire_incidents_dag and current dag run status:running
[2025-03-08T18:23:23.768+0000] {taskinstance.py:732} INFO - ::endgroup::
[2025-03-08T18:23:23.769+0000] {subprocess.py:78} INFO - Tmp dir root location: /tmp
[2025-03-08T18:23:23.770+0000] {subprocess.py:88} INFO - Running command: ['/usr/bin/bash', '-c', 'docker run --rm \\--network=pg-network-fire-incidents \\nyc_fire_incidents:v001 \\--api_url=data.cityofnewyork.us \\--token=xoIfIdDlHq6gGzxqLqbUeMpsG \\--dataset_id=8m42-w767 \\--limit_rows=10000 \\--username=root \\--password=root \\--host_name=fire_incidents_db_container \\--port=5432 \\--database=fire_incidents_db \\--tbl_name=fire_incidents_tbl']
[2025-03-08T18:23:23.782+0000] {subprocess.py:99} INFO - Output:
[2025-03-08T18:23:25.352+0000] {subprocess.py:106} INFO - /app/pull_fire_incidents.py:23 DeprecationWarning: The `***.operators.python_operator.PythonOperator` class is deprecated. Please use `'***.operators.python.PythonOperator'`.
[2025-03-08T18:23:25.712+0000] {subprocess.py:106} INFO - Traceback (most recent call last):
[2025-03-08T18:23:25.712+0000] {subprocess.py:106} INFO -   File "/app/pull_fire_incidents.py", line 74, in <module>
[2025-03-08T18:23:25.712+0000] {subprocess.py:106} INFO -     bash_function()
[2025-03-08T18:23:25.713+0000] {subprocess.py:106} INFO -   File "/app/pull_fire_incidents.py", line 70, in bash_function
[2025-03-08T18:23:25.713+0000] {subprocess.py:106} INFO -     task_instance = kwargs['ti']
[2025-03-08T18:23:25.713+0000] {subprocess.py:106} INFO - KeyError: 'ti'
[2025-03-08T18:23:26.308+0000] {subprocess.py:110} INFO - Command exited with return code 1
[2025-03-08T18:23:26.320+0000] {taskinstance.py:3313} ERROR - Task failed with exception
Traceback (most recent call last):
  File "/home/airflow/.local/lib/python3.12/site-packages/airflow/models/taskinstance.py", line 768, in _execute_task
    result = _execute_callable(context=context, **execute_callable_kwargs)
             ^^^^^^^^^^^^^^^^^^^^^^^^^^^^^^^^^^^^^^^^^^^^^^^^^^^^^^^^^^^^^
  File "/home/airflow/.local/lib/python3.12/site-packages/airflow/models/taskinstance.py", line 734, in _execute_callable
    return ExecutionCallableRunner(
           ^^^^^^^^^^^^^^^^^^^^^^^^
  File "/home/airflow/.local/lib/python3.12/site-packages/airflow/utils/operator_helpers.py", line 252, in run
    return self.func(*args, **kwargs)
           ^^^^^^^^^^^^^^^^^^^^^^^^^^
  File "/home/airflow/.local/lib/python3.12/site-packages/airflow/models/baseoperator.py", line 424, in wrapper
    return func(self, *args, **kwargs)
           ^^^^^^^^^^^^^^^^^^^^^^^^^^^
  File "/home/airflow/.local/lib/python3.12/site-packages/airflow/operators/bash.py", line 276, in execute
    raise AirflowException(
airflow.exceptions.AirflowException: Bash command failed. The command returned a non-zero exit code 1.
[2025-03-08T18:23:26.326+0000] {logging_mixin.py:190} INFO - Task instance in failure state
[2025-03-08T18:23:26.327+0000] {logging_mixin.py:190} INFO - Task start:2025-03-08 18:23:23.630654+00:00 end:2025-03-08 18:23:26.326413+00:00 duration:2.695759
[2025-03-08T18:23:26.327+0000] {logging_mixin.py:190} INFO - Task:<Task(BashOperator): task_etl_fire_incident_using_bash> dag:<DAG: etl_fire_incidents_dag> dagrun:<DagRun etl_fire_incidents_dag @ 2025-03-08 15:00:00+00:00: scheduled__2025-03-08T15:00:00+00:00, state:running, queued_at: 2025-03-08 18:23:22.177638+00:00. externally triggered: False>
[2025-03-08T18:23:26.327+0000] {logging_mixin.py:190} INFO - Failure caused by Bash command failed. The command returned a non-zero exit code 1.
[2025-03-08T18:23:26.327+0000] {taskinstance.py:1226} INFO - Marking task as UP_FOR_RETRY. dag_id=etl_fire_incidents_dag, task_id=task_etl_fire_incident_using_bash, run_id=scheduled__2025-03-08T15:00:00+00:00, execution_date=20250308T150000, start_date=20250308T182323, end_date=20250308T182326
[2025-03-08T18:23:26.360+0000] {taskinstance.py:341} INFO - ::group::Post task execution logs
[2025-03-08T18:23:26.361+0000] {standard_task_runner.py:124} ERROR - Failed to execute job 454 for task task_etl_fire_incident_using_bash (Bash command failed. The command returned a non-zero exit code 1.; 350)
Traceback (most recent call last):
  File "/home/airflow/.local/lib/python3.12/site-packages/airflow/task/task_runner/standard_task_runner.py", line 117, in _start_by_fork
    ret = args.func(args, dag=self.dag)
          ^^^^^^^^^^^^^^^^^^^^^^^^^^^^^
  File "/home/airflow/.local/lib/python3.12/site-packages/airflow/cli/cli_config.py", line 49, in command
    return func(*args, **kwargs)
           ^^^^^^^^^^^^^^^^^^^^^
  File "/home/airflow/.local/lib/python3.12/site-packages/airflow/utils/cli.py", line 116, in wrapper
    return f(*args, **kwargs)
           ^^^^^^^^^^^^^^^^^^
  File "/home/airflow/.local/lib/python3.12/site-packages/airflow/cli/commands/task_command.py", line 483, in task_run
    task_return_code = _run_task_by_selected_method(args, _dag, ti)
                       ^^^^^^^^^^^^^^^^^^^^^^^^^^^^^^^^^^^^^^^^^^^^
  File "/home/airflow/.local/lib/python3.12/site-packages/airflow/cli/commands/task_command.py", line 256, in _run_task_by_selected_method
    return _run_raw_task(args, ti)
           ^^^^^^^^^^^^^^^^^^^^^^^
  File "/home/airflow/.local/lib/python3.12/site-packages/airflow/cli/commands/task_command.py", line 341, in _run_raw_task
    return ti._run_raw_task(
           ^^^^^^^^^^^^^^^^^
  File "/home/airflow/.local/lib/python3.12/site-packages/airflow/utils/session.py", line 97, in wrapper
    return func(*args, session=session, **kwargs)
           ^^^^^^^^^^^^^^^^^^^^^^^^^^^^^^^^^^^^^^
  File "/home/airflow/.local/lib/python3.12/site-packages/airflow/models/taskinstance.py", line 3006, in _run_raw_task
    return _run_raw_task(
           ^^^^^^^^^^^^^^
  File "/home/airflow/.local/lib/python3.12/site-packages/airflow/models/taskinstance.py", line 274, in _run_raw_task
    TaskInstance._execute_task_with_callbacks(
  File "/home/airflow/.local/lib/python3.12/site-packages/airflow/models/taskinstance.py", line 3161, in _execute_task_with_callbacks
    result = self._execute_task(context, task_orig)
             ^^^^^^^^^^^^^^^^^^^^^^^^^^^^^^^^^^^^^^
  File "/home/airflow/.local/lib/python3.12/site-packages/airflow/models/taskinstance.py", line 3185, in _execute_task
    return _execute_task(self, context, task_orig)
           ^^^^^^^^^^^^^^^^^^^^^^^^^^^^^^^^^^^^^^^
  File "/home/airflow/.local/lib/python3.12/site-packages/airflow/models/taskinstance.py", line 768, in _execute_task
    result = _execute_callable(context=context, **execute_callable_kwargs)
             ^^^^^^^^^^^^^^^^^^^^^^^^^^^^^^^^^^^^^^^^^^^^^^^^^^^^^^^^^^^^^
  File "/home/airflow/.local/lib/python3.12/site-packages/airflow/models/taskinstance.py", line 734, in _execute_callable
    return ExecutionCallableRunner(
           ^^^^^^^^^^^^^^^^^^^^^^^^
  File "/home/airflow/.local/lib/python3.12/site-packages/airflow/utils/operator_helpers.py", line 252, in run
    return self.func(*args, **kwargs)
           ^^^^^^^^^^^^^^^^^^^^^^^^^^
  File "/home/airflow/.local/lib/python3.12/site-packages/airflow/models/baseoperator.py", line 424, in wrapper
    return func(self, *args, **kwargs)
           ^^^^^^^^^^^^^^^^^^^^^^^^^^^
  File "/home/airflow/.local/lib/python3.12/site-packages/airflow/operators/bash.py", line 276, in execute
    raise AirflowException(
airflow.exceptions.AirflowException: Bash command failed. The command returned a non-zero exit code 1.
[2025-03-08T18:23:26.380+0000] {local_task_job_runner.py:266} INFO - Task exited with return code 1
[2025-03-08T18:23:26.402+0000] {taskinstance.py:3901} INFO - 0 downstream tasks scheduled from follow-on schedule check
[2025-03-08T18:23:26.404+0000] {local_task_job_runner.py:245} INFO - ::endgroup::
[2025-03-08T18:43:45.685+0000] {local_task_job_runner.py:123} INFO - ::group::Pre task execution logs
[2025-03-08T18:43:45.705+0000] {taskinstance.py:2614} INFO - Dependencies all met for dep_context=non-requeueable deps ti=<TaskInstance: etl_fire_incidents_dag.task_etl_fire_incident_using_bash scheduled__2025-03-08T15:00:00+00:00 [queued]>
[2025-03-08T18:43:45.711+0000] {taskinstance.py:2614} INFO - Dependencies all met for dep_context=requeueable deps ti=<TaskInstance: etl_fire_incidents_dag.task_etl_fire_incident_using_bash scheduled__2025-03-08T15:00:00+00:00 [queued]>
[2025-03-08T18:43:45.711+0000] {taskinstance.py:2867} INFO - Starting attempt 1 of 2
[2025-03-08T18:43:45.723+0000] {taskinstance.py:2890} INFO - Executing <Task(BashOperator): task_etl_fire_incident_using_bash> on 2025-03-08 15:00:00+00:00
[2025-03-08T18:43:45.730+0000] {warnings.py:112} WARNING - /home/***/.local/lib/python3.12/site-packages/***/task/task_runner/standard_task_runner.py:70: DeprecationWarning: This process (pid=726) is multi-threaded, use of fork() may lead to deadlocks in the child.
  pid = os.fork()

[2025-03-08T18:43:45.733+0000] {standard_task_runner.py:104} INFO - Running: ['***', 'tasks', 'run', 'etl_fire_incidents_dag', 'task_etl_fire_incident_using_bash', 'scheduled__2025-03-08T15:00:00+00:00', '--job-id', '464', '--raw', '--subdir', 'DAGS_FOLDER/fire_incidents_dag.py', '--cfg-path', '/tmp/tmpyi7ib2dq']
[2025-03-08T18:43:45.733+0000] {standard_task_runner.py:105} INFO - Job 464: Subtask task_etl_fire_incident_using_bash
[2025-03-08T18:43:45.733+0000] {standard_task_runner.py:72} INFO - Started process 729 to run task
[2025-03-08T18:43:45.794+0000] {task_command.py:467} INFO - Running <TaskInstance: etl_fire_incidents_dag.task_etl_fire_incident_using_bash scheduled__2025-03-08T15:00:00+00:00 [running]> on host fad361e322ea
[2025-03-08T18:43:45.871+0000] {taskinstance.py:3134} INFO - Exporting env vars: AIRFLOW_CTX_DAG_EMAIL='***@***.com' AIRFLOW_CTX_DAG_OWNER='***' AIRFLOW_CTX_DAG_ID='etl_fire_incidents_dag' AIRFLOW_CTX_TASK_ID='task_etl_fire_incident_using_bash' AIRFLOW_CTX_EXECUTION_DATE='2025-03-08T15:00:00+00:00' AIRFLOW_CTX_TRY_NUMBER='1' AIRFLOW_CTX_DAG_RUN_ID='scheduled__2025-03-08T15:00:00+00:00'
[2025-03-08T18:43:45.872+0000] {logging_mixin.py:190} INFO - Task instance is in running state
[2025-03-08T18:43:45.872+0000] {logging_mixin.py:190} INFO -  Previous state of the Task instance: queued
[2025-03-08T18:43:45.872+0000] {logging_mixin.py:190} INFO - Current task name:task_etl_fire_incident_using_bash state:running start_date:2025-03-08 18:43:45.705455+00:00
[2025-03-08T18:43:45.872+0000] {logging_mixin.py:190} INFO - Dag name:etl_fire_incidents_dag and current dag run status:running
[2025-03-08T18:43:45.873+0000] {taskinstance.py:732} INFO - ::endgroup::
[2025-03-08T18:43:45.873+0000] {subprocess.py:78} INFO - Tmp dir root location: /tmp
[2025-03-08T18:43:45.874+0000] {subprocess.py:88} INFO - Running command: ['/usr/bin/bash', '-c', 'docker run --rm \\--network=pg-network-fire-incidents \\nyc_fire_incidents:v001 \\--api_url=data.cityofnewyork.us \\--token=xoIfIdDlHq6gGzxqLqbUeMpsG \\--dataset_id=8m42-w767 \\--limit_rows=10000 \\--username=root \\--password=root \\--host_name=fire_incidents_db_container \\--port=5432 \\--database=fire_incidents_db \\--tbl_name=fire_incidents_tbl']
[2025-03-08T18:43:45.884+0000] {subprocess.py:99} INFO - Output:
[2025-03-08T18:43:47.376+0000] {subprocess.py:106} INFO - /app/pull_fire_incidents.py:23 DeprecationWarning: The `***.operators.python_operator.PythonOperator` class is deprecated. Please use `'***.operators.python.PythonOperator'`.
[2025-03-08T18:43:48.190+0000] {subprocess.py:110} INFO - Command exited with return code 0
[2025-03-08T18:43:48.218+0000] {taskinstance.py:341} INFO - ::group::Post task execution logs
[2025-03-08T18:43:48.218+0000] {taskinstance.py:353} INFO - Marking task as SUCCESS. dag_id=etl_fire_incidents_dag, task_id=task_etl_fire_incident_using_bash, run_id=scheduled__2025-03-08T15:00:00+00:00, execution_date=20250308T150000, start_date=20250308T184345, end_date=20250308T184348
[2025-03-08T18:43:48.235+0000] {logging_mixin.py:190} INFO - Task instance in success state
[2025-03-08T18:43:48.236+0000] {logging_mixin.py:190} INFO -  Previous state of the Task instance: running
[2025-03-08T18:43:48.236+0000] {logging_mixin.py:190} INFO - Dag name:etl_fire_incidents_dag queued_at:2025-03-08 18:43:44.153274+00:00
[2025-03-08T18:43:48.236+0000] {logging_mixin.py:190} INFO - Task hostname:fad361e322ea operator:BashOperator
[2025-03-08T18:43:48.279+0000] {local_task_job_runner.py:266} INFO - Task exited with return code 0
[2025-03-08T18:43:48.307+0000] {taskinstance.py:3901} INFO - 1 downstream tasks scheduled from follow-on schedule check
[2025-03-08T18:43:48.309+0000] {local_task_job_runner.py:245} INFO - ::endgroup::
[2025-03-08T18:52:35.948+0000] {local_task_job_runner.py:123} INFO - ::group::Pre task execution logs
[2025-03-08T18:52:35.972+0000] {taskinstance.py:2614} INFO - Dependencies all met for dep_context=non-requeueable deps ti=<TaskInstance: etl_fire_incidents_dag.task_etl_fire_incident_using_bash scheduled__2025-03-08T15:00:00+00:00 [queued]>
[2025-03-08T18:52:35.980+0000] {taskinstance.py:2614} INFO - Dependencies all met for dep_context=requeueable deps ti=<TaskInstance: etl_fire_incidents_dag.task_etl_fire_incident_using_bash scheduled__2025-03-08T15:00:00+00:00 [queued]>
[2025-03-08T18:52:35.980+0000] {taskinstance.py:2867} INFO - Starting attempt 1 of 2
[2025-03-08T18:52:35.998+0000] {taskinstance.py:2890} INFO - Executing <Task(BashOperator): task_etl_fire_incident_using_bash> on 2025-03-08 15:00:00+00:00
[2025-03-08T18:52:36.003+0000] {warnings.py:112} WARNING - /home/***/.local/lib/python3.12/site-packages/***/task/task_runner/standard_task_runner.py:70: DeprecationWarning: This process (pid=889) is multi-threaded, use of fork() may lead to deadlocks in the child.
  pid = os.fork()

[2025-03-08T18:52:36.004+0000] {standard_task_runner.py:72} INFO - Started process 898 to run task
[2025-03-08T18:52:36.005+0000] {standard_task_runner.py:104} INFO - Running: ['***', 'tasks', 'run', 'etl_fire_incidents_dag', 'task_etl_fire_incident_using_bash', 'scheduled__2025-03-08T15:00:00+00:00', '--job-id', '469', '--raw', '--subdir', 'DAGS_FOLDER/fire_incidents_dag.py', '--cfg-path', '/tmp/tmpzw6qkbfa']
[2025-03-08T18:52:36.005+0000] {standard_task_runner.py:105} INFO - Job 469: Subtask task_etl_fire_incident_using_bash
[2025-03-08T18:52:36.040+0000] {task_command.py:467} INFO - Running <TaskInstance: etl_fire_incidents_dag.task_etl_fire_incident_using_bash scheduled__2025-03-08T15:00:00+00:00 [running]> on host fad361e322ea
[2025-03-08T18:52:36.107+0000] {taskinstance.py:3134} INFO - Exporting env vars: AIRFLOW_CTX_DAG_EMAIL='***@***.com' AIRFLOW_CTX_DAG_OWNER='***' AIRFLOW_CTX_DAG_ID='etl_fire_incidents_dag' AIRFLOW_CTX_TASK_ID='task_etl_fire_incident_using_bash' AIRFLOW_CTX_EXECUTION_DATE='2025-03-08T15:00:00+00:00' AIRFLOW_CTX_TRY_NUMBER='1' AIRFLOW_CTX_DAG_RUN_ID='scheduled__2025-03-08T15:00:00+00:00'
[2025-03-08T18:52:36.108+0000] {logging_mixin.py:190} INFO - Task instance is in running state
[2025-03-08T18:52:36.108+0000] {logging_mixin.py:190} INFO -  Previous state of the Task instance: queued
[2025-03-08T18:52:36.108+0000] {logging_mixin.py:190} INFO - Current task name:task_etl_fire_incident_using_bash state:running start_date:2025-03-08 18:52:35.973360+00:00
[2025-03-08T18:52:36.108+0000] {logging_mixin.py:190} INFO - Dag name:etl_fire_incidents_dag and current dag run status:running
[2025-03-08T18:52:36.108+0000] {taskinstance.py:732} INFO - ::endgroup::
[2025-03-08T18:52:36.109+0000] {subprocess.py:78} INFO - Tmp dir root location: /tmp
[2025-03-08T18:52:36.110+0000] {subprocess.py:88} INFO - Running command: ['/usr/bin/bash', '-c', 'docker run --rm \\--network=pg-network-fire-incidents \\nyc_fire_incidents:v001 \\--api_url=data.cityofnewyork.us \\--token=xoIfIdDlHq6gGzxqLqbUeMpsG \\--dataset_id=8m42-w767 \\--limit_rows=10000 \\--username=root \\--password=root \\--host_name=fire_incidents_db_container \\--port=5432 \\--database=fire_incidents_db \\--tbl_name=fire_incidents_tbl']
[2025-03-08T18:52:36.121+0000] {subprocess.py:99} INFO - Output:
[2025-03-08T18:52:38.098+0000] {subprocess.py:106} INFO - /app/pull_fire_incidents.py:23 DeprecationWarning: The `***.operators.python_operator.PythonOperator` class is deprecated. Please use `'***.operators.python.PythonOperator'`.
[2025-03-08T18:52:38.434+0000] {subprocess.py:106} INFO - Traceback (most recent call last):
[2025-03-08T18:52:38.434+0000] {subprocess.py:106} INFO -   File "/app/pull_fire_incidents.py", line 74, in <module>
[2025-03-08T18:52:38.434+0000] {subprocess.py:106} INFO -     bash_function(args)
[2025-03-08T18:52:38.435+0000] {subprocess.py:106} INFO -   File "/app/pull_fire_incidents.py", line 70, in bash_function
[2025-03-08T18:52:38.435+0000] {subprocess.py:106} INFO -     task_instance = kwargs['ti']
[2025-03-08T18:52:38.435+0000] {subprocess.py:106} INFO - KeyError: 'ti'
[2025-03-08T18:52:40.451+0000] {subprocess.py:110} INFO - Command exited with return code 1
[2025-03-08T18:52:40.461+0000] {taskinstance.py:3313} ERROR - Task failed with exception
Traceback (most recent call last):
  File "/home/airflow/.local/lib/python3.12/site-packages/airflow/models/taskinstance.py", line 768, in _execute_task
    result = _execute_callable(context=context, **execute_callable_kwargs)
             ^^^^^^^^^^^^^^^^^^^^^^^^^^^^^^^^^^^^^^^^^^^^^^^^^^^^^^^^^^^^^
  File "/home/airflow/.local/lib/python3.12/site-packages/airflow/models/taskinstance.py", line 734, in _execute_callable
    return ExecutionCallableRunner(
           ^^^^^^^^^^^^^^^^^^^^^^^^
  File "/home/airflow/.local/lib/python3.12/site-packages/airflow/utils/operator_helpers.py", line 252, in run
    return self.func(*args, **kwargs)
           ^^^^^^^^^^^^^^^^^^^^^^^^^^
  File "/home/airflow/.local/lib/python3.12/site-packages/airflow/models/baseoperator.py", line 424, in wrapper
    return func(self, *args, **kwargs)
           ^^^^^^^^^^^^^^^^^^^^^^^^^^^
  File "/home/airflow/.local/lib/python3.12/site-packages/airflow/operators/bash.py", line 276, in execute
    raise AirflowException(
airflow.exceptions.AirflowException: Bash command failed. The command returned a non-zero exit code 1.
[2025-03-08T18:52:40.470+0000] {logging_mixin.py:190} INFO - Task instance in failure state
[2025-03-08T18:52:40.471+0000] {logging_mixin.py:190} INFO - Task start:2025-03-08 18:52:35.973360+00:00 end:2025-03-08 18:52:40.470127+00:00 duration:4.496767
[2025-03-08T18:52:40.471+0000] {logging_mixin.py:190} INFO - Task:<Task(BashOperator): task_etl_fire_incident_using_bash> dag:<DAG: etl_fire_incidents_dag> dagrun:<DagRun etl_fire_incidents_dag @ 2025-03-08 15:00:00+00:00: scheduled__2025-03-08T15:00:00+00:00, state:running, queued_at: 2025-03-08 18:52:34.555797+00:00. externally triggered: False>
[2025-03-08T18:52:40.471+0000] {logging_mixin.py:190} INFO - Failure caused by Bash command failed. The command returned a non-zero exit code 1.
[2025-03-08T18:52:40.471+0000] {taskinstance.py:1226} INFO - Marking task as UP_FOR_RETRY. dag_id=etl_fire_incidents_dag, task_id=task_etl_fire_incident_using_bash, run_id=scheduled__2025-03-08T15:00:00+00:00, execution_date=20250308T150000, start_date=20250308T185235, end_date=20250308T185240
[2025-03-08T18:52:40.505+0000] {taskinstance.py:341} INFO - ::group::Post task execution logs
[2025-03-08T18:52:40.506+0000] {standard_task_runner.py:124} ERROR - Failed to execute job 469 for task task_etl_fire_incident_using_bash (Bash command failed. The command returned a non-zero exit code 1.; 898)
Traceback (most recent call last):
  File "/home/airflow/.local/lib/python3.12/site-packages/airflow/task/task_runner/standard_task_runner.py", line 117, in _start_by_fork
    ret = args.func(args, dag=self.dag)
          ^^^^^^^^^^^^^^^^^^^^^^^^^^^^^
  File "/home/airflow/.local/lib/python3.12/site-packages/airflow/cli/cli_config.py", line 49, in command
    return func(*args, **kwargs)
           ^^^^^^^^^^^^^^^^^^^^^
  File "/home/airflow/.local/lib/python3.12/site-packages/airflow/utils/cli.py", line 116, in wrapper
    return f(*args, **kwargs)
           ^^^^^^^^^^^^^^^^^^
  File "/home/airflow/.local/lib/python3.12/site-packages/airflow/cli/commands/task_command.py", line 483, in task_run
    task_return_code = _run_task_by_selected_method(args, _dag, ti)
                       ^^^^^^^^^^^^^^^^^^^^^^^^^^^^^^^^^^^^^^^^^^^^
  File "/home/airflow/.local/lib/python3.12/site-packages/airflow/cli/commands/task_command.py", line 256, in _run_task_by_selected_method
    return _run_raw_task(args, ti)
           ^^^^^^^^^^^^^^^^^^^^^^^
  File "/home/airflow/.local/lib/python3.12/site-packages/airflow/cli/commands/task_command.py", line 341, in _run_raw_task
    return ti._run_raw_task(
           ^^^^^^^^^^^^^^^^^
  File "/home/airflow/.local/lib/python3.12/site-packages/airflow/utils/session.py", line 97, in wrapper
    return func(*args, session=session, **kwargs)
           ^^^^^^^^^^^^^^^^^^^^^^^^^^^^^^^^^^^^^^
  File "/home/airflow/.local/lib/python3.12/site-packages/airflow/models/taskinstance.py", line 3006, in _run_raw_task
    return _run_raw_task(
           ^^^^^^^^^^^^^^
  File "/home/airflow/.local/lib/python3.12/site-packages/airflow/models/taskinstance.py", line 274, in _run_raw_task
    TaskInstance._execute_task_with_callbacks(
  File "/home/airflow/.local/lib/python3.12/site-packages/airflow/models/taskinstance.py", line 3161, in _execute_task_with_callbacks
    result = self._execute_task(context, task_orig)
             ^^^^^^^^^^^^^^^^^^^^^^^^^^^^^^^^^^^^^^
  File "/home/airflow/.local/lib/python3.12/site-packages/airflow/models/taskinstance.py", line 3185, in _execute_task
    return _execute_task(self, context, task_orig)
           ^^^^^^^^^^^^^^^^^^^^^^^^^^^^^^^^^^^^^^^
  File "/home/airflow/.local/lib/python3.12/site-packages/airflow/models/taskinstance.py", line 768, in _execute_task
    result = _execute_callable(context=context, **execute_callable_kwargs)
             ^^^^^^^^^^^^^^^^^^^^^^^^^^^^^^^^^^^^^^^^^^^^^^^^^^^^^^^^^^^^^
  File "/home/airflow/.local/lib/python3.12/site-packages/airflow/models/taskinstance.py", line 734, in _execute_callable
    return ExecutionCallableRunner(
           ^^^^^^^^^^^^^^^^^^^^^^^^
  File "/home/airflow/.local/lib/python3.12/site-packages/airflow/utils/operator_helpers.py", line 252, in run
    return self.func(*args, **kwargs)
           ^^^^^^^^^^^^^^^^^^^^^^^^^^
  File "/home/airflow/.local/lib/python3.12/site-packages/airflow/models/baseoperator.py", line 424, in wrapper
    return func(self, *args, **kwargs)
           ^^^^^^^^^^^^^^^^^^^^^^^^^^^
  File "/home/airflow/.local/lib/python3.12/site-packages/airflow/operators/bash.py", line 276, in execute
    raise AirflowException(
airflow.exceptions.AirflowException: Bash command failed. The command returned a non-zero exit code 1.
[2025-03-08T18:52:40.559+0000] {local_task_job_runner.py:266} INFO - Task exited with return code 1
[2025-03-08T18:52:40.579+0000] {taskinstance.py:3901} INFO - 0 downstream tasks scheduled from follow-on schedule check
[2025-03-08T18:52:40.587+0000] {local_task_job_runner.py:245} INFO - ::endgroup::
[2025-03-08T18:58:31.489+0000] {local_task_job_runner.py:123} INFO - ::group::Pre task execution logs
[2025-03-08T18:58:31.506+0000] {taskinstance.py:2614} INFO - Dependencies all met for dep_context=non-requeueable deps ti=<TaskInstance: etl_fire_incidents_dag.task_etl_fire_incident_using_bash scheduled__2025-03-08T15:00:00+00:00 [queued]>
[2025-03-08T18:58:31.515+0000] {taskinstance.py:2614} INFO - Dependencies all met for dep_context=requeueable deps ti=<TaskInstance: etl_fire_incidents_dag.task_etl_fire_incident_using_bash scheduled__2025-03-08T15:00:00+00:00 [queued]>
[2025-03-08T18:58:31.515+0000] {taskinstance.py:2867} INFO - Starting attempt 1 of 2
[2025-03-08T18:58:31.528+0000] {taskinstance.py:2890} INFO - Executing <Task(BashOperator): task_etl_fire_incident_using_bash> on 2025-03-08 15:00:00+00:00
[2025-03-08T18:58:31.538+0000] {warnings.py:112} WARNING - /home/***/.local/lib/python3.12/site-packages/***/task/task_runner/standard_task_runner.py:70: DeprecationWarning: This process (pid=1036) is multi-threaded, use of fork() may lead to deadlocks in the child.
  pid = os.fork()

[2025-03-08T18:58:31.539+0000] {standard_task_runner.py:72} INFO - Started process 1038 to run task
[2025-03-08T18:58:31.540+0000] {standard_task_runner.py:104} INFO - Running: ['***', 'tasks', 'run', 'etl_fire_incidents_dag', 'task_etl_fire_incident_using_bash', 'scheduled__2025-03-08T15:00:00+00:00', '--job-id', '473', '--raw', '--subdir', 'DAGS_FOLDER/fire_incidents_dag.py', '--cfg-path', '/tmp/tmppjvi4q2x']
[2025-03-08T18:58:31.541+0000] {standard_task_runner.py:105} INFO - Job 473: Subtask task_etl_fire_incident_using_bash
[2025-03-08T18:58:31.595+0000] {task_command.py:467} INFO - Running <TaskInstance: etl_fire_incidents_dag.task_etl_fire_incident_using_bash scheduled__2025-03-08T15:00:00+00:00 [running]> on host fad361e322ea
[2025-03-08T18:58:31.684+0000] {taskinstance.py:3134} INFO - Exporting env vars: AIRFLOW_CTX_DAG_EMAIL='***@***.com' AIRFLOW_CTX_DAG_OWNER='***' AIRFLOW_CTX_DAG_ID='etl_fire_incidents_dag' AIRFLOW_CTX_TASK_ID='task_etl_fire_incident_using_bash' AIRFLOW_CTX_EXECUTION_DATE='2025-03-08T15:00:00+00:00' AIRFLOW_CTX_TRY_NUMBER='1' AIRFLOW_CTX_DAG_RUN_ID='scheduled__2025-03-08T15:00:00+00:00'
[2025-03-08T18:58:31.686+0000] {logging_mixin.py:190} INFO - Task instance is in running state
[2025-03-08T18:58:31.687+0000] {logging_mixin.py:190} INFO -  Previous state of the Task instance: queued
[2025-03-08T18:58:31.687+0000] {logging_mixin.py:190} INFO - Current task name:task_etl_fire_incident_using_bash state:running start_date:2025-03-08 18:58:31.507291+00:00
[2025-03-08T18:58:31.687+0000] {logging_mixin.py:190} INFO - Dag name:etl_fire_incidents_dag and current dag run status:running
[2025-03-08T18:58:31.687+0000] {taskinstance.py:732} INFO - ::endgroup::
[2025-03-08T18:58:31.688+0000] {subprocess.py:78} INFO - Tmp dir root location: /tmp
[2025-03-08T18:58:31.689+0000] {subprocess.py:88} INFO - Running command: ['/usr/bin/bash', '-c', 'docker run --rm \\--network=pg-network-fire-incidents \\nyc_fire_incidents:v001 \\--api_url=data.cityofnewyork.us \\--token=xoIfIdDlHq6gGzxqLqbUeMpsG \\--dataset_id=8m42-w767 \\--limit_rows=10000 \\--username=root \\--password=root \\--host_name=fire_incidents_db_container \\--port=5432 \\--database=fire_incidents_db \\--tbl_name=fire_incidents_tbl']
[2025-03-08T18:58:31.704+0000] {subprocess.py:99} INFO - Output:
[2025-03-08T18:58:33.283+0000] {subprocess.py:106} INFO - /app/pull_fire_incidents.py:23 DeprecationWarning: The `***.operators.python_operator.PythonOperator` class is deprecated. Please use `'***.operators.python.PythonOperator'`.
[2025-03-08T18:58:33.603+0000] {subprocess.py:106} INFO - Traceback (most recent call last):
[2025-03-08T18:58:33.603+0000] {subprocess.py:106} INFO -   File "/app/pull_fire_incidents.py", line 74, in <module>
[2025-03-08T18:58:33.603+0000] {subprocess.py:106} INFO -     bash_function(args)
[2025-03-08T18:58:33.604+0000] {subprocess.py:106} INFO -   File "/app/pull_fire_incidents.py", line 70, in bash_function
[2025-03-08T18:58:33.604+0000] {subprocess.py:106} INFO -     task_instance = kwargs['ti']
[2025-03-08T18:58:33.604+0000] {subprocess.py:106} INFO - KeyError: 'ti'
[2025-03-08T18:58:34.242+0000] {subprocess.py:110} INFO - Command exited with return code 1
[2025-03-08T18:58:34.255+0000] {taskinstance.py:3313} ERROR - Task failed with exception
Traceback (most recent call last):
  File "/home/airflow/.local/lib/python3.12/site-packages/airflow/models/taskinstance.py", line 768, in _execute_task
    result = _execute_callable(context=context, **execute_callable_kwargs)
             ^^^^^^^^^^^^^^^^^^^^^^^^^^^^^^^^^^^^^^^^^^^^^^^^^^^^^^^^^^^^^
  File "/home/airflow/.local/lib/python3.12/site-packages/airflow/models/taskinstance.py", line 734, in _execute_callable
    return ExecutionCallableRunner(
           ^^^^^^^^^^^^^^^^^^^^^^^^
  File "/home/airflow/.local/lib/python3.12/site-packages/airflow/utils/operator_helpers.py", line 252, in run
    return self.func(*args, **kwargs)
           ^^^^^^^^^^^^^^^^^^^^^^^^^^
  File "/home/airflow/.local/lib/python3.12/site-packages/airflow/models/baseoperator.py", line 424, in wrapper
    return func(self, *args, **kwargs)
           ^^^^^^^^^^^^^^^^^^^^^^^^^^^
  File "/home/airflow/.local/lib/python3.12/site-packages/airflow/operators/bash.py", line 276, in execute
    raise AirflowException(
airflow.exceptions.AirflowException: Bash command failed. The command returned a non-zero exit code 1.
[2025-03-08T18:58:34.264+0000] {logging_mixin.py:190} INFO - Task instance in failure state
[2025-03-08T18:58:34.265+0000] {logging_mixin.py:190} INFO - Task start:2025-03-08 18:58:31.507291+00:00 end:2025-03-08 18:58:34.263954+00:00 duration:2.756663
[2025-03-08T18:58:34.265+0000] {logging_mixin.py:190} INFO - Task:<Task(BashOperator): task_etl_fire_incident_using_bash> dag:<DAG: etl_fire_incidents_dag> dagrun:<DagRun etl_fire_incidents_dag @ 2025-03-08 15:00:00+00:00: scheduled__2025-03-08T15:00:00+00:00, state:running, queued_at: 2025-03-08 18:58:29.747912+00:00. externally triggered: False>
[2025-03-08T18:58:34.265+0000] {logging_mixin.py:190} INFO - Failure caused by Bash command failed. The command returned a non-zero exit code 1.
[2025-03-08T18:58:34.266+0000] {taskinstance.py:1226} INFO - Marking task as UP_FOR_RETRY. dag_id=etl_fire_incidents_dag, task_id=task_etl_fire_incident_using_bash, run_id=scheduled__2025-03-08T15:00:00+00:00, execution_date=20250308T150000, start_date=20250308T185831, end_date=20250308T185834
[2025-03-08T18:58:34.301+0000] {taskinstance.py:341} INFO - ::group::Post task execution logs
[2025-03-08T18:58:34.301+0000] {standard_task_runner.py:124} ERROR - Failed to execute job 473 for task task_etl_fire_incident_using_bash (Bash command failed. The command returned a non-zero exit code 1.; 1038)
Traceback (most recent call last):
  File "/home/airflow/.local/lib/python3.12/site-packages/airflow/task/task_runner/standard_task_runner.py", line 117, in _start_by_fork
    ret = args.func(args, dag=self.dag)
          ^^^^^^^^^^^^^^^^^^^^^^^^^^^^^
  File "/home/airflow/.local/lib/python3.12/site-packages/airflow/cli/cli_config.py", line 49, in command
    return func(*args, **kwargs)
           ^^^^^^^^^^^^^^^^^^^^^
  File "/home/airflow/.local/lib/python3.12/site-packages/airflow/utils/cli.py", line 116, in wrapper
    return f(*args, **kwargs)
           ^^^^^^^^^^^^^^^^^^
  File "/home/airflow/.local/lib/python3.12/site-packages/airflow/cli/commands/task_command.py", line 483, in task_run
    task_return_code = _run_task_by_selected_method(args, _dag, ti)
                       ^^^^^^^^^^^^^^^^^^^^^^^^^^^^^^^^^^^^^^^^^^^^
  File "/home/airflow/.local/lib/python3.12/site-packages/airflow/cli/commands/task_command.py", line 256, in _run_task_by_selected_method
    return _run_raw_task(args, ti)
           ^^^^^^^^^^^^^^^^^^^^^^^
  File "/home/airflow/.local/lib/python3.12/site-packages/airflow/cli/commands/task_command.py", line 341, in _run_raw_task
    return ti._run_raw_task(
           ^^^^^^^^^^^^^^^^^
  File "/home/airflow/.local/lib/python3.12/site-packages/airflow/utils/session.py", line 97, in wrapper
    return func(*args, session=session, **kwargs)
           ^^^^^^^^^^^^^^^^^^^^^^^^^^^^^^^^^^^^^^
  File "/home/airflow/.local/lib/python3.12/site-packages/airflow/models/taskinstance.py", line 3006, in _run_raw_task
    return _run_raw_task(
           ^^^^^^^^^^^^^^
  File "/home/airflow/.local/lib/python3.12/site-packages/airflow/models/taskinstance.py", line 274, in _run_raw_task
    TaskInstance._execute_task_with_callbacks(
  File "/home/airflow/.local/lib/python3.12/site-packages/airflow/models/taskinstance.py", line 3161, in _execute_task_with_callbacks
    result = self._execute_task(context, task_orig)
             ^^^^^^^^^^^^^^^^^^^^^^^^^^^^^^^^^^^^^^
  File "/home/airflow/.local/lib/python3.12/site-packages/airflow/models/taskinstance.py", line 3185, in _execute_task
    return _execute_task(self, context, task_orig)
           ^^^^^^^^^^^^^^^^^^^^^^^^^^^^^^^^^^^^^^^
  File "/home/airflow/.local/lib/python3.12/site-packages/airflow/models/taskinstance.py", line 768, in _execute_task
    result = _execute_callable(context=context, **execute_callable_kwargs)
             ^^^^^^^^^^^^^^^^^^^^^^^^^^^^^^^^^^^^^^^^^^^^^^^^^^^^^^^^^^^^^
  File "/home/airflow/.local/lib/python3.12/site-packages/airflow/models/taskinstance.py", line 734, in _execute_callable
    return ExecutionCallableRunner(
           ^^^^^^^^^^^^^^^^^^^^^^^^
  File "/home/airflow/.local/lib/python3.12/site-packages/airflow/utils/operator_helpers.py", line 252, in run
    return self.func(*args, **kwargs)
           ^^^^^^^^^^^^^^^^^^^^^^^^^^
  File "/home/airflow/.local/lib/python3.12/site-packages/airflow/models/baseoperator.py", line 424, in wrapper
    return func(self, *args, **kwargs)
           ^^^^^^^^^^^^^^^^^^^^^^^^^^^
  File "/home/airflow/.local/lib/python3.12/site-packages/airflow/operators/bash.py", line 276, in execute
    raise AirflowException(
airflow.exceptions.AirflowException: Bash command failed. The command returned a non-zero exit code 1.
[2025-03-08T18:58:34.329+0000] {local_task_job_runner.py:266} INFO - Task exited with return code 1
[2025-03-08T18:58:34.346+0000] {taskinstance.py:3901} INFO - 0 downstream tasks scheduled from follow-on schedule check
[2025-03-08T18:58:34.348+0000] {local_task_job_runner.py:245} INFO - ::endgroup::
