[2025-03-04T23:13:11.576+0000] {local_task_job_runner.py:123} INFO - ::group::Pre task execution logs
[2025-03-04T23:13:11.588+0000] {taskinstance.py:2614} INFO - Dependencies all met for dep_context=non-requeueable deps ti=<TaskInstance: task_etl_fire_incident_using_bash.task_etl_fire_incident_using_bash manual__2025-03-04T23:13:09.525799+00:00 [queued]>
[2025-03-04T23:13:11.594+0000] {taskinstance.py:2614} INFO - Dependencies all met for dep_context=requeueable deps ti=<TaskInstance: task_etl_fire_incident_using_bash.task_etl_fire_incident_using_bash manual__2025-03-04T23:13:09.525799+00:00 [queued]>
[2025-03-04T23:13:11.594+0000] {taskinstance.py:2867} INFO - Starting attempt 1 of 2
[2025-03-04T23:13:11.733+0000] {taskinstance.py:2890} INFO - Executing <Task(BashOperator): task_etl_fire_incident_using_bash> on 2025-03-04 23:13:09.525799+00:00
[2025-03-04T23:13:11.738+0000] {warnings.py:112} WARNING - /home/***/.local/lib/python3.12/site-packages/***/task/task_runner/standard_task_runner.py:70: DeprecationWarning: This process (pid=326) is multi-threaded, use of fork() may lead to deadlocks in the child.
  pid = os.fork()

[2025-03-04T23:13:11.739+0000] {standard_task_runner.py:72} INFO - Started process 328 to run task
[2025-03-04T23:13:11.740+0000] {standard_task_runner.py:104} INFO - Running: ['***', 'tasks', 'run', 'task_etl_fire_incident_using_bash', 'task_etl_fire_incident_using_bash', 'manual__2025-03-04T23:13:09.525799+00:00', '--job-id', '165', '--raw', '--subdir', 'DAGS_FOLDER/fire_incidents_dag.py', '--cfg-path', '/tmp/tmpybylb_sf']
[2025-03-04T23:13:11.741+0000] {standard_task_runner.py:105} INFO - Job 165: Subtask task_etl_fire_incident_using_bash
[2025-03-04T23:13:11.780+0000] {task_command.py:467} INFO - Running <TaskInstance: task_etl_fire_incident_using_bash.task_etl_fire_incident_using_bash manual__2025-03-04T23:13:09.525799+00:00 [running]> on host b76212952943
[2025-03-04T23:13:11.845+0000] {taskinstance.py:3134} INFO - Exporting env vars: AIRFLOW_CTX_DAG_EMAIL='***@***.com' AIRFLOW_CTX_DAG_OWNER='***' AIRFLOW_CTX_DAG_ID='task_etl_fire_incident_using_bash' AIRFLOW_CTX_TASK_ID='task_etl_fire_incident_using_bash' AIRFLOW_CTX_EXECUTION_DATE='2025-03-04T23:13:09.525799+00:00' AIRFLOW_CTX_TRY_NUMBER='1' AIRFLOW_CTX_DAG_RUN_ID='manual__2025-03-04T23:13:09.525799+00:00'
[2025-03-04T23:13:11.846+0000] {logging_mixin.py:190} INFO - Task instance is in running state
[2025-03-04T23:13:11.847+0000] {logging_mixin.py:190} INFO -  Previous state of the Task instance: queued
[2025-03-04T23:13:11.847+0000] {logging_mixin.py:190} INFO - Current task name:task_etl_fire_incident_using_bash state:running start_date:2025-03-04 23:13:11.589277+00:00
[2025-03-04T23:13:11.847+0000] {logging_mixin.py:190} INFO - Dag name:task_etl_fire_incident_using_bash and current dag run status:running
[2025-03-04T23:13:11.847+0000] {taskinstance.py:732} INFO - ::endgroup::
[2025-03-04T23:13:11.848+0000] {subprocess.py:78} INFO - Tmp dir root location: /tmp
[2025-03-04T23:13:11.849+0000] {subprocess.py:88} INFO - Running command: ['/usr/bin/bash', '-c', 'docker run --rm --network=pg-network-fire-incidents nyc_fire_incidents:v001 --api_url=data.cityofnewyork.us --token=xoIfIdDlHq6gGzxqLqbUeMpsG --dataset_id=8m42-w767 --limit_rows=10000 --username=root --password=root --host_name=fire_incidents_db_container --port=5432 --database=fire_incidents_db --tbl_name=fire_incidents_tbl']
[2025-03-04T23:13:11.861+0000] {subprocess.py:99} INFO - Output:
[2025-03-04T23:13:11.883+0000] {subprocess.py:106} INFO - docker: Cannot connect to the Docker daemon at unix:///var/run/docker.sock. Is the docker daemon running?.
[2025-03-04T23:13:11.884+0000] {subprocess.py:106} INFO - See 'docker run --help'.
[2025-03-04T23:13:11.884+0000] {subprocess.py:110} INFO - Command exited with return code 125
[2025-03-04T23:13:11.897+0000] {taskinstance.py:3313} ERROR - Task failed with exception
Traceback (most recent call last):
  File "/home/airflow/.local/lib/python3.12/site-packages/airflow/models/taskinstance.py", line 768, in _execute_task
    result = _execute_callable(context=context, **execute_callable_kwargs)
             ^^^^^^^^^^^^^^^^^^^^^^^^^^^^^^^^^^^^^^^^^^^^^^^^^^^^^^^^^^^^^
  File "/home/airflow/.local/lib/python3.12/site-packages/airflow/models/taskinstance.py", line 734, in _execute_callable
    return ExecutionCallableRunner(
           ^^^^^^^^^^^^^^^^^^^^^^^^
  File "/home/airflow/.local/lib/python3.12/site-packages/airflow/utils/operator_helpers.py", line 252, in run
    return self.func(*args, **kwargs)
           ^^^^^^^^^^^^^^^^^^^^^^^^^^
  File "/home/airflow/.local/lib/python3.12/site-packages/airflow/models/baseoperator.py", line 424, in wrapper
    return func(self, *args, **kwargs)
           ^^^^^^^^^^^^^^^^^^^^^^^^^^^
  File "/home/airflow/.local/lib/python3.12/site-packages/airflow/operators/bash.py", line 276, in execute
    raise AirflowException(
airflow.exceptions.AirflowException: Bash command failed. The command returned a non-zero exit code 125.
[2025-03-04T23:13:11.907+0000] {logging_mixin.py:190} INFO - Task instance in failure state
[2025-03-04T23:13:11.907+0000] {logging_mixin.py:190} INFO - Task start:2025-03-04 23:13:11.589277+00:00 end:2025-03-04 23:13:11.906756+00:00 duration:0.317479
[2025-03-04T23:13:11.908+0000] {logging_mixin.py:190} INFO - Task:<Task(BashOperator): task_etl_fire_incident_using_bash> dag:<DAG: task_etl_fire_incident_using_bash> dagrun:<DagRun task_etl_fire_incident_using_bash @ 2025-03-04 23:13:09.525799+00:00: manual__2025-03-04T23:13:09.525799+00:00, state:running, queued_at: 2025-03-04 23:13:09.554294+00:00. externally triggered: True>
[2025-03-04T23:13:11.908+0000] {logging_mixin.py:190} INFO - Failure caused by Bash command failed. The command returned a non-zero exit code 125.
[2025-03-04T23:13:11.909+0000] {taskinstance.py:1226} INFO - Marking task as UP_FOR_RETRY. dag_id=task_etl_fire_incident_using_bash, task_id=task_etl_fire_incident_using_bash, run_id=manual__2025-03-04T23:13:09.525799+00:00, execution_date=20250304T231309, start_date=20250304T231311, end_date=20250304T231311
[2025-03-04T23:13:11.935+0000] {taskinstance.py:341} INFO - ::group::Post task execution logs
[2025-03-04T23:13:11.935+0000] {standard_task_runner.py:124} ERROR - Failed to execute job 165 for task task_etl_fire_incident_using_bash (Bash command failed. The command returned a non-zero exit code 125.; 328)
Traceback (most recent call last):
  File "/home/airflow/.local/lib/python3.12/site-packages/airflow/task/task_runner/standard_task_runner.py", line 117, in _start_by_fork
    ret = args.func(args, dag=self.dag)
          ^^^^^^^^^^^^^^^^^^^^^^^^^^^^^
  File "/home/airflow/.local/lib/python3.12/site-packages/airflow/cli/cli_config.py", line 49, in command
    return func(*args, **kwargs)
           ^^^^^^^^^^^^^^^^^^^^^
  File "/home/airflow/.local/lib/python3.12/site-packages/airflow/utils/cli.py", line 116, in wrapper
    return f(*args, **kwargs)
           ^^^^^^^^^^^^^^^^^^
  File "/home/airflow/.local/lib/python3.12/site-packages/airflow/cli/commands/task_command.py", line 483, in task_run
    task_return_code = _run_task_by_selected_method(args, _dag, ti)
                       ^^^^^^^^^^^^^^^^^^^^^^^^^^^^^^^^^^^^^^^^^^^^
  File "/home/airflow/.local/lib/python3.12/site-packages/airflow/cli/commands/task_command.py", line 256, in _run_task_by_selected_method
    return _run_raw_task(args, ti)
           ^^^^^^^^^^^^^^^^^^^^^^^
  File "/home/airflow/.local/lib/python3.12/site-packages/airflow/cli/commands/task_command.py", line 341, in _run_raw_task
    return ti._run_raw_task(
           ^^^^^^^^^^^^^^^^^
  File "/home/airflow/.local/lib/python3.12/site-packages/airflow/utils/session.py", line 97, in wrapper
    return func(*args, session=session, **kwargs)
           ^^^^^^^^^^^^^^^^^^^^^^^^^^^^^^^^^^^^^^
  File "/home/airflow/.local/lib/python3.12/site-packages/airflow/models/taskinstance.py", line 3006, in _run_raw_task
    return _run_raw_task(
           ^^^^^^^^^^^^^^
  File "/home/airflow/.local/lib/python3.12/site-packages/airflow/models/taskinstance.py", line 274, in _run_raw_task
    TaskInstance._execute_task_with_callbacks(
  File "/home/airflow/.local/lib/python3.12/site-packages/airflow/models/taskinstance.py", line 3161, in _execute_task_with_callbacks
    result = self._execute_task(context, task_orig)
             ^^^^^^^^^^^^^^^^^^^^^^^^^^^^^^^^^^^^^^
  File "/home/airflow/.local/lib/python3.12/site-packages/airflow/models/taskinstance.py", line 3185, in _execute_task
    return _execute_task(self, context, task_orig)
           ^^^^^^^^^^^^^^^^^^^^^^^^^^^^^^^^^^^^^^^
  File "/home/airflow/.local/lib/python3.12/site-packages/airflow/models/taskinstance.py", line 768, in _execute_task
    result = _execute_callable(context=context, **execute_callable_kwargs)
             ^^^^^^^^^^^^^^^^^^^^^^^^^^^^^^^^^^^^^^^^^^^^^^^^^^^^^^^^^^^^^
  File "/home/airflow/.local/lib/python3.12/site-packages/airflow/models/taskinstance.py", line 734, in _execute_callable
    return ExecutionCallableRunner(
           ^^^^^^^^^^^^^^^^^^^^^^^^
  File "/home/airflow/.local/lib/python3.12/site-packages/airflow/utils/operator_helpers.py", line 252, in run
    return self.func(*args, **kwargs)
           ^^^^^^^^^^^^^^^^^^^^^^^^^^
  File "/home/airflow/.local/lib/python3.12/site-packages/airflow/models/baseoperator.py", line 424, in wrapper
    return func(self, *args, **kwargs)
           ^^^^^^^^^^^^^^^^^^^^^^^^^^^
  File "/home/airflow/.local/lib/python3.12/site-packages/airflow/operators/bash.py", line 276, in execute
    raise AirflowException(
airflow.exceptions.AirflowException: Bash command failed. The command returned a non-zero exit code 125.
[2025-03-04T23:13:11.954+0000] {local_task_job_runner.py:266} INFO - Task exited with return code 1
[2025-03-04T23:13:11.976+0000] {taskinstance.py:3901} INFO - 0 downstream tasks scheduled from follow-on schedule check
[2025-03-04T23:13:11.978+0000] {local_task_job_runner.py:245} INFO - ::endgroup::
