[2025-03-08T16:57:37.122+0000] {local_task_job_runner.py:123} INFO - ::group::Pre task execution logs
[2025-03-08T16:57:37.136+0000] {taskinstance.py:2614} INFO - Dependencies all met for dep_context=non-requeueable deps ti=<TaskInstance: etl_fire_incidents_dag.task_etl_fire_incident_using_bash manual__2025-03-08T16:51:34.538083+00:00 [queued]>
[2025-03-08T16:57:37.142+0000] {taskinstance.py:2614} INFO - Dependencies all met for dep_context=requeueable deps ti=<TaskInstance: etl_fire_incidents_dag.task_etl_fire_incident_using_bash manual__2025-03-08T16:51:34.538083+00:00 [queued]>
[2025-03-08T16:57:37.142+0000] {taskinstance.py:2867} INFO - Starting attempt 2 of 2
[2025-03-08T16:57:37.158+0000] {taskinstance.py:2890} INFO - Executing <Task(BashOperator): task_etl_fire_incident_using_bash> on 2025-03-08 16:51:34.538083+00:00
[2025-03-08T16:57:37.164+0000] {warnings.py:112} WARNING - /home/***/.local/lib/python3.12/site-packages/***/task/task_runner/standard_task_runner.py:70: DeprecationWarning: This process (pid=230) is multi-threaded, use of fork() may lead to deadlocks in the child.
  pid = os.fork()

[2025-03-08T16:57:37.166+0000] {standard_task_runner.py:72} INFO - Started process 232 to run task
[2025-03-08T16:57:37.166+0000] {standard_task_runner.py:104} INFO - Running: ['***', 'tasks', 'run', 'etl_fire_incidents_dag', 'task_etl_fire_incident_using_bash', 'manual__2025-03-08T16:51:34.538083+00:00', '--job-id', '360', '--raw', '--subdir', 'DAGS_FOLDER/fire_incidents_dag.py', '--cfg-path', '/tmp/tmp98gx8tak']
[2025-03-08T16:57:37.167+0000] {standard_task_runner.py:105} INFO - Job 360: Subtask task_etl_fire_incident_using_bash
[2025-03-08T16:57:37.201+0000] {task_command.py:467} INFO - Running <TaskInstance: etl_fire_incidents_dag.task_etl_fire_incident_using_bash manual__2025-03-08T16:51:34.538083+00:00 [running]> on host 79bdbab86acf
[2025-03-08T16:57:37.267+0000] {taskinstance.py:3134} INFO - Exporting env vars: AIRFLOW_CTX_DAG_EMAIL='***@***.com' AIRFLOW_CTX_DAG_OWNER='***' AIRFLOW_CTX_DAG_ID='etl_fire_incidents_dag' AIRFLOW_CTX_TASK_ID='task_etl_fire_incident_using_bash' AIRFLOW_CTX_EXECUTION_DATE='2025-03-08T16:51:34.538083+00:00' AIRFLOW_CTX_TRY_NUMBER='2' AIRFLOW_CTX_DAG_RUN_ID='manual__2025-03-08T16:51:34.538083+00:00'
[2025-03-08T16:57:37.268+0000] {logging_mixin.py:190} INFO - Task instance is in running state
[2025-03-08T16:57:37.269+0000] {logging_mixin.py:190} INFO -  Previous state of the Task instance: queued
[2025-03-08T16:57:37.269+0000] {logging_mixin.py:190} INFO - Current task name:task_etl_fire_incident_using_bash state:running start_date:2025-03-08 16:57:37.136730+00:00
[2025-03-08T16:57:37.269+0000] {logging_mixin.py:190} INFO - Dag name:etl_fire_incidents_dag and current dag run status:running
[2025-03-08T16:57:37.269+0000] {taskinstance.py:732} INFO - ::endgroup::
[2025-03-08T16:57:37.270+0000] {subprocess.py:78} INFO - Tmp dir root location: /tmp
[2025-03-08T16:57:37.270+0000] {subprocess.py:88} INFO - Running command: ['/usr/bin/bash', '-c', 'docker run --rm \\--network=pg-network-fire-incidents \\nyc_fire_incidents:v001 \\--api_url=data.cityofnewyork.us \\--token=xoIfIdDlHq6gGzxqLqbUeMpsG \\--dataset_id=8m42-w767 \\--limit_rows=10000 \\--username=root \\--password=root \\--host_name=fire_incidents_db_container \\--port=5432 \\--database=fire_incidents_db \\--tbl_name=fire_incidents_tbl']
[2025-03-08T16:57:37.281+0000] {subprocess.py:99} INFO - Output:
[2025-03-08T16:57:38.522+0000] {subprocess.py:106} INFO - Traceback (most recent call last):
[2025-03-08T16:57:38.523+0000] {subprocess.py:106} INFO -   File "/app/pull_fire_incidents.py", line 22, in <module>
[2025-03-08T16:57:38.524+0000] {subprocess.py:106} INFO -     from ***.models import TaskInstance
[2025-03-08T16:57:38.524+0000] {subprocess.py:106} INFO - ModuleNotFoundError: No module named '***'
[2025-03-08T16:57:39.036+0000] {subprocess.py:110} INFO - Command exited with return code 1
[2025-03-08T16:57:39.047+0000] {taskinstance.py:3313} ERROR - Task failed with exception
Traceback (most recent call last):
  File "/home/airflow/.local/lib/python3.12/site-packages/airflow/models/taskinstance.py", line 768, in _execute_task
    result = _execute_callable(context=context, **execute_callable_kwargs)
             ^^^^^^^^^^^^^^^^^^^^^^^^^^^^^^^^^^^^^^^^^^^^^^^^^^^^^^^^^^^^^
  File "/home/airflow/.local/lib/python3.12/site-packages/airflow/models/taskinstance.py", line 734, in _execute_callable
    return ExecutionCallableRunner(
           ^^^^^^^^^^^^^^^^^^^^^^^^
  File "/home/airflow/.local/lib/python3.12/site-packages/airflow/utils/operator_helpers.py", line 252, in run
    return self.func(*args, **kwargs)
           ^^^^^^^^^^^^^^^^^^^^^^^^^^
  File "/home/airflow/.local/lib/python3.12/site-packages/airflow/models/baseoperator.py", line 424, in wrapper
    return func(self, *args, **kwargs)
           ^^^^^^^^^^^^^^^^^^^^^^^^^^^
  File "/home/airflow/.local/lib/python3.12/site-packages/airflow/operators/bash.py", line 276, in execute
    raise AirflowException(
airflow.exceptions.AirflowException: Bash command failed. The command returned a non-zero exit code 1.
[2025-03-08T16:57:39.050+0000] {logging_mixin.py:190} INFO - Task instance in failure state
[2025-03-08T16:57:39.050+0000] {logging_mixin.py:190} INFO - Task start:2025-03-08 16:57:37.136730+00:00 end:2025-03-08 16:57:39.050029+00:00 duration:1.913299
[2025-03-08T16:57:39.051+0000] {logging_mixin.py:190} INFO - Task:<Task(BashOperator): task_etl_fire_incident_using_bash> dag:<DAG: etl_fire_incidents_dag> dagrun:<DagRun etl_fire_incidents_dag @ 2025-03-08 16:51:34.538083+00:00: manual__2025-03-08T16:51:34.538083+00:00, state:running, queued_at: 2025-03-08 16:51:34.615748+00:00. externally triggered: True>
[2025-03-08T16:57:39.051+0000] {logging_mixin.py:190} INFO - Failure caused by Bash command failed. The command returned a non-zero exit code 1.
[2025-03-08T16:57:39.051+0000] {taskinstance.py:1226} INFO - Marking task as FAILED. dag_id=etl_fire_incidents_dag, task_id=task_etl_fire_incident_using_bash, run_id=manual__2025-03-08T16:51:34.538083+00:00, execution_date=20250308T165134, start_date=20250308T165737, end_date=20250308T165739
[2025-03-08T16:57:39.076+0000] {taskinstance.py:341} INFO - ::group::Post task execution logs
[2025-03-08T16:57:39.077+0000] {standard_task_runner.py:124} ERROR - Failed to execute job 360 for task task_etl_fire_incident_using_bash (Bash command failed. The command returned a non-zero exit code 1.; 232)
Traceback (most recent call last):
  File "/home/airflow/.local/lib/python3.12/site-packages/airflow/task/task_runner/standard_task_runner.py", line 117, in _start_by_fork
    ret = args.func(args, dag=self.dag)
          ^^^^^^^^^^^^^^^^^^^^^^^^^^^^^
  File "/home/airflow/.local/lib/python3.12/site-packages/airflow/cli/cli_config.py", line 49, in command
    return func(*args, **kwargs)
           ^^^^^^^^^^^^^^^^^^^^^
  File "/home/airflow/.local/lib/python3.12/site-packages/airflow/utils/cli.py", line 116, in wrapper
    return f(*args, **kwargs)
           ^^^^^^^^^^^^^^^^^^
  File "/home/airflow/.local/lib/python3.12/site-packages/airflow/cli/commands/task_command.py", line 483, in task_run
    task_return_code = _run_task_by_selected_method(args, _dag, ti)
                       ^^^^^^^^^^^^^^^^^^^^^^^^^^^^^^^^^^^^^^^^^^^^
  File "/home/airflow/.local/lib/python3.12/site-packages/airflow/cli/commands/task_command.py", line 256, in _run_task_by_selected_method
    return _run_raw_task(args, ti)
           ^^^^^^^^^^^^^^^^^^^^^^^
  File "/home/airflow/.local/lib/python3.12/site-packages/airflow/cli/commands/task_command.py", line 341, in _run_raw_task
    return ti._run_raw_task(
           ^^^^^^^^^^^^^^^^^
  File "/home/airflow/.local/lib/python3.12/site-packages/airflow/utils/session.py", line 97, in wrapper
    return func(*args, session=session, **kwargs)
           ^^^^^^^^^^^^^^^^^^^^^^^^^^^^^^^^^^^^^^
  File "/home/airflow/.local/lib/python3.12/site-packages/airflow/models/taskinstance.py", line 3006, in _run_raw_task
    return _run_raw_task(
           ^^^^^^^^^^^^^^
  File "/home/airflow/.local/lib/python3.12/site-packages/airflow/models/taskinstance.py", line 274, in _run_raw_task
    TaskInstance._execute_task_with_callbacks(
  File "/home/airflow/.local/lib/python3.12/site-packages/airflow/models/taskinstance.py", line 3161, in _execute_task_with_callbacks
    result = self._execute_task(context, task_orig)
             ^^^^^^^^^^^^^^^^^^^^^^^^^^^^^^^^^^^^^^
  File "/home/airflow/.local/lib/python3.12/site-packages/airflow/models/taskinstance.py", line 3185, in _execute_task
    return _execute_task(self, context, task_orig)
           ^^^^^^^^^^^^^^^^^^^^^^^^^^^^^^^^^^^^^^^
  File "/home/airflow/.local/lib/python3.12/site-packages/airflow/models/taskinstance.py", line 768, in _execute_task
    result = _execute_callable(context=context, **execute_callable_kwargs)
             ^^^^^^^^^^^^^^^^^^^^^^^^^^^^^^^^^^^^^^^^^^^^^^^^^^^^^^^^^^^^^
  File "/home/airflow/.local/lib/python3.12/site-packages/airflow/models/taskinstance.py", line 734, in _execute_callable
    return ExecutionCallableRunner(
           ^^^^^^^^^^^^^^^^^^^^^^^^
  File "/home/airflow/.local/lib/python3.12/site-packages/airflow/utils/operator_helpers.py", line 252, in run
    return self.func(*args, **kwargs)
           ^^^^^^^^^^^^^^^^^^^^^^^^^^
  File "/home/airflow/.local/lib/python3.12/site-packages/airflow/models/baseoperator.py", line 424, in wrapper
    return func(self, *args, **kwargs)
           ^^^^^^^^^^^^^^^^^^^^^^^^^^^
  File "/home/airflow/.local/lib/python3.12/site-packages/airflow/operators/bash.py", line 276, in execute
    raise AirflowException(
airflow.exceptions.AirflowException: Bash command failed. The command returned a non-zero exit code 1.
[2025-03-08T16:57:39.106+0000] {local_task_job_runner.py:266} INFO - Task exited with return code 1
[2025-03-08T16:57:39.131+0000] {taskinstance.py:3901} INFO - 0 downstream tasks scheduled from follow-on schedule check
[2025-03-08T16:57:39.140+0000] {local_task_job_runner.py:245} INFO - ::endgroup::
