[2025-03-08T18:52:58.704+0000] {local_task_job_runner.py:123} INFO - ::group::Pre task execution logs
[2025-03-08T18:52:58.717+0000] {taskinstance.py:2614} INFO - Dependencies all met for dep_context=non-requeueable deps ti=<TaskInstance: etl_fire_incidents_dag.task_etl_fire_incident_using_bash manual__2025-03-08T18:52:45.254054+00:00 [queued]>
[2025-03-08T18:52:58.722+0000] {taskinstance.py:2614} INFO - Dependencies all met for dep_context=requeueable deps ti=<TaskInstance: etl_fire_incidents_dag.task_etl_fire_incident_using_bash manual__2025-03-08T18:52:45.254054+00:00 [queued]>
[2025-03-08T18:52:58.723+0000] {taskinstance.py:2867} INFO - Starting attempt 1 of 2
[2025-03-08T18:52:58.739+0000] {taskinstance.py:2890} INFO - Executing <Task(BashOperator): task_etl_fire_incident_using_bash> on 2025-03-08 18:52:45.254054+00:00
[2025-03-08T18:52:58.748+0000] {warnings.py:112} WARNING - /home/***/.local/lib/python3.12/site-packages/***/task/task_runner/standard_task_runner.py:70: DeprecationWarning: This process (pid=910) is multi-threaded, use of fork() may lead to deadlocks in the child.
  pid = os.fork()

[2025-03-08T18:52:58.749+0000] {standard_task_runner.py:72} INFO - Started process 912 to run task
[2025-03-08T18:52:58.750+0000] {standard_task_runner.py:104} INFO - Running: ['***', 'tasks', 'run', 'etl_fire_incidents_dag', 'task_etl_fire_incident_using_bash', 'manual__2025-03-08T18:52:45.254054+00:00', '--job-id', '470', '--raw', '--subdir', 'DAGS_FOLDER/fire_incidents_dag.py', '--cfg-path', '/tmp/tmpa2_z89oq']
[2025-03-08T18:52:58.750+0000] {standard_task_runner.py:105} INFO - Job 470: Subtask task_etl_fire_incident_using_bash
[2025-03-08T18:52:58.785+0000] {task_command.py:467} INFO - Running <TaskInstance: etl_fire_incidents_dag.task_etl_fire_incident_using_bash manual__2025-03-08T18:52:45.254054+00:00 [running]> on host fad361e322ea
[2025-03-08T18:52:58.857+0000] {taskinstance.py:3134} INFO - Exporting env vars: AIRFLOW_CTX_DAG_EMAIL='***@***.com' AIRFLOW_CTX_DAG_OWNER='***' AIRFLOW_CTX_DAG_ID='etl_fire_incidents_dag' AIRFLOW_CTX_TASK_ID='task_etl_fire_incident_using_bash' AIRFLOW_CTX_EXECUTION_DATE='2025-03-08T18:52:45.254054+00:00' AIRFLOW_CTX_TRY_NUMBER='1' AIRFLOW_CTX_DAG_RUN_ID='manual__2025-03-08T18:52:45.254054+00:00'
[2025-03-08T18:52:58.859+0000] {logging_mixin.py:190} INFO - Task instance is in running state
[2025-03-08T18:52:58.859+0000] {logging_mixin.py:190} INFO -  Previous state of the Task instance: queued
[2025-03-08T18:52:58.860+0000] {logging_mixin.py:190} INFO - Current task name:task_etl_fire_incident_using_bash state:running start_date:2025-03-08 18:52:58.718073+00:00
[2025-03-08T18:52:58.860+0000] {logging_mixin.py:190} INFO - Dag name:etl_fire_incidents_dag and current dag run status:running
[2025-03-08T18:52:58.860+0000] {taskinstance.py:732} INFO - ::endgroup::
[2025-03-08T18:52:58.861+0000] {subprocess.py:78} INFO - Tmp dir root location: /tmp
[2025-03-08T18:52:58.872+0000] {subprocess.py:88} INFO - Running command: ['/usr/bin/bash', '-c', 'docker run --rm \\--network=pg-network-fire-incidents \\nyc_fire_incidents:v001 \\--api_url=data.cityofnewyork.us \\--token=xoIfIdDlHq6gGzxqLqbUeMpsG \\--dataset_id=8m42-w767 \\--limit_rows=10000 \\--username=root \\--password=root \\--host_name=fire_incidents_db_container \\--port=5432 \\--database=fire_incidents_db \\--tbl_name=fire_incidents_tbl']
[2025-03-08T18:52:58.884+0000] {subprocess.py:99} INFO - Output:
[2025-03-08T18:53:00.416+0000] {subprocess.py:106} INFO - /app/pull_fire_incidents.py:23 DeprecationWarning: The `***.operators.python_operator.PythonOperator` class is deprecated. Please use `'***.operators.python.PythonOperator'`.
[2025-03-08T18:53:00.716+0000] {subprocess.py:106} INFO - Traceback (most recent call last):
[2025-03-08T18:53:00.716+0000] {subprocess.py:106} INFO -   File "/app/pull_fire_incidents.py", line 74, in <module>
[2025-03-08T18:53:00.716+0000] {subprocess.py:106} INFO -     bash_function(args)
[2025-03-08T18:53:00.717+0000] {subprocess.py:106} INFO -   File "/app/pull_fire_incidents.py", line 70, in bash_function
[2025-03-08T18:53:00.717+0000] {subprocess.py:106} INFO -     task_instance = kwargs['ti']
[2025-03-08T18:53:00.717+0000] {subprocess.py:106} INFO - KeyError: 'ti'
[2025-03-08T18:53:01.319+0000] {subprocess.py:110} INFO - Command exited with return code 1
[2025-03-08T18:53:01.333+0000] {taskinstance.py:3313} ERROR - Task failed with exception
Traceback (most recent call last):
  File "/home/airflow/.local/lib/python3.12/site-packages/airflow/models/taskinstance.py", line 768, in _execute_task
    result = _execute_callable(context=context, **execute_callable_kwargs)
             ^^^^^^^^^^^^^^^^^^^^^^^^^^^^^^^^^^^^^^^^^^^^^^^^^^^^^^^^^^^^^
  File "/home/airflow/.local/lib/python3.12/site-packages/airflow/models/taskinstance.py", line 734, in _execute_callable
    return ExecutionCallableRunner(
           ^^^^^^^^^^^^^^^^^^^^^^^^
  File "/home/airflow/.local/lib/python3.12/site-packages/airflow/utils/operator_helpers.py", line 252, in run
    return self.func(*args, **kwargs)
           ^^^^^^^^^^^^^^^^^^^^^^^^^^
  File "/home/airflow/.local/lib/python3.12/site-packages/airflow/models/baseoperator.py", line 424, in wrapper
    return func(self, *args, **kwargs)
           ^^^^^^^^^^^^^^^^^^^^^^^^^^^
  File "/home/airflow/.local/lib/python3.12/site-packages/airflow/operators/bash.py", line 276, in execute
    raise AirflowException(
airflow.exceptions.AirflowException: Bash command failed. The command returned a non-zero exit code 1.
[2025-03-08T18:53:01.337+0000] {logging_mixin.py:190} INFO - Task instance in failure state
[2025-03-08T18:53:01.338+0000] {logging_mixin.py:190} INFO - Task start:2025-03-08 18:52:58.718073+00:00 end:2025-03-08 18:53:01.337079+00:00 duration:2.619006
[2025-03-08T18:53:01.338+0000] {logging_mixin.py:190} INFO - Task:<Task(BashOperator): task_etl_fire_incident_using_bash> dag:<DAG: etl_fire_incidents_dag> dagrun:<DagRun etl_fire_incidents_dag @ 2025-03-08 18:52:45.254054+00:00: manual__2025-03-08T18:52:45.254054+00:00, state:running, queued_at: 2025-03-08 18:52:45.265347+00:00. externally triggered: True>
[2025-03-08T18:53:01.338+0000] {logging_mixin.py:190} INFO - Failure caused by Bash command failed. The command returned a non-zero exit code 1.
[2025-03-08T18:53:01.338+0000] {taskinstance.py:1226} INFO - Marking task as UP_FOR_RETRY. dag_id=etl_fire_incidents_dag, task_id=task_etl_fire_incident_using_bash, run_id=manual__2025-03-08T18:52:45.254054+00:00, execution_date=20250308T185245, start_date=20250308T185258, end_date=20250308T185301
[2025-03-08T18:53:01.343+0000] {taskinstance.py:341} INFO - ::group::Post task execution logs
[2025-03-08T18:53:01.344+0000] {standard_task_runner.py:124} ERROR - Failed to execute job 470 for task task_etl_fire_incident_using_bash ((psycopg2.errors.ForeignKeyViolation) insert or update on table "task_fail" violates foreign key constraint "task_fail_ti_fkey"
DETAIL:  Key (dag_id, task_id, run_id, map_index)=(etl_fire_incidents_dag, task_etl_fire_incident_using_bash, manual__2025-03-08T18:52:45.254054+00:00, -1) is not present in table "task_instance".

[SQL: INSERT INTO task_fail (task_id, dag_id, run_id, map_index, start_date, end_date, duration) VALUES (%(task_id)s, %(dag_id)s, %(run_id)s, %(map_index)s, %(start_date)s, %(end_date)s, %(duration)s) RETURNING task_fail.id]
[parameters: {'task_id': 'task_etl_fire_incident_using_bash', 'dag_id': 'etl_fire_incidents_dag', 'run_id': 'manual__2025-03-08T18:52:45.254054+00:00', 'map_index': -1, 'start_date': datetime.datetime(2025, 3, 8, 18, 52, 58, 718073, tzinfo=Timezone('UTC')), 'end_date': datetime.datetime(2025, 3, 8, 18, 53, 1, 337079, tzinfo=Timezone('UTC')), 'duration': 2}]
(Background on this error at: https://sqlalche.me/e/14/gkpj); 912)
Traceback (most recent call last):
  File "/home/airflow/.local/lib/python3.12/site-packages/airflow/models/taskinstance.py", line 274, in _run_raw_task
    TaskInstance._execute_task_with_callbacks(
  File "/home/airflow/.local/lib/python3.12/site-packages/airflow/models/taskinstance.py", line 3161, in _execute_task_with_callbacks
    result = self._execute_task(context, task_orig)
             ^^^^^^^^^^^^^^^^^^^^^^^^^^^^^^^^^^^^^^
  File "/home/airflow/.local/lib/python3.12/site-packages/airflow/models/taskinstance.py", line 3185, in _execute_task
    return _execute_task(self, context, task_orig)
           ^^^^^^^^^^^^^^^^^^^^^^^^^^^^^^^^^^^^^^^
  File "/home/airflow/.local/lib/python3.12/site-packages/airflow/models/taskinstance.py", line 768, in _execute_task
    result = _execute_callable(context=context, **execute_callable_kwargs)
             ^^^^^^^^^^^^^^^^^^^^^^^^^^^^^^^^^^^^^^^^^^^^^^^^^^^^^^^^^^^^^
  File "/home/airflow/.local/lib/python3.12/site-packages/airflow/models/taskinstance.py", line 734, in _execute_callable
    return ExecutionCallableRunner(
           ^^^^^^^^^^^^^^^^^^^^^^^^
  File "/home/airflow/.local/lib/python3.12/site-packages/airflow/utils/operator_helpers.py", line 252, in run
    return self.func(*args, **kwargs)
           ^^^^^^^^^^^^^^^^^^^^^^^^^^
  File "/home/airflow/.local/lib/python3.12/site-packages/airflow/models/baseoperator.py", line 424, in wrapper
    return func(self, *args, **kwargs)
           ^^^^^^^^^^^^^^^^^^^^^^^^^^^
  File "/home/airflow/.local/lib/python3.12/site-packages/airflow/operators/bash.py", line 276, in execute
    raise AirflowException(
airflow.exceptions.AirflowException: Bash command failed. The command returned a non-zero exit code 1.

During handling of the above exception, another exception occurred:

Traceback (most recent call last):
  File "/home/airflow/.local/lib/python3.12/site-packages/sqlalchemy/engine/base.py", line 1910, in _execute_context
    self.dialect.do_execute(
  File "/home/airflow/.local/lib/python3.12/site-packages/sqlalchemy/engine/default.py", line 736, in do_execute
    cursor.execute(statement, parameters)
psycopg2.errors.ForeignKeyViolation: insert or update on table "task_fail" violates foreign key constraint "task_fail_ti_fkey"
DETAIL:  Key (dag_id, task_id, run_id, map_index)=(etl_fire_incidents_dag, task_etl_fire_incident_using_bash, manual__2025-03-08T18:52:45.254054+00:00, -1) is not present in table "task_instance".


The above exception was the direct cause of the following exception:

Traceback (most recent call last):
  File "/home/airflow/.local/lib/python3.12/site-packages/airflow/task/task_runner/standard_task_runner.py", line 117, in _start_by_fork
    ret = args.func(args, dag=self.dag)
          ^^^^^^^^^^^^^^^^^^^^^^^^^^^^^
  File "/home/airflow/.local/lib/python3.12/site-packages/airflow/cli/cli_config.py", line 49, in command
    return func(*args, **kwargs)
           ^^^^^^^^^^^^^^^^^^^^^
  File "/home/airflow/.local/lib/python3.12/site-packages/airflow/utils/cli.py", line 116, in wrapper
    return f(*args, **kwargs)
           ^^^^^^^^^^^^^^^^^^
  File "/home/airflow/.local/lib/python3.12/site-packages/airflow/cli/commands/task_command.py", line 483, in task_run
    task_return_code = _run_task_by_selected_method(args, _dag, ti)
                       ^^^^^^^^^^^^^^^^^^^^^^^^^^^^^^^^^^^^^^^^^^^^
  File "/home/airflow/.local/lib/python3.12/site-packages/airflow/cli/commands/task_command.py", line 256, in _run_task_by_selected_method
    return _run_raw_task(args, ti)
           ^^^^^^^^^^^^^^^^^^^^^^^
  File "/home/airflow/.local/lib/python3.12/site-packages/airflow/cli/commands/task_command.py", line 341, in _run_raw_task
    return ti._run_raw_task(
           ^^^^^^^^^^^^^^^^^
  File "/home/airflow/.local/lib/python3.12/site-packages/airflow/utils/session.py", line 97, in wrapper
    return func(*args, session=session, **kwargs)
           ^^^^^^^^^^^^^^^^^^^^^^^^^^^^^^^^^^^^^^
  File "/home/airflow/.local/lib/python3.12/site-packages/airflow/models/taskinstance.py", line 3006, in _run_raw_task
    return _run_raw_task(
           ^^^^^^^^^^^^^^
  File "/home/airflow/.local/lib/python3.12/site-packages/airflow/models/taskinstance.py", line 328, in _run_raw_task
    ti.handle_failure(e, test_mode, context, session=session)
  File "/home/airflow/.local/lib/python3.12/site-packages/airflow/utils/session.py", line 94, in wrapper
    return func(*args, **kwargs)
           ^^^^^^^^^^^^^^^^^^^^^
  File "/home/airflow/.local/lib/python3.12/site-packages/airflow/models/taskinstance.py", line 3434, in handle_failure
    _handle_failure(
  File "/home/airflow/.local/lib/python3.12/site-packages/airflow/utils/session.py", line 94, in wrapper
    return func(*args, **kwargs)
           ^^^^^^^^^^^^^^^^^^^^^
  File "/home/airflow/.local/lib/python3.12/site-packages/airflow/api_internal/internal_api_call.py", line 166, in wrapper
    return func(*args, **kwargs)
           ^^^^^^^^^^^^^^^^^^^^^
  File "/home/airflow/.local/lib/python3.12/site-packages/airflow/models/taskinstance.py", line 1244, in _handle_failure
    TaskInstance.save_to_db(task_instance, session)
  File "/home/airflow/.local/lib/python3.12/site-packages/airflow/api_internal/internal_api_call.py", line 166, in wrapper
    return func(*args, **kwargs)
           ^^^^^^^^^^^^^^^^^^^^^
  File "/home/airflow/.local/lib/python3.12/site-packages/airflow/utils/session.py", line 94, in wrapper
    return func(*args, **kwargs)
           ^^^^^^^^^^^^^^^^^^^^^
  File "/home/airflow/.local/lib/python3.12/site-packages/airflow/models/taskinstance.py", line 3402, in save_to_db
    ti.get_dagrun().refresh_from_db()
    ^^^^^^^^^^^^^^^
  File "/home/airflow/.local/lib/python3.12/site-packages/airflow/utils/session.py", line 96, in wrapper
    with create_session() as session:
         ^^^^^^^^^^^^^^^^
  File "/usr/local/lib/python3.12/contextlib.py", line 144, in __exit__
    next(self.gen)
  File "/home/airflow/.local/lib/python3.12/site-packages/airflow/utils/session.py", line 57, in create_session
    session.commit()
  File "/home/airflow/.local/lib/python3.12/site-packages/sqlalchemy/orm/session.py", line 1454, in commit
    self._transaction.commit(_to_root=self.future)
  File "/home/airflow/.local/lib/python3.12/site-packages/sqlalchemy/orm/session.py", line 832, in commit
    self._prepare_impl()
  File "/home/airflow/.local/lib/python3.12/site-packages/sqlalchemy/orm/session.py", line 811, in _prepare_impl
    self.session.flush()
  File "/home/airflow/.local/lib/python3.12/site-packages/sqlalchemy/orm/session.py", line 3449, in flush
    self._flush(objects)
  File "/home/airflow/.local/lib/python3.12/site-packages/sqlalchemy/orm/session.py", line 3588, in _flush
    with util.safe_reraise():
         ^^^^^^^^^^^^^^^^^^^
  File "/home/airflow/.local/lib/python3.12/site-packages/sqlalchemy/util/langhelpers.py", line 70, in __exit__
    compat.raise_(
  File "/home/airflow/.local/lib/python3.12/site-packages/sqlalchemy/util/compat.py", line 211, in raise_
    raise exception
  File "/home/airflow/.local/lib/python3.12/site-packages/sqlalchemy/orm/session.py", line 3549, in _flush
    flush_context.execute()
  File "/home/airflow/.local/lib/python3.12/site-packages/sqlalchemy/orm/unitofwork.py", line 456, in execute
    rec.execute(self)
  File "/home/airflow/.local/lib/python3.12/site-packages/sqlalchemy/orm/unitofwork.py", line 630, in execute
    util.preloaded.orm_persistence.save_obj(
  File "/home/airflow/.local/lib/python3.12/site-packages/sqlalchemy/orm/persistence.py", line 245, in save_obj
    _emit_insert_statements(
  File "/home/airflow/.local/lib/python3.12/site-packages/sqlalchemy/orm/persistence.py", line 1238, in _emit_insert_statements
    result = connection._execute_20(
             ^^^^^^^^^^^^^^^^^^^^^^^
  File "/home/airflow/.local/lib/python3.12/site-packages/sqlalchemy/engine/base.py", line 1710, in _execute_20
    return meth(self, args_10style, kwargs_10style, execution_options)
           ^^^^^^^^^^^^^^^^^^^^^^^^^^^^^^^^^^^^^^^^^^^^^^^^^^^^^^^^^^^
  File "/home/airflow/.local/lib/python3.12/site-packages/sqlalchemy/sql/elements.py", line 334, in _execute_on_connection
    return connection._execute_clauseelement(
           ^^^^^^^^^^^^^^^^^^^^^^^^^^^^^^^^^^
  File "/home/airflow/.local/lib/python3.12/site-packages/sqlalchemy/engine/base.py", line 1577, in _execute_clauseelement
    ret = self._execute_context(
          ^^^^^^^^^^^^^^^^^^^^^^
  File "/home/airflow/.local/lib/python3.12/site-packages/sqlalchemy/engine/base.py", line 1953, in _execute_context
    self._handle_dbapi_exception(
  File "/home/airflow/.local/lib/python3.12/site-packages/sqlalchemy/engine/base.py", line 2134, in _handle_dbapi_exception
    util.raise_(
  File "/home/airflow/.local/lib/python3.12/site-packages/sqlalchemy/util/compat.py", line 211, in raise_
    raise exception
  File "/home/airflow/.local/lib/python3.12/site-packages/sqlalchemy/engine/base.py", line 1910, in _execute_context
    self.dialect.do_execute(
  File "/home/airflow/.local/lib/python3.12/site-packages/sqlalchemy/engine/default.py", line 736, in do_execute
    cursor.execute(statement, parameters)
sqlalchemy.exc.IntegrityError: (psycopg2.errors.ForeignKeyViolation) insert or update on table "task_fail" violates foreign key constraint "task_fail_ti_fkey"
DETAIL:  Key (dag_id, task_id, run_id, map_index)=(etl_fire_incidents_dag, task_etl_fire_incident_using_bash, manual__2025-03-08T18:52:45.254054+00:00, -1) is not present in table "task_instance".

[SQL: INSERT INTO task_fail (task_id, dag_id, run_id, map_index, start_date, end_date, duration) VALUES (%(task_id)s, %(dag_id)s, %(run_id)s, %(map_index)s, %(start_date)s, %(end_date)s, %(duration)s) RETURNING task_fail.id]
[parameters: {'task_id': 'task_etl_fire_incident_using_bash', 'dag_id': 'etl_fire_incidents_dag', 'run_id': 'manual__2025-03-08T18:52:45.254054+00:00', 'map_index': -1, 'start_date': datetime.datetime(2025, 3, 8, 18, 52, 58, 718073, tzinfo=Timezone('UTC')), 'end_date': datetime.datetime(2025, 3, 8, 18, 53, 1, 337079, tzinfo=Timezone('UTC')), 'duration': 2}]
(Background on this error at: https://sqlalche.me/e/14/gkpj)
[2025-03-08T18:53:01.372+0000] {local_task_job_runner.py:266} INFO - Task exited with return code 1
[2025-03-08T18:53:01.378+0000] {local_task_job_runner.py:245} INFO - ::endgroup::
