[2025-03-04T21:19:58.254+0000] {local_task_job_runner.py:123} INFO - ::group::Pre task execution logs
[2025-03-04T21:19:58.268+0000] {taskinstance.py:2614} INFO - Dependencies all met for dep_context=non-requeueable deps ti=<TaskInstance: pull_fire_incidents_dag.task_etl_fire_incident manual__2025-03-03T22:46:58.022572+00:00 [queued]>
[2025-03-04T21:19:58.274+0000] {taskinstance.py:2614} INFO - Dependencies all met for dep_context=requeueable deps ti=<TaskInstance: pull_fire_incidents_dag.task_etl_fire_incident manual__2025-03-03T22:46:58.022572+00:00 [queued]>
[2025-03-04T21:19:58.275+0000] {taskinstance.py:2867} INFO - Starting attempt 1 of 2
[2025-03-04T21:19:58.311+0000] {taskinstance.py:2890} INFO - Executing <Task(BashOperator): task_etl_fire_incident> on 2025-03-03 22:46:58.022572+00:00
[2025-03-04T21:19:58.316+0000] {warnings.py:112} WARNING - /home/***/.local/lib/python3.12/site-packages/***/task/task_runner/standard_task_runner.py:70: DeprecationWarning: This process (pid=103) is multi-threaded, use of fork() may lead to deadlocks in the child.
  pid = os.fork()

[2025-03-04T21:19:58.317+0000] {standard_task_runner.py:72} INFO - Started process 105 to run task
[2025-03-04T21:19:58.318+0000] {standard_task_runner.py:104} INFO - Running: ['***', 'tasks', 'run', 'pull_fire_incidents_dag', 'task_etl_fire_incident', 'manual__2025-03-03T22:46:58.022572+00:00', '--job-id', '140', '--raw', '--subdir', 'DAGS_FOLDER/fire_incidents_dag.py', '--cfg-path', '/tmp/tmpkng69v05']
[2025-03-04T21:19:58.319+0000] {standard_task_runner.py:105} INFO - Job 140: Subtask task_etl_fire_incident
[2025-03-04T21:19:59.185+0000] {task_command.py:467} INFO - Running <TaskInstance: pull_fire_incidents_dag.task_etl_fire_incident manual__2025-03-03T22:46:58.022572+00:00 [running]> on host ee9eaebe87f1
[2025-03-04T21:19:59.260+0000] {taskinstance.py:3134} INFO - Exporting env vars: AIRFLOW_CTX_DAG_EMAIL='***@***.com' AIRFLOW_CTX_DAG_OWNER='***' AIRFLOW_CTX_DAG_ID='pull_fire_incidents_dag' AIRFLOW_CTX_TASK_ID='task_etl_fire_incident' AIRFLOW_CTX_EXECUTION_DATE='2025-03-03T22:46:58.022572+00:00' AIRFLOW_CTX_TRY_NUMBER='1' AIRFLOW_CTX_DAG_RUN_ID='manual__2025-03-03T22:46:58.022572+00:00'
[2025-03-04T21:19:59.261+0000] {logging_mixin.py:190} INFO - Task instance is in running state
[2025-03-04T21:19:59.261+0000] {logging_mixin.py:190} INFO -  Previous state of the Task instance: queued
[2025-03-04T21:19:59.262+0000] {logging_mixin.py:190} INFO - Current task name:task_etl_fire_incident state:running start_date:2025-03-04 21:19:58.269075+00:00
[2025-03-04T21:19:59.262+0000] {logging_mixin.py:190} INFO - Dag name:pull_fire_incidents_dag and current dag run status:running
[2025-03-04T21:19:59.262+0000] {taskinstance.py:732} INFO - ::endgroup::
[2025-03-04T21:19:59.264+0000] {subprocess.py:78} INFO - Tmp dir root location: /tmp
[2025-03-04T21:19:59.265+0000] {subprocess.py:88} INFO - Running command: ['/usr/bin/bash', '-c', '\n      docker run -it       --network=pg-network-fire-incidents       nyc_fire_incidents:v001       --api_url=data.cityofnewyork.us       --token=xoIfIdDlHq6gGzxqLqbUeMpsG       --dataset_id=8m42-w767       --limit_rows=10000       --username=root       --password=root       --host_name=fire_incidents_db_container       --port=5432       --database=fire_incidents_db       --tbl_name=fire_incidents_tbl\n    ']
[2025-03-04T21:19:59.280+0000] {subprocess.py:99} INFO - Output:
[2025-03-04T21:19:59.400+0000] {subprocess.py:106} INFO - the input device is not a TTY
[2025-03-04T21:19:59.401+0000] {subprocess.py:110} INFO - Command exited with return code 1
[2025-03-04T21:19:59.410+0000] {taskinstance.py:3313} ERROR - Task failed with exception
Traceback (most recent call last):
  File "/home/airflow/.local/lib/python3.12/site-packages/airflow/models/taskinstance.py", line 768, in _execute_task
    result = _execute_callable(context=context, **execute_callable_kwargs)
             ^^^^^^^^^^^^^^^^^^^^^^^^^^^^^^^^^^^^^^^^^^^^^^^^^^^^^^^^^^^^^
  File "/home/airflow/.local/lib/python3.12/site-packages/airflow/models/taskinstance.py", line 734, in _execute_callable
    return ExecutionCallableRunner(
           ^^^^^^^^^^^^^^^^^^^^^^^^
  File "/home/airflow/.local/lib/python3.12/site-packages/airflow/utils/operator_helpers.py", line 252, in run
    return self.func(*args, **kwargs)
           ^^^^^^^^^^^^^^^^^^^^^^^^^^
  File "/home/airflow/.local/lib/python3.12/site-packages/airflow/models/baseoperator.py", line 424, in wrapper
    return func(self, *args, **kwargs)
           ^^^^^^^^^^^^^^^^^^^^^^^^^^^
  File "/home/airflow/.local/lib/python3.12/site-packages/airflow/operators/bash.py", line 276, in execute
    raise AirflowException(
airflow.exceptions.AirflowException: Bash command failed. The command returned a non-zero exit code 1.
[2025-03-04T21:19:59.417+0000] {logging_mixin.py:190} INFO - Task instance in failure state
[2025-03-04T21:19:59.417+0000] {logging_mixin.py:190} INFO - Task start:2025-03-04 21:19:58.269075+00:00 end:2025-03-04 21:19:59.417305+00:00 duration:1.14823
[2025-03-04T21:19:59.418+0000] {logging_mixin.py:190} INFO - Task:<Task(BashOperator): task_etl_fire_incident> dag:<DAG: pull_fire_incidents_dag> dagrun:<DagRun pull_fire_incidents_dag @ 2025-03-03 22:46:58.022572+00:00: manual__2025-03-03T22:46:58.022572+00:00, state:running, queued_at: 2025-03-03 22:46:58.058616+00:00. externally triggered: True>
[2025-03-04T21:19:59.418+0000] {logging_mixin.py:190} INFO - Failure caused by Bash command failed. The command returned a non-zero exit code 1.
[2025-03-04T21:19:59.418+0000] {taskinstance.py:1226} INFO - Marking task as UP_FOR_RETRY. dag_id=pull_fire_incidents_dag, task_id=task_etl_fire_incident, run_id=manual__2025-03-03T22:46:58.022572+00:00, execution_date=20250303T224658, start_date=20250304T211958, end_date=20250304T211959
[2025-03-04T21:19:59.446+0000] {taskinstance.py:341} INFO - ::group::Post task execution logs
[2025-03-04T21:19:59.446+0000] {standard_task_runner.py:124} ERROR - Failed to execute job 140 for task task_etl_fire_incident (Bash command failed. The command returned a non-zero exit code 1.; 105)
Traceback (most recent call last):
  File "/home/airflow/.local/lib/python3.12/site-packages/airflow/task/task_runner/standard_task_runner.py", line 117, in _start_by_fork
    ret = args.func(args, dag=self.dag)
          ^^^^^^^^^^^^^^^^^^^^^^^^^^^^^
  File "/home/airflow/.local/lib/python3.12/site-packages/airflow/cli/cli_config.py", line 49, in command
    return func(*args, **kwargs)
           ^^^^^^^^^^^^^^^^^^^^^
  File "/home/airflow/.local/lib/python3.12/site-packages/airflow/utils/cli.py", line 116, in wrapper
    return f(*args, **kwargs)
           ^^^^^^^^^^^^^^^^^^
  File "/home/airflow/.local/lib/python3.12/site-packages/airflow/cli/commands/task_command.py", line 483, in task_run
    task_return_code = _run_task_by_selected_method(args, _dag, ti)
                       ^^^^^^^^^^^^^^^^^^^^^^^^^^^^^^^^^^^^^^^^^^^^
  File "/home/airflow/.local/lib/python3.12/site-packages/airflow/cli/commands/task_command.py", line 256, in _run_task_by_selected_method
    return _run_raw_task(args, ti)
           ^^^^^^^^^^^^^^^^^^^^^^^
  File "/home/airflow/.local/lib/python3.12/site-packages/airflow/cli/commands/task_command.py", line 341, in _run_raw_task
    return ti._run_raw_task(
           ^^^^^^^^^^^^^^^^^
  File "/home/airflow/.local/lib/python3.12/site-packages/airflow/utils/session.py", line 97, in wrapper
    return func(*args, session=session, **kwargs)
           ^^^^^^^^^^^^^^^^^^^^^^^^^^^^^^^^^^^^^^
  File "/home/airflow/.local/lib/python3.12/site-packages/airflow/models/taskinstance.py", line 3006, in _run_raw_task
    return _run_raw_task(
           ^^^^^^^^^^^^^^
  File "/home/airflow/.local/lib/python3.12/site-packages/airflow/models/taskinstance.py", line 274, in _run_raw_task
    TaskInstance._execute_task_with_callbacks(
  File "/home/airflow/.local/lib/python3.12/site-packages/airflow/models/taskinstance.py", line 3161, in _execute_task_with_callbacks
    result = self._execute_task(context, task_orig)
             ^^^^^^^^^^^^^^^^^^^^^^^^^^^^^^^^^^^^^^
  File "/home/airflow/.local/lib/python3.12/site-packages/airflow/models/taskinstance.py", line 3185, in _execute_task
    return _execute_task(self, context, task_orig)
           ^^^^^^^^^^^^^^^^^^^^^^^^^^^^^^^^^^^^^^^
  File "/home/airflow/.local/lib/python3.12/site-packages/airflow/models/taskinstance.py", line 768, in _execute_task
    result = _execute_callable(context=context, **execute_callable_kwargs)
             ^^^^^^^^^^^^^^^^^^^^^^^^^^^^^^^^^^^^^^^^^^^^^^^^^^^^^^^^^^^^^
  File "/home/airflow/.local/lib/python3.12/site-packages/airflow/models/taskinstance.py", line 734, in _execute_callable
    return ExecutionCallableRunner(
           ^^^^^^^^^^^^^^^^^^^^^^^^
  File "/home/airflow/.local/lib/python3.12/site-packages/airflow/utils/operator_helpers.py", line 252, in run
    return self.func(*args, **kwargs)
           ^^^^^^^^^^^^^^^^^^^^^^^^^^
  File "/home/airflow/.local/lib/python3.12/site-packages/airflow/models/baseoperator.py", line 424, in wrapper
    return func(self, *args, **kwargs)
           ^^^^^^^^^^^^^^^^^^^^^^^^^^^
  File "/home/airflow/.local/lib/python3.12/site-packages/airflow/operators/bash.py", line 276, in execute
    raise AirflowException(
airflow.exceptions.AirflowException: Bash command failed. The command returned a non-zero exit code 1.
[2025-03-04T21:19:59.495+0000] {local_task_job_runner.py:266} INFO - Task exited with return code 1
[2025-03-04T21:19:59.692+0000] {taskinstance.py:3901} INFO - 0 downstream tasks scheduled from follow-on schedule check
[2025-03-04T21:19:59.696+0000] {local_task_job_runner.py:245} INFO - ::endgroup::
